INFO 2019-05-12 14:23:13,918 daniel1
INFO 2019-05-12 14:24:32,113 daniel1
2019-05-13 01:15:00,759 [Thread-3:3760] [django.request:228] [log:log_response] [ERROR]- Internal Server Error: /admin/application/rank/
Traceback (most recent call last):
  File "D:\development\Python\lib\site-packages\django\db\backends\utils.py", line 84, in _execute
    return self.cursor.execute(sql, params)
  File "D:\development\Python\lib\site-packages\django\db\backends\mysql\base.py", line 71, in execute
    return self.cursor.execute(query, args)
  File "D:\development\Python\lib\site-packages\pymysql\cursors.py", line 170, in execute
    result = self._query(query)
  File "D:\development\Python\lib\site-packages\pymysql\cursors.py", line 328, in _query
    conn.query(q)
  File "D:\development\Python\lib\site-packages\pymysql\connections.py", line 517, in query
    self._affected_rows = self._read_query_result(unbuffered=unbuffered)
  File "D:\development\Python\lib\site-packages\pymysql\connections.py", line 732, in _read_query_result
    result.read()
  File "D:\development\Python\lib\site-packages\pymysql\connections.py", line 1075, in read
    first_packet = self.connection._read_packet()
  File "D:\development\Python\lib\site-packages\pymysql\connections.py", line 684, in _read_packet
    packet.check_error()
  File "D:\development\Python\lib\site-packages\pymysql\protocol.py", line 220, in check_error
    err.raise_mysql_exception(self._data)
  File "D:\development\Python\lib\site-packages\pymysql\err.py", line 109, in raise_mysql_exception
    raise errorclass(errno, errval)
pymysql.err.ProgrammingError: (1146, "Table 'plant.application_subject' doesn't exist")

The above exception was the direct cause of the following exception:

Traceback (most recent call last):
  File "D:\development\Python\lib\site-packages\django\core\handlers\exception.py", line 34, in inner
    response = get_response(request)
  File "D:\development\Python\lib\site-packages\django\core\handlers\base.py", line 115, in _get_response
    response = self.process_exception_by_middleware(e, request)
  File "D:\development\Python\lib\site-packages\django\core\handlers\base.py", line 113, in _get_response
    response = wrapped_callback(request, *callback_args, **callback_kwargs)
  File "D:\development\Python\lib\site-packages\django\contrib\admin\options.py", line 606, in wrapper
    return self.admin_site.admin_view(view)(*args, **kwargs)
  File "D:\development\Python\lib\site-packages\django\utils\decorators.py", line 142, in _wrapped_view
    response = view_func(request, *args, **kwargs)
  File "D:\development\Python\lib\site-packages\django\views\decorators\cache.py", line 44, in _wrapped_view_func
    response = view_func(request, *args, **kwargs)
  File "D:\development\Python\lib\site-packages\django\contrib\admin\sites.py", line 223, in inner
    return view(request, *args, **kwargs)
  File "D:\development\Python\lib\site-packages\django\utils\decorators.py", line 45, in _wrapper
    return bound_method(*args, **kwargs)
  File "D:\development\Python\lib\site-packages\django\utils\decorators.py", line 142, in _wrapped_view
    response = view_func(request, *args, **kwargs)
  File "D:\development\Python\lib\site-packages\django\contrib\admin\options.py", line 1672, in changelist_view
    cl = self.get_changelist_instance(request)
  File "D:\development\Python\lib\site-packages\django\contrib\admin\options.py", line 744, in get_changelist_instance
    sortable_by,
  File "D:\development\Python\lib\site-packages\django\contrib\admin\views\main.py", line 81, in __init__
    self.queryset = self.get_queryset(request)
  File "D:\development\Python\lib\site-packages\django\contrib\admin\views\main.py", line 405, in get_queryset
    filters_use_distinct) = self.get_filters(request)
  File "D:\development\Python\lib\site-packages\django\contrib\admin\views\main.py", line 135, in get_filters
    self.model, self.model_admin, field_path=field_path,
  File "D:\development\Python\lib\site-packages\django\contrib\admin\filters.py", line 159, in create
    return list_filter_class(field, request, params, model, model_admin, field_path=field_path)
  File "D:\development\Python\lib\site-packages\django\contrib\admin\filters.py", line 170, in __init__
    self.lookup_choices = self.field_choices(field, request, model_admin)
  File "D:\development\Python\lib\site-packages\django\contrib\admin\filters.py", line 201, in field_choices
    return field.get_choices(include_blank=False, ordering=ordering)
  File "D:\development\Python\lib\site-packages\django\db\models\fields\__init__.py", line 831, in get_choices
    for x in rel_model._default_manager.complex_filter(limit_choices_to).order_by(*ordering)
  File "D:\development\Python\lib\site-packages\django\db\models\query.py", line 274, in __iter__
    self._fetch_all()
  File "D:\development\Python\lib\site-packages\django\db\models\query.py", line 1242, in _fetch_all
    self._result_cache = list(self._iterable_class(self))
  File "D:\development\Python\lib\site-packages\django\db\models\query.py", line 55, in __iter__
    results = compiler.execute_sql(chunked_fetch=self.chunked_fetch, chunk_size=self.chunk_size)
  File "D:\development\Python\lib\site-packages\django\db\models\sql\compiler.py", line 1097, in execute_sql
    cursor.execute(sql, params)
  File "D:\development\Python\lib\site-packages\django\db\backends\utils.py", line 99, in execute
    return super().execute(sql, params)
  File "D:\development\Python\lib\site-packages\django\db\backends\utils.py", line 67, in execute
    return self._execute_with_wrappers(sql, params, many=False, executor=self._execute)
  File "D:\development\Python\lib\site-packages\django\db\backends\utils.py", line 76, in _execute_with_wrappers
    return executor(sql, params, many, context)
  File "D:\development\Python\lib\site-packages\django\db\backends\utils.py", line 84, in _execute
    return self.cursor.execute(sql, params)
  File "D:\development\Python\lib\site-packages\django\db\utils.py", line 89, in __exit__
    raise dj_exc_value.with_traceback(traceback) from exc_value
  File "D:\development\Python\lib\site-packages\django\db\backends\utils.py", line 84, in _execute
    return self.cursor.execute(sql, params)
  File "D:\development\Python\lib\site-packages\django\db\backends\mysql\base.py", line 71, in execute
    return self.cursor.execute(query, args)
  File "D:\development\Python\lib\site-packages\pymysql\cursors.py", line 170, in execute
    result = self._query(query)
  File "D:\development\Python\lib\site-packages\pymysql\cursors.py", line 328, in _query
    conn.query(q)
  File "D:\development\Python\lib\site-packages\pymysql\connections.py", line 517, in query
    self._affected_rows = self._read_query_result(unbuffered=unbuffered)
  File "D:\development\Python\lib\site-packages\pymysql\connections.py", line 732, in _read_query_result
    result.read()
  File "D:\development\Python\lib\site-packages\pymysql\connections.py", line 1075, in read
    first_packet = self.connection._read_packet()
  File "D:\development\Python\lib\site-packages\pymysql\connections.py", line 684, in _read_packet
    packet.check_error()
  File "D:\development\Python\lib\site-packages\pymysql\protocol.py", line 220, in check_error
    err.raise_mysql_exception(self._data)
  File "D:\development\Python\lib\site-packages\pymysql\err.py", line 109, in raise_mysql_exception
    raise errorclass(errno, errval)
django.db.utils.ProgrammingError: (1146, "Table 'plant.application_subject' doesn't exist")
2019-05-13 01:16:20,358 [Thread-3:13824] [django.request:228] [log:log_response] [ERROR]- Internal Server Error: /admin/application/rank/
Traceback (most recent call last):
  File "D:\development\Python\lib\site-packages\django\db\backends\utils.py", line 84, in _execute
    return self.cursor.execute(sql, params)
  File "D:\development\Python\lib\site-packages\django\db\backends\mysql\base.py", line 71, in execute
    return self.cursor.execute(query, args)
  File "D:\development\Python\lib\site-packages\pymysql\cursors.py", line 170, in execute
    result = self._query(query)
  File "D:\development\Python\lib\site-packages\pymysql\cursors.py", line 328, in _query
    conn.query(q)
  File "D:\development\Python\lib\site-packages\pymysql\connections.py", line 517, in query
    self._affected_rows = self._read_query_result(unbuffered=unbuffered)
  File "D:\development\Python\lib\site-packages\pymysql\connections.py", line 732, in _read_query_result
    result.read()
  File "D:\development\Python\lib\site-packages\pymysql\connections.py", line 1075, in read
    first_packet = self.connection._read_packet()
  File "D:\development\Python\lib\site-packages\pymysql\connections.py", line 684, in _read_packet
    packet.check_error()
  File "D:\development\Python\lib\site-packages\pymysql\protocol.py", line 220, in check_error
    err.raise_mysql_exception(self._data)
  File "D:\development\Python\lib\site-packages\pymysql\err.py", line 109, in raise_mysql_exception
    raise errorclass(errno, errval)
pymysql.err.ProgrammingError: (1146, "Table 'plant.application_subject' doesn't exist")

The above exception was the direct cause of the following exception:

Traceback (most recent call last):
  File "D:\development\Python\lib\site-packages\django\core\handlers\exception.py", line 34, in inner
    response = get_response(request)
  File "D:\development\Python\lib\site-packages\django\core\handlers\base.py", line 115, in _get_response
    response = self.process_exception_by_middleware(e, request)
  File "D:\development\Python\lib\site-packages\django\core\handlers\base.py", line 113, in _get_response
    response = wrapped_callback(request, *callback_args, **callback_kwargs)
  File "D:\development\Python\lib\site-packages\django\contrib\admin\options.py", line 606, in wrapper
    return self.admin_site.admin_view(view)(*args, **kwargs)
  File "D:\development\Python\lib\site-packages\django\utils\decorators.py", line 142, in _wrapped_view
    response = view_func(request, *args, **kwargs)
  File "D:\development\Python\lib\site-packages\django\views\decorators\cache.py", line 44, in _wrapped_view_func
    response = view_func(request, *args, **kwargs)
  File "D:\development\Python\lib\site-packages\django\contrib\admin\sites.py", line 223, in inner
    return view(request, *args, **kwargs)
  File "D:\development\Python\lib\site-packages\django\utils\decorators.py", line 45, in _wrapper
    return bound_method(*args, **kwargs)
  File "D:\development\Python\lib\site-packages\django\utils\decorators.py", line 142, in _wrapped_view
    response = view_func(request, *args, **kwargs)
  File "D:\development\Python\lib\site-packages\django\contrib\admin\options.py", line 1672, in changelist_view
    cl = self.get_changelist_instance(request)
  File "D:\development\Python\lib\site-packages\django\contrib\admin\options.py", line 744, in get_changelist_instance
    sortable_by,
  File "D:\development\Python\lib\site-packages\django\contrib\admin\views\main.py", line 81, in __init__
    self.queryset = self.get_queryset(request)
  File "D:\development\Python\lib\site-packages\django\contrib\admin\views\main.py", line 405, in get_queryset
    filters_use_distinct) = self.get_filters(request)
  File "D:\development\Python\lib\site-packages\django\contrib\admin\views\main.py", line 135, in get_filters
    self.model, self.model_admin, field_path=field_path,
  File "D:\development\Python\lib\site-packages\django\contrib\admin\filters.py", line 159, in create
    return list_filter_class(field, request, params, model, model_admin, field_path=field_path)
  File "D:\development\Python\lib\site-packages\django\contrib\admin\filters.py", line 170, in __init__
    self.lookup_choices = self.field_choices(field, request, model_admin)
  File "D:\development\Python\lib\site-packages\django\contrib\admin\filters.py", line 201, in field_choices
    return field.get_choices(include_blank=False, ordering=ordering)
  File "D:\development\Python\lib\site-packages\django\db\models\fields\__init__.py", line 831, in get_choices
    for x in rel_model._default_manager.complex_filter(limit_choices_to).order_by(*ordering)
  File "D:\development\Python\lib\site-packages\django\db\models\query.py", line 274, in __iter__
    self._fetch_all()
  File "D:\development\Python\lib\site-packages\django\db\models\query.py", line 1242, in _fetch_all
    self._result_cache = list(self._iterable_class(self))
  File "D:\development\Python\lib\site-packages\django\db\models\query.py", line 55, in __iter__
    results = compiler.execute_sql(chunked_fetch=self.chunked_fetch, chunk_size=self.chunk_size)
  File "D:\development\Python\lib\site-packages\django\db\models\sql\compiler.py", line 1097, in execute_sql
    cursor.execute(sql, params)
  File "D:\development\Python\lib\site-packages\django\db\backends\utils.py", line 99, in execute
    return super().execute(sql, params)
  File "D:\development\Python\lib\site-packages\django\db\backends\utils.py", line 67, in execute
    return self._execute_with_wrappers(sql, params, many=False, executor=self._execute)
  File "D:\development\Python\lib\site-packages\django\db\backends\utils.py", line 76, in _execute_with_wrappers
    return executor(sql, params, many, context)
  File "D:\development\Python\lib\site-packages\django\db\backends\utils.py", line 84, in _execute
    return self.cursor.execute(sql, params)
  File "D:\development\Python\lib\site-packages\django\db\utils.py", line 89, in __exit__
    raise dj_exc_value.with_traceback(traceback) from exc_value
  File "D:\development\Python\lib\site-packages\django\db\backends\utils.py", line 84, in _execute
    return self.cursor.execute(sql, params)
  File "D:\development\Python\lib\site-packages\django\db\backends\mysql\base.py", line 71, in execute
    return self.cursor.execute(query, args)
  File "D:\development\Python\lib\site-packages\pymysql\cursors.py", line 170, in execute
    result = self._query(query)
  File "D:\development\Python\lib\site-packages\pymysql\cursors.py", line 328, in _query
    conn.query(q)
  File "D:\development\Python\lib\site-packages\pymysql\connections.py", line 517, in query
    self._affected_rows = self._read_query_result(unbuffered=unbuffered)
  File "D:\development\Python\lib\site-packages\pymysql\connections.py", line 732, in _read_query_result
    result.read()
  File "D:\development\Python\lib\site-packages\pymysql\connections.py", line 1075, in read
    first_packet = self.connection._read_packet()
  File "D:\development\Python\lib\site-packages\pymysql\connections.py", line 684, in _read_packet
    packet.check_error()
  File "D:\development\Python\lib\site-packages\pymysql\protocol.py", line 220, in check_error
    err.raise_mysql_exception(self._data)
  File "D:\development\Python\lib\site-packages\pymysql\err.py", line 109, in raise_mysql_exception
    raise errorclass(errno, errval)
django.db.utils.ProgrammingError: (1146, "Table 'plant.application_subject' doesn't exist")
2019-05-13 01:20:54,660 [Thread-3:4660] [django.request:228] [log:log_response] [ERROR]- Internal Server Error: /admin/application/subject/
Traceback (most recent call last):
  File "D:\development\Python\lib\site-packages\django\db\backends\utils.py", line 84, in _execute
    return self.cursor.execute(sql, params)
  File "D:\development\Python\lib\site-packages\django\db\backends\mysql\base.py", line 71, in execute
    return self.cursor.execute(query, args)
  File "D:\development\Python\lib\site-packages\pymysql\cursors.py", line 170, in execute
    result = self._query(query)
  File "D:\development\Python\lib\site-packages\pymysql\cursors.py", line 328, in _query
    conn.query(q)
  File "D:\development\Python\lib\site-packages\pymysql\connections.py", line 517, in query
    self._affected_rows = self._read_query_result(unbuffered=unbuffered)
  File "D:\development\Python\lib\site-packages\pymysql\connections.py", line 732, in _read_query_result
    result.read()
  File "D:\development\Python\lib\site-packages\pymysql\connections.py", line 1075, in read
    first_packet = self.connection._read_packet()
  File "D:\development\Python\lib\site-packages\pymysql\connections.py", line 684, in _read_packet
    packet.check_error()
  File "D:\development\Python\lib\site-packages\pymysql\protocol.py", line 220, in check_error
    err.raise_mysql_exception(self._data)
  File "D:\development\Python\lib\site-packages\pymysql\err.py", line 109, in raise_mysql_exception
    raise errorclass(errno, errval)
pymysql.err.ProgrammingError: (1146, "Table 'plant.application_subject' doesn't exist")

The above exception was the direct cause of the following exception:

Traceback (most recent call last):
  File "D:\development\Python\lib\site-packages\django\core\handlers\exception.py", line 34, in inner
    response = get_response(request)
  File "D:\development\Python\lib\site-packages\django\core\handlers\base.py", line 115, in _get_response
    response = self.process_exception_by_middleware(e, request)
  File "D:\development\Python\lib\site-packages\django\core\handlers\base.py", line 113, in _get_response
    response = wrapped_callback(request, *callback_args, **callback_kwargs)
  File "D:\development\Python\lib\site-packages\django\contrib\admin\options.py", line 606, in wrapper
    return self.admin_site.admin_view(view)(*args, **kwargs)
  File "D:\development\Python\lib\site-packages\django\utils\decorators.py", line 142, in _wrapped_view
    response = view_func(request, *args, **kwargs)
  File "D:\development\Python\lib\site-packages\django\views\decorators\cache.py", line 44, in _wrapped_view_func
    response = view_func(request, *args, **kwargs)
  File "D:\development\Python\lib\site-packages\django\contrib\admin\sites.py", line 223, in inner
    return view(request, *args, **kwargs)
  File "D:\development\Python\lib\site-packages\django\utils\decorators.py", line 45, in _wrapper
    return bound_method(*args, **kwargs)
  File "D:\development\Python\lib\site-packages\django\utils\decorators.py", line 142, in _wrapped_view
    response = view_func(request, *args, **kwargs)
  File "D:\development\Python\lib\site-packages\django\contrib\admin\options.py", line 1672, in changelist_view
    cl = self.get_changelist_instance(request)
  File "D:\development\Python\lib\site-packages\django\contrib\admin\options.py", line 744, in get_changelist_instance
    sortable_by,
  File "D:\development\Python\lib\site-packages\django\contrib\admin\views\main.py", line 82, in __init__
    self.get_results(request)
  File "D:\development\Python\lib\site-packages\django\contrib\admin\views\main.py", line 210, in get_results
    result_count = paginator.count
  File "D:\development\Python\lib\site-packages\django\utils\functional.py", line 80, in __get__
    res = instance.__dict__[self.name] = self.func(instance)
  File "D:\development\Python\lib\site-packages\django\core\paginator.py", line 91, in count
    return c()
  File "D:\development\Python\lib\site-packages\django\db\models\query.py", line 392, in count
    return self.query.get_count(using=self.db)
  File "D:\development\Python\lib\site-packages\django\db\models\sql\query.py", line 504, in get_count
    number = obj.get_aggregation(using, ['__count'])['__count']
  File "D:\development\Python\lib\site-packages\django\db\models\sql\query.py", line 489, in get_aggregation
    result = compiler.execute_sql(SINGLE)
  File "D:\development\Python\lib\site-packages\django\db\models\sql\compiler.py", line 1097, in execute_sql
    cursor.execute(sql, params)
  File "D:\development\Python\lib\site-packages\django\db\backends\utils.py", line 99, in execute
    return super().execute(sql, params)
  File "D:\development\Python\lib\site-packages\django\db\backends\utils.py", line 67, in execute
    return self._execute_with_wrappers(sql, params, many=False, executor=self._execute)
  File "D:\development\Python\lib\site-packages\django\db\backends\utils.py", line 76, in _execute_with_wrappers
    return executor(sql, params, many, context)
  File "D:\development\Python\lib\site-packages\django\db\backends\utils.py", line 84, in _execute
    return self.cursor.execute(sql, params)
  File "D:\development\Python\lib\site-packages\django\db\utils.py", line 89, in __exit__
    raise dj_exc_value.with_traceback(traceback) from exc_value
  File "D:\development\Python\lib\site-packages\django\db\backends\utils.py", line 84, in _execute
    return self.cursor.execute(sql, params)
  File "D:\development\Python\lib\site-packages\django\db\backends\mysql\base.py", line 71, in execute
    return self.cursor.execute(query, args)
  File "D:\development\Python\lib\site-packages\pymysql\cursors.py", line 170, in execute
    result = self._query(query)
  File "D:\development\Python\lib\site-packages\pymysql\cursors.py", line 328, in _query
    conn.query(q)
  File "D:\development\Python\lib\site-packages\pymysql\connections.py", line 517, in query
    self._affected_rows = self._read_query_result(unbuffered=unbuffered)
  File "D:\development\Python\lib\site-packages\pymysql\connections.py", line 732, in _read_query_result
    result.read()
  File "D:\development\Python\lib\site-packages\pymysql\connections.py", line 1075, in read
    first_packet = self.connection._read_packet()
  File "D:\development\Python\lib\site-packages\pymysql\connections.py", line 684, in _read_packet
    packet.check_error()
  File "D:\development\Python\lib\site-packages\pymysql\protocol.py", line 220, in check_error
    err.raise_mysql_exception(self._data)
  File "D:\development\Python\lib\site-packages\pymysql\err.py", line 109, in raise_mysql_exception
    raise errorclass(errno, errval)
django.db.utils.ProgrammingError: (1146, "Table 'plant.application_subject' doesn't exist")
2019-05-13 01:22:42,667 [Thread-3:13860] [django.request:228] [log:log_response] [ERROR]- Internal Server Error: /admin/application/subject/
Traceback (most recent call last):
  File "D:\development\Python\lib\site-packages\django\db\backends\utils.py", line 84, in _execute
    return self.cursor.execute(sql, params)
  File "D:\development\Python\lib\site-packages\django\db\backends\mysql\base.py", line 71, in execute
    return self.cursor.execute(query, args)
  File "D:\development\Python\lib\site-packages\pymysql\cursors.py", line 170, in execute
    result = self._query(query)
  File "D:\development\Python\lib\site-packages\pymysql\cursors.py", line 328, in _query
    conn.query(q)
  File "D:\development\Python\lib\site-packages\pymysql\connections.py", line 517, in query
    self._affected_rows = self._read_query_result(unbuffered=unbuffered)
  File "D:\development\Python\lib\site-packages\pymysql\connections.py", line 732, in _read_query_result
    result.read()
  File "D:\development\Python\lib\site-packages\pymysql\connections.py", line 1075, in read
    first_packet = self.connection._read_packet()
  File "D:\development\Python\lib\site-packages\pymysql\connections.py", line 684, in _read_packet
    packet.check_error()
  File "D:\development\Python\lib\site-packages\pymysql\protocol.py", line 220, in check_error
    err.raise_mysql_exception(self._data)
  File "D:\development\Python\lib\site-packages\pymysql\err.py", line 109, in raise_mysql_exception
    raise errorclass(errno, errval)
pymysql.err.ProgrammingError: (1146, "Table 'plant.subject' doesn't exist")

The above exception was the direct cause of the following exception:

Traceback (most recent call last):
  File "D:\development\Python\lib\site-packages\django\core\handlers\exception.py", line 34, in inner
    response = get_response(request)
  File "D:\development\Python\lib\site-packages\django\core\handlers\base.py", line 115, in _get_response
    response = self.process_exception_by_middleware(e, request)
  File "D:\development\Python\lib\site-packages\django\core\handlers\base.py", line 113, in _get_response
    response = wrapped_callback(request, *callback_args, **callback_kwargs)
  File "D:\development\Python\lib\site-packages\django\contrib\admin\options.py", line 606, in wrapper
    return self.admin_site.admin_view(view)(*args, **kwargs)
  File "D:\development\Python\lib\site-packages\django\utils\decorators.py", line 142, in _wrapped_view
    response = view_func(request, *args, **kwargs)
  File "D:\development\Python\lib\site-packages\django\views\decorators\cache.py", line 44, in _wrapped_view_func
    response = view_func(request, *args, **kwargs)
  File "D:\development\Python\lib\site-packages\django\contrib\admin\sites.py", line 223, in inner
    return view(request, *args, **kwargs)
  File "D:\development\Python\lib\site-packages\django\utils\decorators.py", line 45, in _wrapper
    return bound_method(*args, **kwargs)
  File "D:\development\Python\lib\site-packages\django\utils\decorators.py", line 142, in _wrapped_view
    response = view_func(request, *args, **kwargs)
  File "D:\development\Python\lib\site-packages\django\contrib\admin\options.py", line 1672, in changelist_view
    cl = self.get_changelist_instance(request)
  File "D:\development\Python\lib\site-packages\django\contrib\admin\options.py", line 744, in get_changelist_instance
    sortable_by,
  File "D:\development\Python\lib\site-packages\django\contrib\admin\views\main.py", line 82, in __init__
    self.get_results(request)
  File "D:\development\Python\lib\site-packages\django\contrib\admin\views\main.py", line 210, in get_results
    result_count = paginator.count
  File "D:\development\Python\lib\site-packages\django\utils\functional.py", line 80, in __get__
    res = instance.__dict__[self.name] = self.func(instance)
  File "D:\development\Python\lib\site-packages\django\core\paginator.py", line 91, in count
    return c()
  File "D:\development\Python\lib\site-packages\django\db\models\query.py", line 392, in count
    return self.query.get_count(using=self.db)
  File "D:\development\Python\lib\site-packages\django\db\models\sql\query.py", line 504, in get_count
    number = obj.get_aggregation(using, ['__count'])['__count']
  File "D:\development\Python\lib\site-packages\django\db\models\sql\query.py", line 489, in get_aggregation
    result = compiler.execute_sql(SINGLE)
  File "D:\development\Python\lib\site-packages\django\db\models\sql\compiler.py", line 1097, in execute_sql
    cursor.execute(sql, params)
  File "D:\development\Python\lib\site-packages\django\db\backends\utils.py", line 99, in execute
    return super().execute(sql, params)
  File "D:\development\Python\lib\site-packages\django\db\backends\utils.py", line 67, in execute
    return self._execute_with_wrappers(sql, params, many=False, executor=self._execute)
  File "D:\development\Python\lib\site-packages\django\db\backends\utils.py", line 76, in _execute_with_wrappers
    return executor(sql, params, many, context)
  File "D:\development\Python\lib\site-packages\django\db\backends\utils.py", line 84, in _execute
    return self.cursor.execute(sql, params)
  File "D:\development\Python\lib\site-packages\django\db\utils.py", line 89, in __exit__
    raise dj_exc_value.with_traceback(traceback) from exc_value
  File "D:\development\Python\lib\site-packages\django\db\backends\utils.py", line 84, in _execute
    return self.cursor.execute(sql, params)
  File "D:\development\Python\lib\site-packages\django\db\backends\mysql\base.py", line 71, in execute
    return self.cursor.execute(query, args)
  File "D:\development\Python\lib\site-packages\pymysql\cursors.py", line 170, in execute
    result = self._query(query)
  File "D:\development\Python\lib\site-packages\pymysql\cursors.py", line 328, in _query
    conn.query(q)
  File "D:\development\Python\lib\site-packages\pymysql\connections.py", line 517, in query
    self._affected_rows = self._read_query_result(unbuffered=unbuffered)
  File "D:\development\Python\lib\site-packages\pymysql\connections.py", line 732, in _read_query_result
    result.read()
  File "D:\development\Python\lib\site-packages\pymysql\connections.py", line 1075, in read
    first_packet = self.connection._read_packet()
  File "D:\development\Python\lib\site-packages\pymysql\connections.py", line 684, in _read_packet
    packet.check_error()
  File "D:\development\Python\lib\site-packages\pymysql\protocol.py", line 220, in check_error
    err.raise_mysql_exception(self._data)
  File "D:\development\Python\lib\site-packages\pymysql\err.py", line 109, in raise_mysql_exception
    raise errorclass(errno, errval)
django.db.utils.ProgrammingError: (1146, "Table 'plant.subject' doesn't exist")
2019-05-13 01:25:51,048 [Thread-3:13860] [django.request:228] [log:log_response] [ERROR]- Internal Server Error: /admin/application/subject/
Traceback (most recent call last):
  File "D:\development\Python\lib\site-packages\django\db\backends\utils.py", line 84, in _execute
    return self.cursor.execute(sql, params)
  File "D:\development\Python\lib\site-packages\django\db\backends\mysql\base.py", line 71, in execute
    return self.cursor.execute(query, args)
  File "D:\development\Python\lib\site-packages\pymysql\cursors.py", line 170, in execute
    result = self._query(query)
  File "D:\development\Python\lib\site-packages\pymysql\cursors.py", line 328, in _query
    conn.query(q)
  File "D:\development\Python\lib\site-packages\pymysql\connections.py", line 517, in query
    self._affected_rows = self._read_query_result(unbuffered=unbuffered)
  File "D:\development\Python\lib\site-packages\pymysql\connections.py", line 732, in _read_query_result
    result.read()
  File "D:\development\Python\lib\site-packages\pymysql\connections.py", line 1075, in read
    first_packet = self.connection._read_packet()
  File "D:\development\Python\lib\site-packages\pymysql\connections.py", line 684, in _read_packet
    packet.check_error()
  File "D:\development\Python\lib\site-packages\pymysql\protocol.py", line 220, in check_error
    err.raise_mysql_exception(self._data)
  File "D:\development\Python\lib\site-packages\pymysql\err.py", line 109, in raise_mysql_exception
    raise errorclass(errno, errval)
pymysql.err.ProgrammingError: (1146, "Table 'plant.subject' doesn't exist")

The above exception was the direct cause of the following exception:

Traceback (most recent call last):
  File "D:\development\Python\lib\site-packages\django\core\handlers\exception.py", line 34, in inner
    response = get_response(request)
  File "D:\development\Python\lib\site-packages\django\core\handlers\base.py", line 115, in _get_response
    response = self.process_exception_by_middleware(e, request)
  File "D:\development\Python\lib\site-packages\django\core\handlers\base.py", line 113, in _get_response
    response = wrapped_callback(request, *callback_args, **callback_kwargs)
  File "D:\development\Python\lib\site-packages\django\contrib\admin\options.py", line 606, in wrapper
    return self.admin_site.admin_view(view)(*args, **kwargs)
  File "D:\development\Python\lib\site-packages\django\utils\decorators.py", line 142, in _wrapped_view
    response = view_func(request, *args, **kwargs)
  File "D:\development\Python\lib\site-packages\django\views\decorators\cache.py", line 44, in _wrapped_view_func
    response = view_func(request, *args, **kwargs)
  File "D:\development\Python\lib\site-packages\django\contrib\admin\sites.py", line 223, in inner
    return view(request, *args, **kwargs)
  File "D:\development\Python\lib\site-packages\django\utils\decorators.py", line 45, in _wrapper
    return bound_method(*args, **kwargs)
  File "D:\development\Python\lib\site-packages\django\utils\decorators.py", line 142, in _wrapped_view
    response = view_func(request, *args, **kwargs)
  File "D:\development\Python\lib\site-packages\django\contrib\admin\options.py", line 1672, in changelist_view
    cl = self.get_changelist_instance(request)
  File "D:\development\Python\lib\site-packages\django\contrib\admin\options.py", line 744, in get_changelist_instance
    sortable_by,
  File "D:\development\Python\lib\site-packages\django\contrib\admin\views\main.py", line 82, in __init__
    self.get_results(request)
  File "D:\development\Python\lib\site-packages\django\contrib\admin\views\main.py", line 210, in get_results
    result_count = paginator.count
  File "D:\development\Python\lib\site-packages\django\utils\functional.py", line 80, in __get__
    res = instance.__dict__[self.name] = self.func(instance)
  File "D:\development\Python\lib\site-packages\django\core\paginator.py", line 91, in count
    return c()
  File "D:\development\Python\lib\site-packages\django\db\models\query.py", line 392, in count
    return self.query.get_count(using=self.db)
  File "D:\development\Python\lib\site-packages\django\db\models\sql\query.py", line 504, in get_count
    number = obj.get_aggregation(using, ['__count'])['__count']
  File "D:\development\Python\lib\site-packages\django\db\models\sql\query.py", line 489, in get_aggregation
    result = compiler.execute_sql(SINGLE)
  File "D:\development\Python\lib\site-packages\django\db\models\sql\compiler.py", line 1097, in execute_sql
    cursor.execute(sql, params)
  File "D:\development\Python\lib\site-packages\django\db\backends\utils.py", line 99, in execute
    return super().execute(sql, params)
  File "D:\development\Python\lib\site-packages\django\db\backends\utils.py", line 67, in execute
    return self._execute_with_wrappers(sql, params, many=False, executor=self._execute)
  File "D:\development\Python\lib\site-packages\django\db\backends\utils.py", line 76, in _execute_with_wrappers
    return executor(sql, params, many, context)
  File "D:\development\Python\lib\site-packages\django\db\backends\utils.py", line 84, in _execute
    return self.cursor.execute(sql, params)
  File "D:\development\Python\lib\site-packages\django\db\utils.py", line 89, in __exit__
    raise dj_exc_value.with_traceback(traceback) from exc_value
  File "D:\development\Python\lib\site-packages\django\db\backends\utils.py", line 84, in _execute
    return self.cursor.execute(sql, params)
  File "D:\development\Python\lib\site-packages\django\db\backends\mysql\base.py", line 71, in execute
    return self.cursor.execute(query, args)
  File "D:\development\Python\lib\site-packages\pymysql\cursors.py", line 170, in execute
    result = self._query(query)
  File "D:\development\Python\lib\site-packages\pymysql\cursors.py", line 328, in _query
    conn.query(q)
  File "D:\development\Python\lib\site-packages\pymysql\connections.py", line 517, in query
    self._affected_rows = self._read_query_result(unbuffered=unbuffered)
  File "D:\development\Python\lib\site-packages\pymysql\connections.py", line 732, in _read_query_result
    result.read()
  File "D:\development\Python\lib\site-packages\pymysql\connections.py", line 1075, in read
    first_packet = self.connection._read_packet()
  File "D:\development\Python\lib\site-packages\pymysql\connections.py", line 684, in _read_packet
    packet.check_error()
  File "D:\development\Python\lib\site-packages\pymysql\protocol.py", line 220, in check_error
    err.raise_mysql_exception(self._data)
  File "D:\development\Python\lib\site-packages\pymysql\err.py", line 109, in raise_mysql_exception
    raise errorclass(errno, errval)
django.db.utils.ProgrammingError: (1146, "Table 'plant.subject' doesn't exist")
2019-05-13 01:27:35,165 [Thread-3:6356] [django.request:228] [log:log_response] [ERROR]- Internal Server Error: /admin/application/vote/
Traceback (most recent call last):
  File "D:\development\Python\lib\site-packages\django\db\backends\utils.py", line 84, in _execute
    return self.cursor.execute(sql, params)
  File "D:\development\Python\lib\site-packages\django\db\backends\mysql\base.py", line 71, in execute
    return self.cursor.execute(query, args)
  File "D:\development\Python\lib\site-packages\pymysql\cursors.py", line 170, in execute
    result = self._query(query)
  File "D:\development\Python\lib\site-packages\pymysql\cursors.py", line 328, in _query
    conn.query(q)
  File "D:\development\Python\lib\site-packages\pymysql\connections.py", line 517, in query
    self._affected_rows = self._read_query_result(unbuffered=unbuffered)
  File "D:\development\Python\lib\site-packages\pymysql\connections.py", line 732, in _read_query_result
    result.read()
  File "D:\development\Python\lib\site-packages\pymysql\connections.py", line 1075, in read
    first_packet = self.connection._read_packet()
  File "D:\development\Python\lib\site-packages\pymysql\connections.py", line 684, in _read_packet
    packet.check_error()
  File "D:\development\Python\lib\site-packages\pymysql\protocol.py", line 220, in check_error
    err.raise_mysql_exception(self._data)
  File "D:\development\Python\lib\site-packages\pymysql\err.py", line 109, in raise_mysql_exception
    raise errorclass(errno, errval)
pymysql.err.InternalError: (1054, "Unknown column 'rank.subject_id' in 'field list'")

The above exception was the direct cause of the following exception:

Traceback (most recent call last):
  File "D:\development\Python\lib\site-packages\django\core\handlers\exception.py", line 34, in inner
    response = get_response(request)
  File "D:\development\Python\lib\site-packages\django\core\handlers\base.py", line 115, in _get_response
    response = self.process_exception_by_middleware(e, request)
  File "D:\development\Python\lib\site-packages\django\core\handlers\base.py", line 113, in _get_response
    response = wrapped_callback(request, *callback_args, **callback_kwargs)
  File "D:\development\Python\lib\site-packages\django\contrib\admin\options.py", line 606, in wrapper
    return self.admin_site.admin_view(view)(*args, **kwargs)
  File "D:\development\Python\lib\site-packages\django\utils\decorators.py", line 142, in _wrapped_view
    response = view_func(request, *args, **kwargs)
  File "D:\development\Python\lib\site-packages\django\views\decorators\cache.py", line 44, in _wrapped_view_func
    response = view_func(request, *args, **kwargs)
  File "D:\development\Python\lib\site-packages\django\contrib\admin\sites.py", line 223, in inner
    return view(request, *args, **kwargs)
  File "D:\development\Python\lib\site-packages\django\utils\decorators.py", line 45, in _wrapper
    return bound_method(*args, **kwargs)
  File "D:\development\Python\lib\site-packages\django\utils\decorators.py", line 142, in _wrapped_view
    response = view_func(request, *args, **kwargs)
  File "D:\development\Python\lib\site-packages\django\contrib\admin\options.py", line 1672, in changelist_view
    cl = self.get_changelist_instance(request)
  File "D:\development\Python\lib\site-packages\django\contrib\admin\options.py", line 744, in get_changelist_instance
    sortable_by,
  File "D:\development\Python\lib\site-packages\django\contrib\admin\views\main.py", line 81, in __init__
    self.queryset = self.get_queryset(request)
  File "D:\development\Python\lib\site-packages\django\contrib\admin\views\main.py", line 405, in get_queryset
    filters_use_distinct) = self.get_filters(request)
  File "D:\development\Python\lib\site-packages\django\contrib\admin\views\main.py", line 135, in get_filters
    self.model, self.model_admin, field_path=field_path,
  File "D:\development\Python\lib\site-packages\django\contrib\admin\filters.py", line 159, in create
    return list_filter_class(field, request, params, model, model_admin, field_path=field_path)
  File "D:\development\Python\lib\site-packages\django\contrib\admin\filters.py", line 170, in __init__
    self.lookup_choices = self.field_choices(field, request, model_admin)
  File "D:\development\Python\lib\site-packages\django\contrib\admin\filters.py", line 201, in field_choices
    return field.get_choices(include_blank=False, ordering=ordering)
  File "D:\development\Python\lib\site-packages\django\db\models\fields\__init__.py", line 831, in get_choices
    for x in rel_model._default_manager.complex_filter(limit_choices_to).order_by(*ordering)
  File "D:\development\Python\lib\site-packages\django\db\models\query.py", line 274, in __iter__
    self._fetch_all()
  File "D:\development\Python\lib\site-packages\django\db\models\query.py", line 1242, in _fetch_all
    self._result_cache = list(self._iterable_class(self))
  File "D:\development\Python\lib\site-packages\django\db\models\query.py", line 55, in __iter__
    results = compiler.execute_sql(chunked_fetch=self.chunked_fetch, chunk_size=self.chunk_size)
  File "D:\development\Python\lib\site-packages\django\db\models\sql\compiler.py", line 1097, in execute_sql
    cursor.execute(sql, params)
  File "D:\development\Python\lib\site-packages\django\db\backends\utils.py", line 99, in execute
    return super().execute(sql, params)
  File "D:\development\Python\lib\site-packages\django\db\backends\utils.py", line 67, in execute
    return self._execute_with_wrappers(sql, params, many=False, executor=self._execute)
  File "D:\development\Python\lib\site-packages\django\db\backends\utils.py", line 76, in _execute_with_wrappers
    return executor(sql, params, many, context)
  File "D:\development\Python\lib\site-packages\django\db\backends\utils.py", line 84, in _execute
    return self.cursor.execute(sql, params)
  File "D:\development\Python\lib\site-packages\django\db\utils.py", line 89, in __exit__
    raise dj_exc_value.with_traceback(traceback) from exc_value
  File "D:\development\Python\lib\site-packages\django\db\backends\utils.py", line 84, in _execute
    return self.cursor.execute(sql, params)
  File "D:\development\Python\lib\site-packages\django\db\backends\mysql\base.py", line 71, in execute
    return self.cursor.execute(query, args)
  File "D:\development\Python\lib\site-packages\pymysql\cursors.py", line 170, in execute
    result = self._query(query)
  File "D:\development\Python\lib\site-packages\pymysql\cursors.py", line 328, in _query
    conn.query(q)
  File "D:\development\Python\lib\site-packages\pymysql\connections.py", line 517, in query
    self._affected_rows = self._read_query_result(unbuffered=unbuffered)
  File "D:\development\Python\lib\site-packages\pymysql\connections.py", line 732, in _read_query_result
    result.read()
  File "D:\development\Python\lib\site-packages\pymysql\connections.py", line 1075, in read
    first_packet = self.connection._read_packet()
  File "D:\development\Python\lib\site-packages\pymysql\connections.py", line 684, in _read_packet
    packet.check_error()
  File "D:\development\Python\lib\site-packages\pymysql\protocol.py", line 220, in check_error
    err.raise_mysql_exception(self._data)
  File "D:\development\Python\lib\site-packages\pymysql\err.py", line 109, in raise_mysql_exception
    raise errorclass(errno, errval)
django.db.utils.InternalError: (1054, "Unknown column 'rank.subject_id' in 'field list'")
2019-05-13 01:27:42,401 [Thread-3:6356] [django.request:228] [log:log_response] [ERROR]- Internal Server Error: /admin/application/rank/
Traceback (most recent call last):
  File "D:\development\Python\lib\site-packages\django\db\backends\utils.py", line 84, in _execute
    return self.cursor.execute(sql, params)
  File "D:\development\Python\lib\site-packages\django\db\backends\mysql\base.py", line 71, in execute
    return self.cursor.execute(query, args)
  File "D:\development\Python\lib\site-packages\pymysql\cursors.py", line 170, in execute
    result = self._query(query)
  File "D:\development\Python\lib\site-packages\pymysql\cursors.py", line 328, in _query
    conn.query(q)
  File "D:\development\Python\lib\site-packages\pymysql\connections.py", line 517, in query
    self._affected_rows = self._read_query_result(unbuffered=unbuffered)
  File "D:\development\Python\lib\site-packages\pymysql\connections.py", line 732, in _read_query_result
    result.read()
  File "D:\development\Python\lib\site-packages\pymysql\connections.py", line 1075, in read
    first_packet = self.connection._read_packet()
  File "D:\development\Python\lib\site-packages\pymysql\connections.py", line 684, in _read_packet
    packet.check_error()
  File "D:\development\Python\lib\site-packages\pymysql\protocol.py", line 220, in check_error
    err.raise_mysql_exception(self._data)
  File "D:\development\Python\lib\site-packages\pymysql\err.py", line 109, in raise_mysql_exception
    raise errorclass(errno, errval)
pymysql.err.ProgrammingError: (1146, "Table 'plant.subject' doesn't exist")

The above exception was the direct cause of the following exception:

Traceback (most recent call last):
  File "D:\development\Python\lib\site-packages\django\core\handlers\exception.py", line 34, in inner
    response = get_response(request)
  File "D:\development\Python\lib\site-packages\django\core\handlers\base.py", line 115, in _get_response
    response = self.process_exception_by_middleware(e, request)
  File "D:\development\Python\lib\site-packages\django\core\handlers\base.py", line 113, in _get_response
    response = wrapped_callback(request, *callback_args, **callback_kwargs)
  File "D:\development\Python\lib\site-packages\django\contrib\admin\options.py", line 606, in wrapper
    return self.admin_site.admin_view(view)(*args, **kwargs)
  File "D:\development\Python\lib\site-packages\django\utils\decorators.py", line 142, in _wrapped_view
    response = view_func(request, *args, **kwargs)
  File "D:\development\Python\lib\site-packages\django\views\decorators\cache.py", line 44, in _wrapped_view_func
    response = view_func(request, *args, **kwargs)
  File "D:\development\Python\lib\site-packages\django\contrib\admin\sites.py", line 223, in inner
    return view(request, *args, **kwargs)
  File "D:\development\Python\lib\site-packages\django\utils\decorators.py", line 45, in _wrapper
    return bound_method(*args, **kwargs)
  File "D:\development\Python\lib\site-packages\django\utils\decorators.py", line 142, in _wrapped_view
    response = view_func(request, *args, **kwargs)
  File "D:\development\Python\lib\site-packages\django\contrib\admin\options.py", line 1672, in changelist_view
    cl = self.get_changelist_instance(request)
  File "D:\development\Python\lib\site-packages\django\contrib\admin\options.py", line 744, in get_changelist_instance
    sortable_by,
  File "D:\development\Python\lib\site-packages\django\contrib\admin\views\main.py", line 81, in __init__
    self.queryset = self.get_queryset(request)
  File "D:\development\Python\lib\site-packages\django\contrib\admin\views\main.py", line 405, in get_queryset
    filters_use_distinct) = self.get_filters(request)
  File "D:\development\Python\lib\site-packages\django\contrib\admin\views\main.py", line 135, in get_filters
    self.model, self.model_admin, field_path=field_path,
  File "D:\development\Python\lib\site-packages\django\contrib\admin\filters.py", line 159, in create
    return list_filter_class(field, request, params, model, model_admin, field_path=field_path)
  File "D:\development\Python\lib\site-packages\django\contrib\admin\filters.py", line 170, in __init__
    self.lookup_choices = self.field_choices(field, request, model_admin)
  File "D:\development\Python\lib\site-packages\django\contrib\admin\filters.py", line 201, in field_choices
    return field.get_choices(include_blank=False, ordering=ordering)
  File "D:\development\Python\lib\site-packages\django\db\models\fields\__init__.py", line 831, in get_choices
    for x in rel_model._default_manager.complex_filter(limit_choices_to).order_by(*ordering)
  File "D:\development\Python\lib\site-packages\django\db\models\query.py", line 274, in __iter__
    self._fetch_all()
  File "D:\development\Python\lib\site-packages\django\db\models\query.py", line 1242, in _fetch_all
    self._result_cache = list(self._iterable_class(self))
  File "D:\development\Python\lib\site-packages\django\db\models\query.py", line 55, in __iter__
    results = compiler.execute_sql(chunked_fetch=self.chunked_fetch, chunk_size=self.chunk_size)
  File "D:\development\Python\lib\site-packages\django\db\models\sql\compiler.py", line 1097, in execute_sql
    cursor.execute(sql, params)
  File "D:\development\Python\lib\site-packages\django\db\backends\utils.py", line 99, in execute
    return super().execute(sql, params)
  File "D:\development\Python\lib\site-packages\django\db\backends\utils.py", line 67, in execute
    return self._execute_with_wrappers(sql, params, many=False, executor=self._execute)
  File "D:\development\Python\lib\site-packages\django\db\backends\utils.py", line 76, in _execute_with_wrappers
    return executor(sql, params, many, context)
  File "D:\development\Python\lib\site-packages\django\db\backends\utils.py", line 84, in _execute
    return self.cursor.execute(sql, params)
  File "D:\development\Python\lib\site-packages\django\db\utils.py", line 89, in __exit__
    raise dj_exc_value.with_traceback(traceback) from exc_value
  File "D:\development\Python\lib\site-packages\django\db\backends\utils.py", line 84, in _execute
    return self.cursor.execute(sql, params)
  File "D:\development\Python\lib\site-packages\django\db\backends\mysql\base.py", line 71, in execute
    return self.cursor.execute(query, args)
  File "D:\development\Python\lib\site-packages\pymysql\cursors.py", line 170, in execute
    result = self._query(query)
  File "D:\development\Python\lib\site-packages\pymysql\cursors.py", line 328, in _query
    conn.query(q)
  File "D:\development\Python\lib\site-packages\pymysql\connections.py", line 517, in query
    self._affected_rows = self._read_query_result(unbuffered=unbuffered)
  File "D:\development\Python\lib\site-packages\pymysql\connections.py", line 732, in _read_query_result
    result.read()
  File "D:\development\Python\lib\site-packages\pymysql\connections.py", line 1075, in read
    first_packet = self.connection._read_packet()
  File "D:\development\Python\lib\site-packages\pymysql\connections.py", line 684, in _read_packet
    packet.check_error()
  File "D:\development\Python\lib\site-packages\pymysql\protocol.py", line 220, in check_error
    err.raise_mysql_exception(self._data)
  File "D:\development\Python\lib\site-packages\pymysql\err.py", line 109, in raise_mysql_exception
    raise errorclass(errno, errval)
django.db.utils.ProgrammingError: (1146, "Table 'plant.subject' doesn't exist")
2019-05-13 01:29:14,252 [Thread-2:15844] [django.request:228] [log:log_response] [ERROR]- Internal Server Error: /admin/application/subject/
Traceback (most recent call last):
  File "D:\development\Python\lib\site-packages\django\db\backends\utils.py", line 84, in _execute
    return self.cursor.execute(sql, params)
  File "D:\development\Python\lib\site-packages\django\db\backends\mysql\base.py", line 71, in execute
    return self.cursor.execute(query, args)
  File "D:\development\Python\lib\site-packages\pymysql\cursors.py", line 170, in execute
    result = self._query(query)
  File "D:\development\Python\lib\site-packages\pymysql\cursors.py", line 328, in _query
    conn.query(q)
  File "D:\development\Python\lib\site-packages\pymysql\connections.py", line 517, in query
    self._affected_rows = self._read_query_result(unbuffered=unbuffered)
  File "D:\development\Python\lib\site-packages\pymysql\connections.py", line 732, in _read_query_result
    result.read()
  File "D:\development\Python\lib\site-packages\pymysql\connections.py", line 1075, in read
    first_packet = self.connection._read_packet()
  File "D:\development\Python\lib\site-packages\pymysql\connections.py", line 684, in _read_packet
    packet.check_error()
  File "D:\development\Python\lib\site-packages\pymysql\protocol.py", line 220, in check_error
    err.raise_mysql_exception(self._data)
  File "D:\development\Python\lib\site-packages\pymysql\err.py", line 109, in raise_mysql_exception
    raise errorclass(errno, errval)
pymysql.err.ProgrammingError: (1146, "Table 'plant.subject' doesn't exist")

The above exception was the direct cause of the following exception:

Traceback (most recent call last):
  File "D:\development\Python\lib\site-packages\django\core\handlers\exception.py", line 34, in inner
    response = get_response(request)
  File "D:\development\Python\lib\site-packages\django\core\handlers\base.py", line 115, in _get_response
    response = self.process_exception_by_middleware(e, request)
  File "D:\development\Python\lib\site-packages\django\core\handlers\base.py", line 113, in _get_response
    response = wrapped_callback(request, *callback_args, **callback_kwargs)
  File "D:\development\Python\lib\site-packages\django\contrib\admin\options.py", line 606, in wrapper
    return self.admin_site.admin_view(view)(*args, **kwargs)
  File "D:\development\Python\lib\site-packages\django\utils\decorators.py", line 142, in _wrapped_view
    response = view_func(request, *args, **kwargs)
  File "D:\development\Python\lib\site-packages\django\views\decorators\cache.py", line 44, in _wrapped_view_func
    response = view_func(request, *args, **kwargs)
  File "D:\development\Python\lib\site-packages\django\contrib\admin\sites.py", line 223, in inner
    return view(request, *args, **kwargs)
  File "D:\development\Python\lib\site-packages\django\utils\decorators.py", line 45, in _wrapper
    return bound_method(*args, **kwargs)
  File "D:\development\Python\lib\site-packages\django\utils\decorators.py", line 142, in _wrapped_view
    response = view_func(request, *args, **kwargs)
  File "D:\development\Python\lib\site-packages\django\contrib\admin\options.py", line 1672, in changelist_view
    cl = self.get_changelist_instance(request)
  File "D:\development\Python\lib\site-packages\django\contrib\admin\options.py", line 744, in get_changelist_instance
    sortable_by,
  File "D:\development\Python\lib\site-packages\django\contrib\admin\views\main.py", line 82, in __init__
    self.get_results(request)
  File "D:\development\Python\lib\site-packages\django\contrib\admin\views\main.py", line 210, in get_results
    result_count = paginator.count
  File "D:\development\Python\lib\site-packages\django\utils\functional.py", line 80, in __get__
    res = instance.__dict__[self.name] = self.func(instance)
  File "D:\development\Python\lib\site-packages\django\core\paginator.py", line 91, in count
    return c()
  File "D:\development\Python\lib\site-packages\django\db\models\query.py", line 392, in count
    return self.query.get_count(using=self.db)
  File "D:\development\Python\lib\site-packages\django\db\models\sql\query.py", line 504, in get_count
    number = obj.get_aggregation(using, ['__count'])['__count']
  File "D:\development\Python\lib\site-packages\django\db\models\sql\query.py", line 489, in get_aggregation
    result = compiler.execute_sql(SINGLE)
  File "D:\development\Python\lib\site-packages\django\db\models\sql\compiler.py", line 1097, in execute_sql
    cursor.execute(sql, params)
  File "D:\development\Python\lib\site-packages\django\db\backends\utils.py", line 99, in execute
    return super().execute(sql, params)
  File "D:\development\Python\lib\site-packages\django\db\backends\utils.py", line 67, in execute
    return self._execute_with_wrappers(sql, params, many=False, executor=self._execute)
  File "D:\development\Python\lib\site-packages\django\db\backends\utils.py", line 76, in _execute_with_wrappers
    return executor(sql, params, many, context)
  File "D:\development\Python\lib\site-packages\django\db\backends\utils.py", line 84, in _execute
    return self.cursor.execute(sql, params)
  File "D:\development\Python\lib\site-packages\django\db\utils.py", line 89, in __exit__
    raise dj_exc_value.with_traceback(traceback) from exc_value
  File "D:\development\Python\lib\site-packages\django\db\backends\utils.py", line 84, in _execute
    return self.cursor.execute(sql, params)
  File "D:\development\Python\lib\site-packages\django\db\backends\mysql\base.py", line 71, in execute
    return self.cursor.execute(query, args)
  File "D:\development\Python\lib\site-packages\pymysql\cursors.py", line 170, in execute
    result = self._query(query)
  File "D:\development\Python\lib\site-packages\pymysql\cursors.py", line 328, in _query
    conn.query(q)
  File "D:\development\Python\lib\site-packages\pymysql\connections.py", line 517, in query
    self._affected_rows = self._read_query_result(unbuffered=unbuffered)
  File "D:\development\Python\lib\site-packages\pymysql\connections.py", line 732, in _read_query_result
    result.read()
  File "D:\development\Python\lib\site-packages\pymysql\connections.py", line 1075, in read
    first_packet = self.connection._read_packet()
  File "D:\development\Python\lib\site-packages\pymysql\connections.py", line 684, in _read_packet
    packet.check_error()
  File "D:\development\Python\lib\site-packages\pymysql\protocol.py", line 220, in check_error
    err.raise_mysql_exception(self._data)
  File "D:\development\Python\lib\site-packages\pymysql\err.py", line 109, in raise_mysql_exception
    raise errorclass(errno, errval)
django.db.utils.ProgrammingError: (1146, "Table 'plant.subject' doesn't exist")
2019-05-13 01:29:18,387 [Thread-2:15844] [django.request:228] [log:log_response] [ERROR]- Internal Server Error: /admin/application/vote/
Traceback (most recent call last):
  File "D:\development\Python\lib\site-packages\django\db\backends\utils.py", line 84, in _execute
    return self.cursor.execute(sql, params)
  File "D:\development\Python\lib\site-packages\django\db\backends\mysql\base.py", line 71, in execute
    return self.cursor.execute(query, args)
  File "D:\development\Python\lib\site-packages\pymysql\cursors.py", line 170, in execute
    result = self._query(query)
  File "D:\development\Python\lib\site-packages\pymysql\cursors.py", line 328, in _query
    conn.query(q)
  File "D:\development\Python\lib\site-packages\pymysql\connections.py", line 517, in query
    self._affected_rows = self._read_query_result(unbuffered=unbuffered)
  File "D:\development\Python\lib\site-packages\pymysql\connections.py", line 732, in _read_query_result
    result.read()
  File "D:\development\Python\lib\site-packages\pymysql\connections.py", line 1075, in read
    first_packet = self.connection._read_packet()
  File "D:\development\Python\lib\site-packages\pymysql\connections.py", line 684, in _read_packet
    packet.check_error()
  File "D:\development\Python\lib\site-packages\pymysql\protocol.py", line 220, in check_error
    err.raise_mysql_exception(self._data)
  File "D:\development\Python\lib\site-packages\pymysql\err.py", line 109, in raise_mysql_exception
    raise errorclass(errno, errval)
pymysql.err.InternalError: (1054, "Unknown column 'rank.subject_id' in 'field list'")

The above exception was the direct cause of the following exception:

Traceback (most recent call last):
  File "D:\development\Python\lib\site-packages\django\core\handlers\exception.py", line 34, in inner
    response = get_response(request)
  File "D:\development\Python\lib\site-packages\django\core\handlers\base.py", line 115, in _get_response
    response = self.process_exception_by_middleware(e, request)
  File "D:\development\Python\lib\site-packages\django\core\handlers\base.py", line 113, in _get_response
    response = wrapped_callback(request, *callback_args, **callback_kwargs)
  File "D:\development\Python\lib\site-packages\django\contrib\admin\options.py", line 606, in wrapper
    return self.admin_site.admin_view(view)(*args, **kwargs)
  File "D:\development\Python\lib\site-packages\django\utils\decorators.py", line 142, in _wrapped_view
    response = view_func(request, *args, **kwargs)
  File "D:\development\Python\lib\site-packages\django\views\decorators\cache.py", line 44, in _wrapped_view_func
    response = view_func(request, *args, **kwargs)
  File "D:\development\Python\lib\site-packages\django\contrib\admin\sites.py", line 223, in inner
    return view(request, *args, **kwargs)
  File "D:\development\Python\lib\site-packages\django\utils\decorators.py", line 45, in _wrapper
    return bound_method(*args, **kwargs)
  File "D:\development\Python\lib\site-packages\django\utils\decorators.py", line 142, in _wrapped_view
    response = view_func(request, *args, **kwargs)
  File "D:\development\Python\lib\site-packages\django\contrib\admin\options.py", line 1672, in changelist_view
    cl = self.get_changelist_instance(request)
  File "D:\development\Python\lib\site-packages\django\contrib\admin\options.py", line 744, in get_changelist_instance
    sortable_by,
  File "D:\development\Python\lib\site-packages\django\contrib\admin\views\main.py", line 81, in __init__
    self.queryset = self.get_queryset(request)
  File "D:\development\Python\lib\site-packages\django\contrib\admin\views\main.py", line 405, in get_queryset
    filters_use_distinct) = self.get_filters(request)
  File "D:\development\Python\lib\site-packages\django\contrib\admin\views\main.py", line 135, in get_filters
    self.model, self.model_admin, field_path=field_path,
  File "D:\development\Python\lib\site-packages\django\contrib\admin\filters.py", line 159, in create
    return list_filter_class(field, request, params, model, model_admin, field_path=field_path)
  File "D:\development\Python\lib\site-packages\django\contrib\admin\filters.py", line 170, in __init__
    self.lookup_choices = self.field_choices(field, request, model_admin)
  File "D:\development\Python\lib\site-packages\django\contrib\admin\filters.py", line 201, in field_choices
    return field.get_choices(include_blank=False, ordering=ordering)
  File "D:\development\Python\lib\site-packages\django\db\models\fields\__init__.py", line 831, in get_choices
    for x in rel_model._default_manager.complex_filter(limit_choices_to).order_by(*ordering)
  File "D:\development\Python\lib\site-packages\django\db\models\query.py", line 274, in __iter__
    self._fetch_all()
  File "D:\development\Python\lib\site-packages\django\db\models\query.py", line 1242, in _fetch_all
    self._result_cache = list(self._iterable_class(self))
  File "D:\development\Python\lib\site-packages\django\db\models\query.py", line 55, in __iter__
    results = compiler.execute_sql(chunked_fetch=self.chunked_fetch, chunk_size=self.chunk_size)
  File "D:\development\Python\lib\site-packages\django\db\models\sql\compiler.py", line 1097, in execute_sql
    cursor.execute(sql, params)
  File "D:\development\Python\lib\site-packages\django\db\backends\utils.py", line 99, in execute
    return super().execute(sql, params)
  File "D:\development\Python\lib\site-packages\django\db\backends\utils.py", line 67, in execute
    return self._execute_with_wrappers(sql, params, many=False, executor=self._execute)
  File "D:\development\Python\lib\site-packages\django\db\backends\utils.py", line 76, in _execute_with_wrappers
    return executor(sql, params, many, context)
  File "D:\development\Python\lib\site-packages\django\db\backends\utils.py", line 84, in _execute
    return self.cursor.execute(sql, params)
  File "D:\development\Python\lib\site-packages\django\db\utils.py", line 89, in __exit__
    raise dj_exc_value.with_traceback(traceback) from exc_value
  File "D:\development\Python\lib\site-packages\django\db\backends\utils.py", line 84, in _execute
    return self.cursor.execute(sql, params)
  File "D:\development\Python\lib\site-packages\django\db\backends\mysql\base.py", line 71, in execute
    return self.cursor.execute(query, args)
  File "D:\development\Python\lib\site-packages\pymysql\cursors.py", line 170, in execute
    result = self._query(query)
  File "D:\development\Python\lib\site-packages\pymysql\cursors.py", line 328, in _query
    conn.query(q)
  File "D:\development\Python\lib\site-packages\pymysql\connections.py", line 517, in query
    self._affected_rows = self._read_query_result(unbuffered=unbuffered)
  File "D:\development\Python\lib\site-packages\pymysql\connections.py", line 732, in _read_query_result
    result.read()
  File "D:\development\Python\lib\site-packages\pymysql\connections.py", line 1075, in read
    first_packet = self.connection._read_packet()
  File "D:\development\Python\lib\site-packages\pymysql\connections.py", line 684, in _read_packet
    packet.check_error()
  File "D:\development\Python\lib\site-packages\pymysql\protocol.py", line 220, in check_error
    err.raise_mysql_exception(self._data)
  File "D:\development\Python\lib\site-packages\pymysql\err.py", line 109, in raise_mysql_exception
    raise errorclass(errno, errval)
django.db.utils.InternalError: (1054, "Unknown column 'rank.subject_id' in 'field list'")
2019-05-13 01:29:23,243 [Thread-2:15844] [django.request:228] [log:log_response] [ERROR]- Internal Server Error: /admin/application/rank/
Traceback (most recent call last):
  File "D:\development\Python\lib\site-packages\django\db\backends\utils.py", line 84, in _execute
    return self.cursor.execute(sql, params)
  File "D:\development\Python\lib\site-packages\django\db\backends\mysql\base.py", line 71, in execute
    return self.cursor.execute(query, args)
  File "D:\development\Python\lib\site-packages\pymysql\cursors.py", line 170, in execute
    result = self._query(query)
  File "D:\development\Python\lib\site-packages\pymysql\cursors.py", line 328, in _query
    conn.query(q)
  File "D:\development\Python\lib\site-packages\pymysql\connections.py", line 517, in query
    self._affected_rows = self._read_query_result(unbuffered=unbuffered)
  File "D:\development\Python\lib\site-packages\pymysql\connections.py", line 732, in _read_query_result
    result.read()
  File "D:\development\Python\lib\site-packages\pymysql\connections.py", line 1075, in read
    first_packet = self.connection._read_packet()
  File "D:\development\Python\lib\site-packages\pymysql\connections.py", line 684, in _read_packet
    packet.check_error()
  File "D:\development\Python\lib\site-packages\pymysql\protocol.py", line 220, in check_error
    err.raise_mysql_exception(self._data)
  File "D:\development\Python\lib\site-packages\pymysql\err.py", line 109, in raise_mysql_exception
    raise errorclass(errno, errval)
pymysql.err.ProgrammingError: (1146, "Table 'plant.subject' doesn't exist")

The above exception was the direct cause of the following exception:

Traceback (most recent call last):
  File "D:\development\Python\lib\site-packages\django\core\handlers\exception.py", line 34, in inner
    response = get_response(request)
  File "D:\development\Python\lib\site-packages\django\core\handlers\base.py", line 115, in _get_response
    response = self.process_exception_by_middleware(e, request)
  File "D:\development\Python\lib\site-packages\django\core\handlers\base.py", line 113, in _get_response
    response = wrapped_callback(request, *callback_args, **callback_kwargs)
  File "D:\development\Python\lib\site-packages\django\contrib\admin\options.py", line 606, in wrapper
    return self.admin_site.admin_view(view)(*args, **kwargs)
  File "D:\development\Python\lib\site-packages\django\utils\decorators.py", line 142, in _wrapped_view
    response = view_func(request, *args, **kwargs)
  File "D:\development\Python\lib\site-packages\django\views\decorators\cache.py", line 44, in _wrapped_view_func
    response = view_func(request, *args, **kwargs)
  File "D:\development\Python\lib\site-packages\django\contrib\admin\sites.py", line 223, in inner
    return view(request, *args, **kwargs)
  File "D:\development\Python\lib\site-packages\django\utils\decorators.py", line 45, in _wrapper
    return bound_method(*args, **kwargs)
  File "D:\development\Python\lib\site-packages\django\utils\decorators.py", line 142, in _wrapped_view
    response = view_func(request, *args, **kwargs)
  File "D:\development\Python\lib\site-packages\django\contrib\admin\options.py", line 1672, in changelist_view
    cl = self.get_changelist_instance(request)
  File "D:\development\Python\lib\site-packages\django\contrib\admin\options.py", line 744, in get_changelist_instance
    sortable_by,
  File "D:\development\Python\lib\site-packages\django\contrib\admin\views\main.py", line 81, in __init__
    self.queryset = self.get_queryset(request)
  File "D:\development\Python\lib\site-packages\django\contrib\admin\views\main.py", line 405, in get_queryset
    filters_use_distinct) = self.get_filters(request)
  File "D:\development\Python\lib\site-packages\django\contrib\admin\views\main.py", line 135, in get_filters
    self.model, self.model_admin, field_path=field_path,
  File "D:\development\Python\lib\site-packages\django\contrib\admin\filters.py", line 159, in create
    return list_filter_class(field, request, params, model, model_admin, field_path=field_path)
  File "D:\development\Python\lib\site-packages\django\contrib\admin\filters.py", line 170, in __init__
    self.lookup_choices = self.field_choices(field, request, model_admin)
  File "D:\development\Python\lib\site-packages\django\contrib\admin\filters.py", line 201, in field_choices
    return field.get_choices(include_blank=False, ordering=ordering)
  File "D:\development\Python\lib\site-packages\django\db\models\fields\__init__.py", line 831, in get_choices
    for x in rel_model._default_manager.complex_filter(limit_choices_to).order_by(*ordering)
  File "D:\development\Python\lib\site-packages\django\db\models\query.py", line 274, in __iter__
    self._fetch_all()
  File "D:\development\Python\lib\site-packages\django\db\models\query.py", line 1242, in _fetch_all
    self._result_cache = list(self._iterable_class(self))
  File "D:\development\Python\lib\site-packages\django\db\models\query.py", line 55, in __iter__
    results = compiler.execute_sql(chunked_fetch=self.chunked_fetch, chunk_size=self.chunk_size)
  File "D:\development\Python\lib\site-packages\django\db\models\sql\compiler.py", line 1097, in execute_sql
    cursor.execute(sql, params)
  File "D:\development\Python\lib\site-packages\django\db\backends\utils.py", line 99, in execute
    return super().execute(sql, params)
  File "D:\development\Python\lib\site-packages\django\db\backends\utils.py", line 67, in execute
    return self._execute_with_wrappers(sql, params, many=False, executor=self._execute)
  File "D:\development\Python\lib\site-packages\django\db\backends\utils.py", line 76, in _execute_with_wrappers
    return executor(sql, params, many, context)
  File "D:\development\Python\lib\site-packages\django\db\backends\utils.py", line 84, in _execute
    return self.cursor.execute(sql, params)
  File "D:\development\Python\lib\site-packages\django\db\utils.py", line 89, in __exit__
    raise dj_exc_value.with_traceback(traceback) from exc_value
  File "D:\development\Python\lib\site-packages\django\db\backends\utils.py", line 84, in _execute
    return self.cursor.execute(sql, params)
  File "D:\development\Python\lib\site-packages\django\db\backends\mysql\base.py", line 71, in execute
    return self.cursor.execute(query, args)
  File "D:\development\Python\lib\site-packages\pymysql\cursors.py", line 170, in execute
    result = self._query(query)
  File "D:\development\Python\lib\site-packages\pymysql\cursors.py", line 328, in _query
    conn.query(q)
  File "D:\development\Python\lib\site-packages\pymysql\connections.py", line 517, in query
    self._affected_rows = self._read_query_result(unbuffered=unbuffered)
  File "D:\development\Python\lib\site-packages\pymysql\connections.py", line 732, in _read_query_result
    result.read()
  File "D:\development\Python\lib\site-packages\pymysql\connections.py", line 1075, in read
    first_packet = self.connection._read_packet()
  File "D:\development\Python\lib\site-packages\pymysql\connections.py", line 684, in _read_packet
    packet.check_error()
  File "D:\development\Python\lib\site-packages\pymysql\protocol.py", line 220, in check_error
    err.raise_mysql_exception(self._data)
  File "D:\development\Python\lib\site-packages\pymysql\err.py", line 109, in raise_mysql_exception
    raise errorclass(errno, errval)
django.db.utils.ProgrammingError: (1146, "Table 'plant.subject' doesn't exist")
2019-05-13 01:29:28,255 [Thread-2:15844] [django.request:228] [log:log_response] [ERROR]- Internal Server Error: /admin/application/vote/
Traceback (most recent call last):
  File "D:\development\Python\lib\site-packages\django\db\backends\utils.py", line 84, in _execute
    return self.cursor.execute(sql, params)
  File "D:\development\Python\lib\site-packages\django\db\backends\mysql\base.py", line 71, in execute
    return self.cursor.execute(query, args)
  File "D:\development\Python\lib\site-packages\pymysql\cursors.py", line 170, in execute
    result = self._query(query)
  File "D:\development\Python\lib\site-packages\pymysql\cursors.py", line 328, in _query
    conn.query(q)
  File "D:\development\Python\lib\site-packages\pymysql\connections.py", line 517, in query
    self._affected_rows = self._read_query_result(unbuffered=unbuffered)
  File "D:\development\Python\lib\site-packages\pymysql\connections.py", line 732, in _read_query_result
    result.read()
  File "D:\development\Python\lib\site-packages\pymysql\connections.py", line 1075, in read
    first_packet = self.connection._read_packet()
  File "D:\development\Python\lib\site-packages\pymysql\connections.py", line 684, in _read_packet
    packet.check_error()
  File "D:\development\Python\lib\site-packages\pymysql\protocol.py", line 220, in check_error
    err.raise_mysql_exception(self._data)
  File "D:\development\Python\lib\site-packages\pymysql\err.py", line 109, in raise_mysql_exception
    raise errorclass(errno, errval)
pymysql.err.InternalError: (1054, "Unknown column 'rank.subject_id' in 'field list'")

The above exception was the direct cause of the following exception:

Traceback (most recent call last):
  File "D:\development\Python\lib\site-packages\django\core\handlers\exception.py", line 34, in inner
    response = get_response(request)
  File "D:\development\Python\lib\site-packages\django\core\handlers\base.py", line 115, in _get_response
    response = self.process_exception_by_middleware(e, request)
  File "D:\development\Python\lib\site-packages\django\core\handlers\base.py", line 113, in _get_response
    response = wrapped_callback(request, *callback_args, **callback_kwargs)
  File "D:\development\Python\lib\site-packages\django\contrib\admin\options.py", line 606, in wrapper
    return self.admin_site.admin_view(view)(*args, **kwargs)
  File "D:\development\Python\lib\site-packages\django\utils\decorators.py", line 142, in _wrapped_view
    response = view_func(request, *args, **kwargs)
  File "D:\development\Python\lib\site-packages\django\views\decorators\cache.py", line 44, in _wrapped_view_func
    response = view_func(request, *args, **kwargs)
  File "D:\development\Python\lib\site-packages\django\contrib\admin\sites.py", line 223, in inner
    return view(request, *args, **kwargs)
  File "D:\development\Python\lib\site-packages\django\utils\decorators.py", line 45, in _wrapper
    return bound_method(*args, **kwargs)
  File "D:\development\Python\lib\site-packages\django\utils\decorators.py", line 142, in _wrapped_view
    response = view_func(request, *args, **kwargs)
  File "D:\development\Python\lib\site-packages\django\contrib\admin\options.py", line 1672, in changelist_view
    cl = self.get_changelist_instance(request)
  File "D:\development\Python\lib\site-packages\django\contrib\admin\options.py", line 744, in get_changelist_instance
    sortable_by,
  File "D:\development\Python\lib\site-packages\django\contrib\admin\views\main.py", line 81, in __init__
    self.queryset = self.get_queryset(request)
  File "D:\development\Python\lib\site-packages\django\contrib\admin\views\main.py", line 405, in get_queryset
    filters_use_distinct) = self.get_filters(request)
  File "D:\development\Python\lib\site-packages\django\contrib\admin\views\main.py", line 135, in get_filters
    self.model, self.model_admin, field_path=field_path,
  File "D:\development\Python\lib\site-packages\django\contrib\admin\filters.py", line 159, in create
    return list_filter_class(field, request, params, model, model_admin, field_path=field_path)
  File "D:\development\Python\lib\site-packages\django\contrib\admin\filters.py", line 170, in __init__
    self.lookup_choices = self.field_choices(field, request, model_admin)
  File "D:\development\Python\lib\site-packages\django\contrib\admin\filters.py", line 201, in field_choices
    return field.get_choices(include_blank=False, ordering=ordering)
  File "D:\development\Python\lib\site-packages\django\db\models\fields\__init__.py", line 831, in get_choices
    for x in rel_model._default_manager.complex_filter(limit_choices_to).order_by(*ordering)
  File "D:\development\Python\lib\site-packages\django\db\models\query.py", line 274, in __iter__
    self._fetch_all()
  File "D:\development\Python\lib\site-packages\django\db\models\query.py", line 1242, in _fetch_all
    self._result_cache = list(self._iterable_class(self))
  File "D:\development\Python\lib\site-packages\django\db\models\query.py", line 55, in __iter__
    results = compiler.execute_sql(chunked_fetch=self.chunked_fetch, chunk_size=self.chunk_size)
  File "D:\development\Python\lib\site-packages\django\db\models\sql\compiler.py", line 1097, in execute_sql
    cursor.execute(sql, params)
  File "D:\development\Python\lib\site-packages\django\db\backends\utils.py", line 99, in execute
    return super().execute(sql, params)
  File "D:\development\Python\lib\site-packages\django\db\backends\utils.py", line 67, in execute
    return self._execute_with_wrappers(sql, params, many=False, executor=self._execute)
  File "D:\development\Python\lib\site-packages\django\db\backends\utils.py", line 76, in _execute_with_wrappers
    return executor(sql, params, many, context)
  File "D:\development\Python\lib\site-packages\django\db\backends\utils.py", line 84, in _execute
    return self.cursor.execute(sql, params)
  File "D:\development\Python\lib\site-packages\django\db\utils.py", line 89, in __exit__
    raise dj_exc_value.with_traceback(traceback) from exc_value
  File "D:\development\Python\lib\site-packages\django\db\backends\utils.py", line 84, in _execute
    return self.cursor.execute(sql, params)
  File "D:\development\Python\lib\site-packages\django\db\backends\mysql\base.py", line 71, in execute
    return self.cursor.execute(query, args)
  File "D:\development\Python\lib\site-packages\pymysql\cursors.py", line 170, in execute
    result = self._query(query)
  File "D:\development\Python\lib\site-packages\pymysql\cursors.py", line 328, in _query
    conn.query(q)
  File "D:\development\Python\lib\site-packages\pymysql\connections.py", line 517, in query
    self._affected_rows = self._read_query_result(unbuffered=unbuffered)
  File "D:\development\Python\lib\site-packages\pymysql\connections.py", line 732, in _read_query_result
    result.read()
  File "D:\development\Python\lib\site-packages\pymysql\connections.py", line 1075, in read
    first_packet = self.connection._read_packet()
  File "D:\development\Python\lib\site-packages\pymysql\connections.py", line 684, in _read_packet
    packet.check_error()
  File "D:\development\Python\lib\site-packages\pymysql\protocol.py", line 220, in check_error
    err.raise_mysql_exception(self._data)
  File "D:\development\Python\lib\site-packages\pymysql\err.py", line 109, in raise_mysql_exception
    raise errorclass(errno, errval)
django.db.utils.InternalError: (1054, "Unknown column 'rank.subject_id' in 'field list'")
2019-05-13 02:47:03,290 [Thread-3:4264] [django.request:228] [log:log_response] [ERROR]- Internal Server Error: /admin/application/subject/add/
Traceback (most recent call last):
  File "D:\development\Python\lib\site-packages\django\db\backends\utils.py", line 84, in _execute
    return self.cursor.execute(sql, params)
  File "D:\development\Python\lib\site-packages\django\db\backends\mysql\base.py", line 71, in execute
    return self.cursor.execute(query, args)
  File "D:\development\Python\lib\site-packages\pymysql\cursors.py", line 170, in execute
    result = self._query(query)
  File "D:\development\Python\lib\site-packages\pymysql\cursors.py", line 328, in _query
    conn.query(q)
  File "D:\development\Python\lib\site-packages\pymysql\connections.py", line 517, in query
    self._affected_rows = self._read_query_result(unbuffered=unbuffered)
  File "D:\development\Python\lib\site-packages\pymysql\connections.py", line 732, in _read_query_result
    result.read()
  File "D:\development\Python\lib\site-packages\pymysql\connections.py", line 1075, in read
    first_packet = self.connection._read_packet()
  File "D:\development\Python\lib\site-packages\pymysql\connections.py", line 684, in _read_packet
    packet.check_error()
  File "D:\development\Python\lib\site-packages\pymysql\protocol.py", line 220, in check_error
    err.raise_mysql_exception(self._data)
  File "D:\development\Python\lib\site-packages\pymysql\err.py", line 109, in raise_mysql_exception
    raise errorclass(errno, errval)
pymysql.err.InternalError: (1366, "Incorrect string value: '\\xE6\\xB4\\xBB\\xE5\\x8A\\x9B' for column 'name' at row 1")

The above exception was the direct cause of the following exception:

Traceback (most recent call last):
  File "D:\development\Python\lib\site-packages\django\core\handlers\exception.py", line 34, in inner
    response = get_response(request)
  File "D:\development\Python\lib\site-packages\django\core\handlers\base.py", line 115, in _get_response
    response = self.process_exception_by_middleware(e, request)
  File "D:\development\Python\lib\site-packages\django\core\handlers\base.py", line 113, in _get_response
    response = wrapped_callback(request, *callback_args, **callback_kwargs)
  File "D:\development\Python\lib\site-packages\django\contrib\admin\options.py", line 606, in wrapper
    return self.admin_site.admin_view(view)(*args, **kwargs)
  File "D:\development\Python\lib\site-packages\django\utils\decorators.py", line 142, in _wrapped_view
    response = view_func(request, *args, **kwargs)
  File "D:\development\Python\lib\site-packages\django\views\decorators\cache.py", line 44, in _wrapped_view_func
    response = view_func(request, *args, **kwargs)
  File "D:\development\Python\lib\site-packages\django\contrib\admin\sites.py", line 223, in inner
    return view(request, *args, **kwargs)
  File "D:\development\Python\lib\site-packages\django\contrib\admin\options.py", line 1634, in add_view
    return self.changeform_view(request, None, form_url, extra_context)
  File "D:\development\Python\lib\site-packages\django\utils\decorators.py", line 45, in _wrapper
    return bound_method(*args, **kwargs)
  File "D:\development\Python\lib\site-packages\django\utils\decorators.py", line 142, in _wrapped_view
    response = view_func(request, *args, **kwargs)
  File "D:\development\Python\lib\site-packages\django\contrib\admin\options.py", line 1522, in changeform_view
    return self._changeform_view(request, object_id, form_url, extra_context)
  File "D:\development\Python\lib\site-packages\django\contrib\admin\options.py", line 1561, in _changeform_view
    self.save_model(request, new_object, form, not add)
  File "D:\development\Python\lib\site-packages\django\contrib\admin\options.py", line 1088, in save_model
    obj.save()
  File "D:\development\Python\lib\site-packages\django\db\models\base.py", line 741, in save
    force_update=force_update, update_fields=update_fields)
  File "D:\development\Python\lib\site-packages\django\db\models\base.py", line 779, in save_base
    force_update, using, update_fields,
  File "D:\development\Python\lib\site-packages\django\db\models\base.py", line 870, in _save_table
    result = self._do_insert(cls._base_manager, using, fields, update_pk, raw)
  File "D:\development\Python\lib\site-packages\django\db\models\base.py", line 908, in _do_insert
    using=using, raw=raw)
  File "D:\development\Python\lib\site-packages\django\db\models\manager.py", line 82, in manager_method
    return getattr(self.get_queryset(), name)(*args, **kwargs)
  File "D:\development\Python\lib\site-packages\django\db\models\query.py", line 1186, in _insert
    return query.get_compiler(using=using).execute_sql(return_id)
  File "D:\development\Python\lib\site-packages\django\db\models\sql\compiler.py", line 1332, in execute_sql
    cursor.execute(sql, params)
  File "D:\development\Python\lib\site-packages\django\db\backends\utils.py", line 99, in execute
    return super().execute(sql, params)
  File "D:\development\Python\lib\site-packages\django\db\backends\utils.py", line 67, in execute
    return self._execute_with_wrappers(sql, params, many=False, executor=self._execute)
  File "D:\development\Python\lib\site-packages\django\db\backends\utils.py", line 76, in _execute_with_wrappers
    return executor(sql, params, many, context)
  File "D:\development\Python\lib\site-packages\django\db\backends\utils.py", line 84, in _execute
    return self.cursor.execute(sql, params)
  File "D:\development\Python\lib\site-packages\django\db\utils.py", line 89, in __exit__
    raise dj_exc_value.with_traceback(traceback) from exc_value
  File "D:\development\Python\lib\site-packages\django\db\backends\utils.py", line 84, in _execute
    return self.cursor.execute(sql, params)
  File "D:\development\Python\lib\site-packages\django\db\backends\mysql\base.py", line 71, in execute
    return self.cursor.execute(query, args)
  File "D:\development\Python\lib\site-packages\pymysql\cursors.py", line 170, in execute
    result = self._query(query)
  File "D:\development\Python\lib\site-packages\pymysql\cursors.py", line 328, in _query
    conn.query(q)
  File "D:\development\Python\lib\site-packages\pymysql\connections.py", line 517, in query
    self._affected_rows = self._read_query_result(unbuffered=unbuffered)
  File "D:\development\Python\lib\site-packages\pymysql\connections.py", line 732, in _read_query_result
    result.read()
  File "D:\development\Python\lib\site-packages\pymysql\connections.py", line 1075, in read
    first_packet = self.connection._read_packet()
  File "D:\development\Python\lib\site-packages\pymysql\connections.py", line 684, in _read_packet
    packet.check_error()
  File "D:\development\Python\lib\site-packages\pymysql\protocol.py", line 220, in check_error
    err.raise_mysql_exception(self._data)
  File "D:\development\Python\lib\site-packages\pymysql\err.py", line 109, in raise_mysql_exception
    raise errorclass(errno, errval)
django.db.utils.InternalError: (1366, "Incorrect string value: '\\xE6\\xB4\\xBB\\xE5\\x8A\\x9B' for column 'name' at row 1")
2019-05-13 02:48:10,050 [Thread-3:4264] [django.request:228] [log:log_response] [ERROR]- Internal Server Error: /admin/application/subject/add/
Traceback (most recent call last):
  File "D:\development\Python\lib\site-packages\django\db\backends\utils.py", line 84, in _execute
    return self.cursor.execute(sql, params)
  File "D:\development\Python\lib\site-packages\django\db\backends\mysql\base.py", line 71, in execute
    return self.cursor.execute(query, args)
  File "D:\development\Python\lib\site-packages\pymysql\cursors.py", line 170, in execute
    result = self._query(query)
  File "D:\development\Python\lib\site-packages\pymysql\cursors.py", line 328, in _query
    conn.query(q)
  File "D:\development\Python\lib\site-packages\pymysql\connections.py", line 517, in query
    self._affected_rows = self._read_query_result(unbuffered=unbuffered)
  File "D:\development\Python\lib\site-packages\pymysql\connections.py", line 732, in _read_query_result
    result.read()
  File "D:\development\Python\lib\site-packages\pymysql\connections.py", line 1075, in read
    first_packet = self.connection._read_packet()
  File "D:\development\Python\lib\site-packages\pymysql\connections.py", line 684, in _read_packet
    packet.check_error()
  File "D:\development\Python\lib\site-packages\pymysql\protocol.py", line 220, in check_error
    err.raise_mysql_exception(self._data)
  File "D:\development\Python\lib\site-packages\pymysql\err.py", line 109, in raise_mysql_exception
    raise errorclass(errno, errval)
pymysql.err.InternalError: (1366, "Incorrect string value: '\\xE5\\x93\\x88\\xE5\\x93\\x88...' for column 'name' at row 1")

The above exception was the direct cause of the following exception:

Traceback (most recent call last):
  File "D:\development\Python\lib\site-packages\django\core\handlers\exception.py", line 34, in inner
    response = get_response(request)
  File "D:\development\Python\lib\site-packages\django\core\handlers\base.py", line 115, in _get_response
    response = self.process_exception_by_middleware(e, request)
  File "D:\development\Python\lib\site-packages\django\core\handlers\base.py", line 113, in _get_response
    response = wrapped_callback(request, *callback_args, **callback_kwargs)
  File "D:\development\Python\lib\site-packages\django\contrib\admin\options.py", line 606, in wrapper
    return self.admin_site.admin_view(view)(*args, **kwargs)
  File "D:\development\Python\lib\site-packages\django\utils\decorators.py", line 142, in _wrapped_view
    response = view_func(request, *args, **kwargs)
  File "D:\development\Python\lib\site-packages\django\views\decorators\cache.py", line 44, in _wrapped_view_func
    response = view_func(request, *args, **kwargs)
  File "D:\development\Python\lib\site-packages\django\contrib\admin\sites.py", line 223, in inner
    return view(request, *args, **kwargs)
  File "D:\development\Python\lib\site-packages\django\contrib\admin\options.py", line 1634, in add_view
    return self.changeform_view(request, None, form_url, extra_context)
  File "D:\development\Python\lib\site-packages\django\utils\decorators.py", line 45, in _wrapper
    return bound_method(*args, **kwargs)
  File "D:\development\Python\lib\site-packages\django\utils\decorators.py", line 142, in _wrapped_view
    response = view_func(request, *args, **kwargs)
  File "D:\development\Python\lib\site-packages\django\contrib\admin\options.py", line 1522, in changeform_view
    return self._changeform_view(request, object_id, form_url, extra_context)
  File "D:\development\Python\lib\site-packages\django\contrib\admin\options.py", line 1561, in _changeform_view
    self.save_model(request, new_object, form, not add)
  File "D:\development\Python\lib\site-packages\django\contrib\admin\options.py", line 1088, in save_model
    obj.save()
  File "D:\development\Python\lib\site-packages\django\db\models\base.py", line 741, in save
    force_update=force_update, update_fields=update_fields)
  File "D:\development\Python\lib\site-packages\django\db\models\base.py", line 779, in save_base
    force_update, using, update_fields,
  File "D:\development\Python\lib\site-packages\django\db\models\base.py", line 870, in _save_table
    result = self._do_insert(cls._base_manager, using, fields, update_pk, raw)
  File "D:\development\Python\lib\site-packages\django\db\models\base.py", line 908, in _do_insert
    using=using, raw=raw)
  File "D:\development\Python\lib\site-packages\django\db\models\manager.py", line 82, in manager_method
    return getattr(self.get_queryset(), name)(*args, **kwargs)
  File "D:\development\Python\lib\site-packages\django\db\models\query.py", line 1186, in _insert
    return query.get_compiler(using=using).execute_sql(return_id)
  File "D:\development\Python\lib\site-packages\django\db\models\sql\compiler.py", line 1332, in execute_sql
    cursor.execute(sql, params)
  File "D:\development\Python\lib\site-packages\django\db\backends\utils.py", line 99, in execute
    return super().execute(sql, params)
  File "D:\development\Python\lib\site-packages\django\db\backends\utils.py", line 67, in execute
    return self._execute_with_wrappers(sql, params, many=False, executor=self._execute)
  File "D:\development\Python\lib\site-packages\django\db\backends\utils.py", line 76, in _execute_with_wrappers
    return executor(sql, params, many, context)
  File "D:\development\Python\lib\site-packages\django\db\backends\utils.py", line 84, in _execute
    return self.cursor.execute(sql, params)
  File "D:\development\Python\lib\site-packages\django\db\utils.py", line 89, in __exit__
    raise dj_exc_value.with_traceback(traceback) from exc_value
  File "D:\development\Python\lib\site-packages\django\db\backends\utils.py", line 84, in _execute
    return self.cursor.execute(sql, params)
  File "D:\development\Python\lib\site-packages\django\db\backends\mysql\base.py", line 71, in execute
    return self.cursor.execute(query, args)
  File "D:\development\Python\lib\site-packages\pymysql\cursors.py", line 170, in execute
    result = self._query(query)
  File "D:\development\Python\lib\site-packages\pymysql\cursors.py", line 328, in _query
    conn.query(q)
  File "D:\development\Python\lib\site-packages\pymysql\connections.py", line 517, in query
    self._affected_rows = self._read_query_result(unbuffered=unbuffered)
  File "D:\development\Python\lib\site-packages\pymysql\connections.py", line 732, in _read_query_result
    result.read()
  File "D:\development\Python\lib\site-packages\pymysql\connections.py", line 1075, in read
    first_packet = self.connection._read_packet()
  File "D:\development\Python\lib\site-packages\pymysql\connections.py", line 684, in _read_packet
    packet.check_error()
  File "D:\development\Python\lib\site-packages\pymysql\protocol.py", line 220, in check_error
    err.raise_mysql_exception(self._data)
  File "D:\development\Python\lib\site-packages\pymysql\err.py", line 109, in raise_mysql_exception
    raise errorclass(errno, errval)
django.db.utils.InternalError: (1366, "Incorrect string value: '\\xE5\\x93\\x88\\xE5\\x93\\x88...' for column 'name' at row 1")
2019-05-13 02:50:35,784 [Thread-3:4264] [django.request:228] [log:log_response] [ERROR]- Internal Server Error: /admin/application/user/add/
Traceback (most recent call last):
  File "D:\development\Python\lib\site-packages\django\db\backends\utils.py", line 84, in _execute
    return self.cursor.execute(sql, params)
  File "D:\development\Python\lib\site-packages\django\db\backends\mysql\base.py", line 71, in execute
    return self.cursor.execute(query, args)
  File "D:\development\Python\lib\site-packages\pymysql\cursors.py", line 170, in execute
    result = self._query(query)
  File "D:\development\Python\lib\site-packages\pymysql\cursors.py", line 328, in _query
    conn.query(q)
  File "D:\development\Python\lib\site-packages\pymysql\connections.py", line 517, in query
    self._affected_rows = self._read_query_result(unbuffered=unbuffered)
  File "D:\development\Python\lib\site-packages\pymysql\connections.py", line 732, in _read_query_result
    result.read()
  File "D:\development\Python\lib\site-packages\pymysql\connections.py", line 1075, in read
    first_packet = self.connection._read_packet()
  File "D:\development\Python\lib\site-packages\pymysql\connections.py", line 684, in _read_packet
    packet.check_error()
  File "D:\development\Python\lib\site-packages\pymysql\protocol.py", line 220, in check_error
    err.raise_mysql_exception(self._data)
  File "D:\development\Python\lib\site-packages\pymysql\err.py", line 109, in raise_mysql_exception
    raise errorclass(errno, errval)
pymysql.err.InternalError: (1267, "Illegal mix of collations (latin1_swedish_ci,IMPLICIT) and (utf8_general_ci,COERCIBLE) for operation '='")

The above exception was the direct cause of the following exception:

Traceback (most recent call last):
  File "D:\development\Python\lib\site-packages\django\core\handlers\exception.py", line 34, in inner
    response = get_response(request)
  File "D:\development\Python\lib\site-packages\django\core\handlers\base.py", line 115, in _get_response
    response = self.process_exception_by_middleware(e, request)
  File "D:\development\Python\lib\site-packages\django\core\handlers\base.py", line 113, in _get_response
    response = wrapped_callback(request, *callback_args, **callback_kwargs)
  File "D:\development\Python\lib\site-packages\django\contrib\admin\options.py", line 606, in wrapper
    return self.admin_site.admin_view(view)(*args, **kwargs)
  File "D:\development\Python\lib\site-packages\django\utils\decorators.py", line 142, in _wrapped_view
    response = view_func(request, *args, **kwargs)
  File "D:\development\Python\lib\site-packages\django\views\decorators\cache.py", line 44, in _wrapped_view_func
    response = view_func(request, *args, **kwargs)
  File "D:\development\Python\lib\site-packages\django\contrib\admin\sites.py", line 223, in inner
    return view(request, *args, **kwargs)
  File "D:\development\Python\lib\site-packages\django\contrib\admin\options.py", line 1634, in add_view
    return self.changeform_view(request, None, form_url, extra_context)
  File "D:\development\Python\lib\site-packages\django\utils\decorators.py", line 45, in _wrapper
    return bound_method(*args, **kwargs)
  File "D:\development\Python\lib\site-packages\django\utils\decorators.py", line 142, in _wrapped_view
    response = view_func(request, *args, **kwargs)
  File "D:\development\Python\lib\site-packages\django\contrib\admin\options.py", line 1522, in changeform_view
    return self._changeform_view(request, object_id, form_url, extra_context)
  File "D:\development\Python\lib\site-packages\django\contrib\admin\options.py", line 1554, in _changeform_view
    form_validated = form.is_valid()
  File "D:\development\Python\lib\site-packages\django\forms\forms.py", line 185, in is_valid
    return self.is_bound and not self.errors
  File "D:\development\Python\lib\site-packages\django\forms\forms.py", line 180, in errors
    self.full_clean()
  File "D:\development\Python\lib\site-packages\django\forms\forms.py", line 383, in full_clean
    self._post_clean()
  File "D:\development\Python\lib\site-packages\django\forms\models.py", line 409, in _post_clean
    self.validate_unique()
  File "D:\development\Python\lib\site-packages\django\forms\models.py", line 418, in validate_unique
    self.instance.validate_unique(exclude=exclude)
  File "D:\development\Python\lib\site-packages\django\db\models\base.py", line 980, in validate_unique
    errors = self._perform_unique_checks(unique_checks)
  File "D:\development\Python\lib\site-packages\django\db\models\base.py", line 1084, in _perform_unique_checks
    if qs.exists():
  File "D:\development\Python\lib\site-packages\django\db\models\query.py", line 766, in exists
    return self.query.has_results(using=self.db)
  File "D:\development\Python\lib\site-packages\django\db\models\sql\query.py", line 522, in has_results
    return compiler.has_results()
  File "D:\development\Python\lib\site-packages\django\db\models\sql\compiler.py", line 1067, in has_results
    return bool(self.execute_sql(SINGLE))
  File "D:\development\Python\lib\site-packages\django\db\models\sql\compiler.py", line 1097, in execute_sql
    cursor.execute(sql, params)
  File "D:\development\Python\lib\site-packages\django\db\backends\utils.py", line 99, in execute
    return super().execute(sql, params)
  File "D:\development\Python\lib\site-packages\django\db\backends\utils.py", line 67, in execute
    return self._execute_with_wrappers(sql, params, many=False, executor=self._execute)
  File "D:\development\Python\lib\site-packages\django\db\backends\utils.py", line 76, in _execute_with_wrappers
    return executor(sql, params, many, context)
  File "D:\development\Python\lib\site-packages\django\db\backends\utils.py", line 84, in _execute
    return self.cursor.execute(sql, params)
  File "D:\development\Python\lib\site-packages\django\db\utils.py", line 89, in __exit__
    raise dj_exc_value.with_traceback(traceback) from exc_value
  File "D:\development\Python\lib\site-packages\django\db\backends\utils.py", line 84, in _execute
    return self.cursor.execute(sql, params)
  File "D:\development\Python\lib\site-packages\django\db\backends\mysql\base.py", line 71, in execute
    return self.cursor.execute(query, args)
  File "D:\development\Python\lib\site-packages\pymysql\cursors.py", line 170, in execute
    result = self._query(query)
  File "D:\development\Python\lib\site-packages\pymysql\cursors.py", line 328, in _query
    conn.query(q)
  File "D:\development\Python\lib\site-packages\pymysql\connections.py", line 517, in query
    self._affected_rows = self._read_query_result(unbuffered=unbuffered)
  File "D:\development\Python\lib\site-packages\pymysql\connections.py", line 732, in _read_query_result
    result.read()
  File "D:\development\Python\lib\site-packages\pymysql\connections.py", line 1075, in read
    first_packet = self.connection._read_packet()
  File "D:\development\Python\lib\site-packages\pymysql\connections.py", line 684, in _read_packet
    packet.check_error()
  File "D:\development\Python\lib\site-packages\pymysql\protocol.py", line 220, in check_error
    err.raise_mysql_exception(self._data)
  File "D:\development\Python\lib\site-packages\pymysql\err.py", line 109, in raise_mysql_exception
    raise errorclass(errno, errval)
django.db.utils.InternalError: (1267, "Illegal mix of collations (latin1_swedish_ci,IMPLICIT) and (utf8_general_ci,COERCIBLE) for operation '='")
2019-05-13 02:55:19,238 [Thread-3:4264] [django.request:228] [log:log_response] [ERROR]- Internal Server Error: /admin/application/rank/add/
Traceback (most recent call last):
  File "D:\development\Python\lib\site-packages\django\core\handlers\exception.py", line 34, in inner
    response = get_response(request)
  File "D:\development\Python\lib\site-packages\django\core\handlers\base.py", line 115, in _get_response
    response = self.process_exception_by_middleware(e, request)
  File "D:\development\Python\lib\site-packages\django\core\handlers\base.py", line 113, in _get_response
    response = wrapped_callback(request, *callback_args, **callback_kwargs)
  File "D:\development\Python\lib\site-packages\django\contrib\admin\options.py", line 606, in wrapper
    return self.admin_site.admin_view(view)(*args, **kwargs)
  File "D:\development\Python\lib\site-packages\django\utils\decorators.py", line 142, in _wrapped_view
    response = view_func(request, *args, **kwargs)
  File "D:\development\Python\lib\site-packages\django\views\decorators\cache.py", line 44, in _wrapped_view_func
    response = view_func(request, *args, **kwargs)
  File "D:\development\Python\lib\site-packages\django\contrib\admin\sites.py", line 223, in inner
    return view(request, *args, **kwargs)
  File "D:\development\Python\lib\site-packages\django\contrib\admin\options.py", line 1634, in add_view
    return self.changeform_view(request, None, form_url, extra_context)
  File "D:\development\Python\lib\site-packages\django\utils\decorators.py", line 45, in _wrapper
    return bound_method(*args, **kwargs)
  File "D:\development\Python\lib\site-packages\django\utils\decorators.py", line 142, in _wrapped_view
    response = view_func(request, *args, **kwargs)
  File "D:\development\Python\lib\site-packages\django\contrib\admin\options.py", line 1522, in changeform_view
    return self._changeform_view(request, object_id, form_url, extra_context)
  File "D:\development\Python\lib\site-packages\django\contrib\admin\options.py", line 1565, in _changeform_view
    self.log_addition(request, new_object, change_message)
  File "D:\development\Python\lib\site-packages\django\contrib\admin\options.py", line 810, in log_addition
    object_repr=str(object),
TypeError: __str__ returned non-string (type Subject)
2019-05-13 03:00:46,698 [Thread-3:11140] [django.request:228] [log:log_response] [ERROR]- Internal Server Error: /admin/application/rank/add/
Traceback (most recent call last):
  File "D:\development\Python\lib\site-packages\django\core\handlers\exception.py", line 34, in inner
    response = get_response(request)
  File "D:\development\Python\lib\site-packages\django\core\handlers\base.py", line 115, in _get_response
    response = self.process_exception_by_middleware(e, request)
  File "D:\development\Python\lib\site-packages\django\core\handlers\base.py", line 113, in _get_response
    response = wrapped_callback(request, *callback_args, **callback_kwargs)
  File "D:\development\Python\lib\site-packages\django\contrib\admin\options.py", line 606, in wrapper
    return self.admin_site.admin_view(view)(*args, **kwargs)
  File "D:\development\Python\lib\site-packages\django\utils\decorators.py", line 142, in _wrapped_view
    response = view_func(request, *args, **kwargs)
  File "D:\development\Python\lib\site-packages\django\views\decorators\cache.py", line 44, in _wrapped_view_func
    response = view_func(request, *args, **kwargs)
  File "D:\development\Python\lib\site-packages\django\contrib\admin\sites.py", line 223, in inner
    return view(request, *args, **kwargs)
  File "D:\development\Python\lib\site-packages\django\contrib\admin\options.py", line 1634, in add_view
    return self.changeform_view(request, None, form_url, extra_context)
  File "D:\development\Python\lib\site-packages\django\utils\decorators.py", line 45, in _wrapper
    return bound_method(*args, **kwargs)
  File "D:\development\Python\lib\site-packages\django\utils\decorators.py", line 142, in _wrapped_view
    response = view_func(request, *args, **kwargs)
  File "D:\development\Python\lib\site-packages\django\contrib\admin\options.py", line 1522, in changeform_view
    return self._changeform_view(request, object_id, form_url, extra_context)
  File "D:\development\Python\lib\site-packages\django\contrib\admin\options.py", line 1565, in _changeform_view
    self.log_addition(request, new_object, change_message)
  File "D:\development\Python\lib\site-packages\django\contrib\admin\options.py", line 810, in log_addition
    object_repr=str(object),
  File "D:\workspace\workspace-python\plant\application\models.py", line 199, in __str__
    return Subject.objects.filter(id=self.subject).first().name
  File "D:\development\Python\lib\site-packages\django\db\models\manager.py", line 82, in manager_method
    return getattr(self.get_queryset(), name)(*args, **kwargs)
  File "D:\development\Python\lib\site-packages\django\db\models\query.py", line 892, in filter
    return self._filter_or_exclude(False, *args, **kwargs)
  File "D:\development\Python\lib\site-packages\django\db\models\query.py", line 910, in _filter_or_exclude
    clone.query.add_q(Q(*args, **kwargs))
  File "D:\development\Python\lib\site-packages\django\db\models\sql\query.py", line 1290, in add_q
    clause, _ = self._add_q(q_object, self.used_aliases)
  File "D:\development\Python\lib\site-packages\django\db\models\sql\query.py", line 1318, in _add_q
    split_subq=split_subq, simple_col=simple_col,
  File "D:\development\Python\lib\site-packages\django\db\models\sql\query.py", line 1251, in build_filter
    condition = self.build_lookup(lookups, col, value)
  File "D:\development\Python\lib\site-packages\django\db\models\sql\query.py", line 1116, in build_lookup
    lookup = lookup_class(lhs, rhs)
  File "D:\development\Python\lib\site-packages\django\db\models\lookups.py", line 20, in __init__
    self.rhs = self.get_prep_lookup()
  File "D:\development\Python\lib\site-packages\django\db\models\lookups.py", line 70, in get_prep_lookup
    return self.lhs.output_field.get_prep_value(self.rhs)
  File "D:\development\Python\lib\site-packages\django\db\models\fields\__init__.py", line 966, in get_prep_value
    return int(value)
TypeError: int() argument must be a string, a bytes-like object or a number, not 'Subject'
2019-05-13 03:03:25,174 [Thread-2:15776] [django.request:228] [log:log_response] [ERROR]- Internal Server Error: /admin/application/rank/add/
Traceback (most recent call last):
  File "D:\development\Python\lib\site-packages\django\core\handlers\exception.py", line 34, in inner
    response = get_response(request)
  File "D:\development\Python\lib\site-packages\django\core\handlers\base.py", line 115, in _get_response
    response = self.process_exception_by_middleware(e, request)
  File "D:\development\Python\lib\site-packages\django\core\handlers\base.py", line 113, in _get_response
    response = wrapped_callback(request, *callback_args, **callback_kwargs)
  File "D:\development\Python\lib\site-packages\django\contrib\admin\options.py", line 606, in wrapper
    return self.admin_site.admin_view(view)(*args, **kwargs)
  File "D:\development\Python\lib\site-packages\django\utils\decorators.py", line 142, in _wrapped_view
    response = view_func(request, *args, **kwargs)
  File "D:\development\Python\lib\site-packages\django\views\decorators\cache.py", line 44, in _wrapped_view_func
    response = view_func(request, *args, **kwargs)
  File "D:\development\Python\lib\site-packages\django\contrib\admin\sites.py", line 223, in inner
    return view(request, *args, **kwargs)
  File "D:\development\Python\lib\site-packages\django\contrib\admin\options.py", line 1634, in add_view
    return self.changeform_view(request, None, form_url, extra_context)
  File "D:\development\Python\lib\site-packages\django\utils\decorators.py", line 45, in _wrapper
    return bound_method(*args, **kwargs)
  File "D:\development\Python\lib\site-packages\django\utils\decorators.py", line 142, in _wrapped_view
    response = view_func(request, *args, **kwargs)
  File "D:\development\Python\lib\site-packages\django\contrib\admin\options.py", line 1522, in changeform_view
    return self._changeform_view(request, object_id, form_url, extra_context)
  File "D:\development\Python\lib\site-packages\django\contrib\admin\options.py", line 1565, in _changeform_view
    self.log_addition(request, new_object, change_message)
  File "D:\development\Python\lib\site-packages\django\contrib\admin\options.py", line 810, in log_addition
    object_repr=str(object),
  File "D:\workspace\workspace-python\plant\application\models.py", line 199, in __str__
    return Subject.objects.filter(id=self.subject).first()
  File "D:\development\Python\lib\site-packages\django\db\models\manager.py", line 82, in manager_method
    return getattr(self.get_queryset(), name)(*args, **kwargs)
  File "D:\development\Python\lib\site-packages\django\db\models\query.py", line 892, in filter
    return self._filter_or_exclude(False, *args, **kwargs)
  File "D:\development\Python\lib\site-packages\django\db\models\query.py", line 910, in _filter_or_exclude
    clone.query.add_q(Q(*args, **kwargs))
  File "D:\development\Python\lib\site-packages\django\db\models\sql\query.py", line 1290, in add_q
    clause, _ = self._add_q(q_object, self.used_aliases)
  File "D:\development\Python\lib\site-packages\django\db\models\sql\query.py", line 1318, in _add_q
    split_subq=split_subq, simple_col=simple_col,
  File "D:\development\Python\lib\site-packages\django\db\models\sql\query.py", line 1251, in build_filter
    condition = self.build_lookup(lookups, col, value)
  File "D:\development\Python\lib\site-packages\django\db\models\sql\query.py", line 1116, in build_lookup
    lookup = lookup_class(lhs, rhs)
  File "D:\development\Python\lib\site-packages\django\db\models\lookups.py", line 20, in __init__
    self.rhs = self.get_prep_lookup()
  File "D:\development\Python\lib\site-packages\django\db\models\lookups.py", line 70, in get_prep_lookup
    return self.lhs.output_field.get_prep_value(self.rhs)
  File "D:\development\Python\lib\site-packages\django\db\models\fields\__init__.py", line 966, in get_prep_value
    return int(value)
TypeError: int() argument must be a string, a bytes-like object or a number, not 'Subject'
2019-05-13 03:05:53,782 [Thread-3:15364] [django.request:228] [log:log_response] [ERROR]- Internal Server Error: /admin/application/rank/add/
Traceback (most recent call last):
  File "D:\development\Python\lib\site-packages\django\core\handlers\exception.py", line 34, in inner
    response = get_response(request)
  File "D:\development\Python\lib\site-packages\django\core\handlers\base.py", line 115, in _get_response
    response = self.process_exception_by_middleware(e, request)
  File "D:\development\Python\lib\site-packages\django\core\handlers\base.py", line 113, in _get_response
    response = wrapped_callback(request, *callback_args, **callback_kwargs)
  File "D:\development\Python\lib\site-packages\django\contrib\admin\options.py", line 606, in wrapper
    return self.admin_site.admin_view(view)(*args, **kwargs)
  File "D:\development\Python\lib\site-packages\django\utils\decorators.py", line 142, in _wrapped_view
    response = view_func(request, *args, **kwargs)
  File "D:\development\Python\lib\site-packages\django\views\decorators\cache.py", line 44, in _wrapped_view_func
    response = view_func(request, *args, **kwargs)
  File "D:\development\Python\lib\site-packages\django\contrib\admin\sites.py", line 223, in inner
    return view(request, *args, **kwargs)
  File "D:\development\Python\lib\site-packages\django\contrib\admin\options.py", line 1634, in add_view
    return self.changeform_view(request, None, form_url, extra_context)
  File "D:\development\Python\lib\site-packages\django\utils\decorators.py", line 45, in _wrapper
    return bound_method(*args, **kwargs)
  File "D:\development\Python\lib\site-packages\django\utils\decorators.py", line 142, in _wrapped_view
    response = view_func(request, *args, **kwargs)
  File "D:\development\Python\lib\site-packages\django\contrib\admin\options.py", line 1522, in changeform_view
    return self._changeform_view(request, object_id, form_url, extra_context)
  File "D:\development\Python\lib\site-packages\django\contrib\admin\options.py", line 1565, in _changeform_view
    self.log_addition(request, new_object, change_message)
  File "D:\development\Python\lib\site-packages\django\contrib\admin\options.py", line 810, in log_addition
    object_repr=str(object),
TypeError: __str__ returned non-string (type Subject)
2019-05-13 03:43:06,881 [Thread-3:16428] [django.request:228] [log:log_response] [ERROR]- Internal Server Error: /admin/application/rank/
Traceback (most recent call last):
  File "D:\development\Python\lib\site-packages\django\db\backends\utils.py", line 84, in _execute
    return self.cursor.execute(sql, params)
  File "D:\development\Python\lib\site-packages\django\db\backends\mysql\base.py", line 71, in execute
    return self.cursor.execute(query, args)
  File "D:\development\Python\lib\site-packages\pymysql\cursors.py", line 170, in execute
    result = self._query(query)
  File "D:\development\Python\lib\site-packages\pymysql\cursors.py", line 328, in _query
    conn.query(q)
  File "D:\development\Python\lib\site-packages\pymysql\connections.py", line 517, in query
    self._affected_rows = self._read_query_result(unbuffered=unbuffered)
  File "D:\development\Python\lib\site-packages\pymysql\connections.py", line 732, in _read_query_result
    result.read()
  File "D:\development\Python\lib\site-packages\pymysql\connections.py", line 1075, in read
    first_packet = self.connection._read_packet()
  File "D:\development\Python\lib\site-packages\pymysql\connections.py", line 684, in _read_packet
    packet.check_error()
  File "D:\development\Python\lib\site-packages\pymysql\protocol.py", line 220, in check_error
    err.raise_mysql_exception(self._data)
  File "D:\development\Python\lib\site-packages\pymysql\err.py", line 109, in raise_mysql_exception
    raise errorclass(errno, errval)
pymysql.err.InternalError: (1054, "Unknown column 'rank.name' in 'field list'")

The above exception was the direct cause of the following exception:

Traceback (most recent call last):
  File "D:\development\Python\lib\site-packages\django\core\handlers\exception.py", line 34, in inner
    response = get_response(request)
  File "D:\development\Python\lib\site-packages\django\core\handlers\base.py", line 115, in _get_response
    response = self.process_exception_by_middleware(e, request)
  File "D:\development\Python\lib\site-packages\django\core\handlers\base.py", line 113, in _get_response
    response = wrapped_callback(request, *callback_args, **callback_kwargs)
  File "D:\development\Python\lib\site-packages\django\contrib\admin\options.py", line 606, in wrapper
    return self.admin_site.admin_view(view)(*args, **kwargs)
  File "D:\development\Python\lib\site-packages\django\utils\decorators.py", line 142, in _wrapped_view
    response = view_func(request, *args, **kwargs)
  File "D:\development\Python\lib\site-packages\django\views\decorators\cache.py", line 44, in _wrapped_view_func
    response = view_func(request, *args, **kwargs)
  File "D:\development\Python\lib\site-packages\django\contrib\admin\sites.py", line 223, in inner
    return view(request, *args, **kwargs)
  File "D:\development\Python\lib\site-packages\django\utils\decorators.py", line 45, in _wrapper
    return bound_method(*args, **kwargs)
  File "D:\development\Python\lib\site-packages\django\utils\decorators.py", line 142, in _wrapped_view
    response = view_func(request, *args, **kwargs)
  File "D:\development\Python\lib\site-packages\django\contrib\admin\options.py", line 1790, in changelist_view
    'selection_note': _('0 of %(cnt)s selected') % {'cnt': len(cl.result_list)},
  File "D:\development\Python\lib\site-packages\django\db\models\query.py", line 256, in __len__
    self._fetch_all()
  File "D:\development\Python\lib\site-packages\django\db\models\query.py", line 1242, in _fetch_all
    self._result_cache = list(self._iterable_class(self))
  File "D:\development\Python\lib\site-packages\django\db\models\query.py", line 55, in __iter__
    results = compiler.execute_sql(chunked_fetch=self.chunked_fetch, chunk_size=self.chunk_size)
  File "D:\development\Python\lib\site-packages\django\db\models\sql\compiler.py", line 1097, in execute_sql
    cursor.execute(sql, params)
  File "D:\development\Python\lib\site-packages\django\db\backends\utils.py", line 99, in execute
    return super().execute(sql, params)
  File "D:\development\Python\lib\site-packages\django\db\backends\utils.py", line 67, in execute
    return self._execute_with_wrappers(sql, params, many=False, executor=self._execute)
  File "D:\development\Python\lib\site-packages\django\db\backends\utils.py", line 76, in _execute_with_wrappers
    return executor(sql, params, many, context)
  File "D:\development\Python\lib\site-packages\django\db\backends\utils.py", line 84, in _execute
    return self.cursor.execute(sql, params)
  File "D:\development\Python\lib\site-packages\django\db\utils.py", line 89, in __exit__
    raise dj_exc_value.with_traceback(traceback) from exc_value
  File "D:\development\Python\lib\site-packages\django\db\backends\utils.py", line 84, in _execute
    return self.cursor.execute(sql, params)
  File "D:\development\Python\lib\site-packages\django\db\backends\mysql\base.py", line 71, in execute
    return self.cursor.execute(query, args)
  File "D:\development\Python\lib\site-packages\pymysql\cursors.py", line 170, in execute
    result = self._query(query)
  File "D:\development\Python\lib\site-packages\pymysql\cursors.py", line 328, in _query
    conn.query(q)
  File "D:\development\Python\lib\site-packages\pymysql\connections.py", line 517, in query
    self._affected_rows = self._read_query_result(unbuffered=unbuffered)
  File "D:\development\Python\lib\site-packages\pymysql\connections.py", line 732, in _read_query_result
    result.read()
  File "D:\development\Python\lib\site-packages\pymysql\connections.py", line 1075, in read
    first_packet = self.connection._read_packet()
  File "D:\development\Python\lib\site-packages\pymysql\connections.py", line 684, in _read_packet
    packet.check_error()
  File "D:\development\Python\lib\site-packages\pymysql\protocol.py", line 220, in check_error
    err.raise_mysql_exception(self._data)
  File "D:\development\Python\lib\site-packages\pymysql\err.py", line 109, in raise_mysql_exception
    raise errorclass(errno, errval)
django.db.utils.InternalError: (1054, "Unknown column 'rank.name' in 'field list'")
2019-05-13 03:43:18,643 [Thread-3:16428] [django.request:228] [log:log_response] [ERROR]- Internal Server Error: /admin/application/rank/
Traceback (most recent call last):
  File "D:\development\Python\lib\site-packages\django\db\backends\utils.py", line 84, in _execute
    return self.cursor.execute(sql, params)
  File "D:\development\Python\lib\site-packages\django\db\backends\mysql\base.py", line 71, in execute
    return self.cursor.execute(query, args)
  File "D:\development\Python\lib\site-packages\pymysql\cursors.py", line 170, in execute
    result = self._query(query)
  File "D:\development\Python\lib\site-packages\pymysql\cursors.py", line 328, in _query
    conn.query(q)
  File "D:\development\Python\lib\site-packages\pymysql\connections.py", line 517, in query
    self._affected_rows = self._read_query_result(unbuffered=unbuffered)
  File "D:\development\Python\lib\site-packages\pymysql\connections.py", line 732, in _read_query_result
    result.read()
  File "D:\development\Python\lib\site-packages\pymysql\connections.py", line 1075, in read
    first_packet = self.connection._read_packet()
  File "D:\development\Python\lib\site-packages\pymysql\connections.py", line 684, in _read_packet
    packet.check_error()
  File "D:\development\Python\lib\site-packages\pymysql\protocol.py", line 220, in check_error
    err.raise_mysql_exception(self._data)
  File "D:\development\Python\lib\site-packages\pymysql\err.py", line 109, in raise_mysql_exception
    raise errorclass(errno, errval)
pymysql.err.InternalError: (1054, "Unknown column 'rank.name' in 'field list'")

The above exception was the direct cause of the following exception:

Traceback (most recent call last):
  File "D:\development\Python\lib\site-packages\django\core\handlers\exception.py", line 34, in inner
    response = get_response(request)
  File "D:\development\Python\lib\site-packages\django\core\handlers\base.py", line 115, in _get_response
    response = self.process_exception_by_middleware(e, request)
  File "D:\development\Python\lib\site-packages\django\core\handlers\base.py", line 113, in _get_response
    response = wrapped_callback(request, *callback_args, **callback_kwargs)
  File "D:\development\Python\lib\site-packages\django\contrib\admin\options.py", line 606, in wrapper
    return self.admin_site.admin_view(view)(*args, **kwargs)
  File "D:\development\Python\lib\site-packages\django\utils\decorators.py", line 142, in _wrapped_view
    response = view_func(request, *args, **kwargs)
  File "D:\development\Python\lib\site-packages\django\views\decorators\cache.py", line 44, in _wrapped_view_func
    response = view_func(request, *args, **kwargs)
  File "D:\development\Python\lib\site-packages\django\contrib\admin\sites.py", line 223, in inner
    return view(request, *args, **kwargs)
  File "D:\development\Python\lib\site-packages\django\utils\decorators.py", line 45, in _wrapper
    return bound_method(*args, **kwargs)
  File "D:\development\Python\lib\site-packages\django\utils\decorators.py", line 142, in _wrapped_view
    response = view_func(request, *args, **kwargs)
  File "D:\development\Python\lib\site-packages\django\contrib\admin\options.py", line 1790, in changelist_view
    'selection_note': _('0 of %(cnt)s selected') % {'cnt': len(cl.result_list)},
  File "D:\development\Python\lib\site-packages\django\db\models\query.py", line 256, in __len__
    self._fetch_all()
  File "D:\development\Python\lib\site-packages\django\db\models\query.py", line 1242, in _fetch_all
    self._result_cache = list(self._iterable_class(self))
  File "D:\development\Python\lib\site-packages\django\db\models\query.py", line 55, in __iter__
    results = compiler.execute_sql(chunked_fetch=self.chunked_fetch, chunk_size=self.chunk_size)
  File "D:\development\Python\lib\site-packages\django\db\models\sql\compiler.py", line 1097, in execute_sql
    cursor.execute(sql, params)
  File "D:\development\Python\lib\site-packages\django\db\backends\utils.py", line 99, in execute
    return super().execute(sql, params)
  File "D:\development\Python\lib\site-packages\django\db\backends\utils.py", line 67, in execute
    return self._execute_with_wrappers(sql, params, many=False, executor=self._execute)
  File "D:\development\Python\lib\site-packages\django\db\backends\utils.py", line 76, in _execute_with_wrappers
    return executor(sql, params, many, context)
  File "D:\development\Python\lib\site-packages\django\db\backends\utils.py", line 84, in _execute
    return self.cursor.execute(sql, params)
  File "D:\development\Python\lib\site-packages\django\db\utils.py", line 89, in __exit__
    raise dj_exc_value.with_traceback(traceback) from exc_value
  File "D:\development\Python\lib\site-packages\django\db\backends\utils.py", line 84, in _execute
    return self.cursor.execute(sql, params)
  File "D:\development\Python\lib\site-packages\django\db\backends\mysql\base.py", line 71, in execute
    return self.cursor.execute(query, args)
  File "D:\development\Python\lib\site-packages\pymysql\cursors.py", line 170, in execute
    result = self._query(query)
  File "D:\development\Python\lib\site-packages\pymysql\cursors.py", line 328, in _query
    conn.query(q)
  File "D:\development\Python\lib\site-packages\pymysql\connections.py", line 517, in query
    self._affected_rows = self._read_query_result(unbuffered=unbuffered)
  File "D:\development\Python\lib\site-packages\pymysql\connections.py", line 732, in _read_query_result
    result.read()
  File "D:\development\Python\lib\site-packages\pymysql\connections.py", line 1075, in read
    first_packet = self.connection._read_packet()
  File "D:\development\Python\lib\site-packages\pymysql\connections.py", line 684, in _read_packet
    packet.check_error()
  File "D:\development\Python\lib\site-packages\pymysql\protocol.py", line 220, in check_error
    err.raise_mysql_exception(self._data)
  File "D:\development\Python\lib\site-packages\pymysql\err.py", line 109, in raise_mysql_exception
    raise errorclass(errno, errval)
django.db.utils.InternalError: (1054, "Unknown column 'rank.name' in 'field list'")
