INFO 2019-04-28 00:52:37,825 danielUPDATE user SET name = 'daniel90911111111111111111111111111110', password = '123', email = '123@qq.com', phone = '18940980522' WHERE id = 1
2019-04-28 00:52:37,975 [Thread-2:2700] [django.request:228] [log:log_response] [ERROR]- Internal Server Error: /api/update_user/
Traceback (most recent call last):
  File "D:\development\Python\lib\site-packages\django\db\backends\utils.py", line 82, in _execute
    return self.cursor.execute(sql)
  File "D:\development\Python\lib\site-packages\django\db\backends\mysql\base.py", line 71, in execute
    return self.cursor.execute(query, args)
  File "D:\development\Python\lib\site-packages\pymysql\cursors.py", line 170, in execute
    result = self._query(query)
  File "D:\development\Python\lib\site-packages\pymysql\cursors.py", line 328, in _query
    conn.query(q)
  File "D:\development\Python\lib\site-packages\pymysql\connections.py", line 517, in query
    self._affected_rows = self._read_query_result(unbuffered=unbuffered)
  File "D:\development\Python\lib\site-packages\pymysql\connections.py", line 732, in _read_query_result
    result.read()
  File "D:\development\Python\lib\site-packages\pymysql\connections.py", line 1075, in read
    first_packet = self.connection._read_packet()
  File "D:\development\Python\lib\site-packages\pymysql\connections.py", line 684, in _read_packet
    packet.check_error()
  File "D:\development\Python\lib\site-packages\pymysql\protocol.py", line 220, in check_error
    err.raise_mysql_exception(self._data)
  File "D:\development\Python\lib\site-packages\pymysql\err.py", line 109, in raise_mysql_exception
    raise errorclass(errno, errval)
pymysql.err.DataError: (1406, "Data too long for column 'name' at row 1")

The above exception was the direct cause of the following exception:

Traceback (most recent call last):
  File "D:\development\Python\lib\site-packages\django\core\handlers\exception.py", line 34, in inner
    response = get_response(request)
  File "D:\development\Python\lib\site-packages\django\core\handlers\base.py", line 115, in _get_response
    response = self.process_exception_by_middleware(e, request)
  File "D:\development\Python\lib\site-packages\django\core\handlers\base.py", line 113, in _get_response
    response = wrapped_callback(request, *callback_args, **callback_kwargs)
  File "D:\workspace\workspace-python\plant\api\views.py", line 35, in update_user
    cursor.execute(sql)
  File "D:\development\Python\lib\site-packages\django\db\backends\utils.py", line 99, in execute
    return super().execute(sql, params)
  File "D:\development\Python\lib\site-packages\django\db\backends\utils.py", line 67, in execute
    return self._execute_with_wrappers(sql, params, many=False, executor=self._execute)
  File "D:\development\Python\lib\site-packages\django\db\backends\utils.py", line 76, in _execute_with_wrappers
    return executor(sql, params, many, context)
  File "D:\development\Python\lib\site-packages\django\db\backends\utils.py", line 84, in _execute
    return self.cursor.execute(sql, params)
  File "D:\development\Python\lib\site-packages\django\db\utils.py", line 89, in __exit__
    raise dj_exc_value.with_traceback(traceback) from exc_value
  File "D:\development\Python\lib\site-packages\django\db\backends\utils.py", line 82, in _execute
    return self.cursor.execute(sql)
  File "D:\development\Python\lib\site-packages\django\db\backends\mysql\base.py", line 71, in execute
    return self.cursor.execute(query, args)
  File "D:\development\Python\lib\site-packages\pymysql\cursors.py", line 170, in execute
    result = self._query(query)
  File "D:\development\Python\lib\site-packages\pymysql\cursors.py", line 328, in _query
    conn.query(q)
  File "D:\development\Python\lib\site-packages\pymysql\connections.py", line 517, in query
    self._affected_rows = self._read_query_result(unbuffered=unbuffered)
  File "D:\development\Python\lib\site-packages\pymysql\connections.py", line 732, in _read_query_result
    result.read()
  File "D:\development\Python\lib\site-packages\pymysql\connections.py", line 1075, in read
    first_packet = self.connection._read_packet()
  File "D:\development\Python\lib\site-packages\pymysql\connections.py", line 684, in _read_packet
    packet.check_error()
  File "D:\development\Python\lib\site-packages\pymysql\protocol.py", line 220, in check_error
    err.raise_mysql_exception(self._data)
  File "D:\development\Python\lib\site-packages\pymysql\err.py", line 109, in raise_mysql_exception
    raise errorclass(errno, errval)
django.db.utils.DataError: (1406, "Data too long for column 'name' at row 1")
INFO 2019-04-28 00:53:44,387 danielUPDATE user SET name = 'daniel910', password = '123', email = '123@qq.com', phone = '18940980522' WHERE id = 1
INFO 2019-04-28 00:53:44,392 daniel0
INFO 2019-04-28 01:15:06,830 danielUPDATE user SET name = 'daniel1514', password = '123', email = '123@qq.com', phone = '18940980522' WHERE id = 1
INFO 2019-04-28 01:15:06,837 daniel0
INFO 2019-04-28 01:17:05,905 danielUPDATE user SET name = 'daniel666', password = '123', email = '123@qq.com', phone = '18940980522' WHERE id = 1
INFO 2019-04-28 01:17:05,910 daniel0
2019-04-28 01:28:55,796 [Thread-9:10656] [django.request:228] [log:log_response] [ERROR]- Internal Server Error: /api/update_user/
Traceback (most recent call last):
  File "D:\development\Python\lib\site-packages\django\core\handlers\exception.py", line 34, in inner
    response = get_response(request)
  File "D:\development\Python\lib\site-packages\django\core\handlers\base.py", line 115, in _get_response
    response = self.process_exception_by_middleware(e, request)
  File "D:\development\Python\lib\site-packages\django\core\handlers\base.py", line 113, in _get_response
    response = wrapped_callback(request, *callback_args, **callback_kwargs)
  File "D:\workspace\workspace-python\plant\api\views.py", line 33, in update_user
    % (name, password, email, phone, id)
TypeError: %d format: a number is required, not str
2019-04-28 01:34:38,821 [Thread-11:3396] [django.request:228] [log:log_response] [ERROR]- Internal Server Error: /api/update_user/
Traceback (most recent call last):
  File "D:\development\Python\lib\site-packages\django\core\handlers\exception.py", line 34, in inner
    response = get_response(request)
  File "D:\development\Python\lib\site-packages\django\core\handlers\base.py", line 115, in _get_response
    response = self.process_exception_by_middleware(e, request)
  File "D:\development\Python\lib\site-packages\django\core\handlers\base.py", line 113, in _get_response
    response = wrapped_callback(request, *callback_args, **callback_kwargs)
  File "D:\workspace\workspace-python\plant\api\views.py", line 33, in update_user
    % (name, password, email, phone, id)
TypeError: %d format: a number is required, not str
2019-04-28 01:40:40,577 [Thread-13:10816] [django.request:228] [log:log_response] [ERROR]- Internal Server Error: /api/update_user/
Traceback (most recent call last):
  File "D:\development\Python\lib\site-packages\django\core\handlers\exception.py", line 34, in inner
    response = get_response(request)
  File "D:\development\Python\lib\site-packages\django\core\handlers\base.py", line 115, in _get_response
    response = self.process_exception_by_middleware(e, request)
  File "D:\development\Python\lib\site-packages\django\core\handlers\base.py", line 113, in _get_response
    response = wrapped_callback(request, *callback_args, **callback_kwargs)
  File "D:\workspace\workspace-python\plant\api\views.py", line 33, in update_user
    % (name, password, email, phone, id)
TypeError: %d format: a number is required, not NoneType
2019-04-28 01:41:28,452 [Thread-13:10816] [django.request:228] [log:log_response] [ERROR]- Internal Server Error: /api/update_user/
Traceback (most recent call last):
  File "D:\development\Python\lib\site-packages\django\core\handlers\exception.py", line 34, in inner
    response = get_response(request)
  File "D:\development\Python\lib\site-packages\django\core\handlers\base.py", line 115, in _get_response
    response = self.process_exception_by_middleware(e, request)
  File "D:\development\Python\lib\site-packages\django\core\handlers\base.py", line 113, in _get_response
    response = wrapped_callback(request, *callback_args, **callback_kwargs)
  File "D:\workspace\workspace-python\plant\api\views.py", line 33, in update_user
    % (name, password, email, phone, id)
TypeError: %d format: a number is required, not NoneType
INFO 2019-04-28 01:43:28,755 danielUPDATE user SET name = 'daniel666', password = '123', email = '123@qq.com', phone = '18940980522' WHERE id = 1
INFO 2019-04-28 01:43:28,762 daniel0
INFO 2019-04-28 01:44:58,686 danielUPDATE user SET name = 'daniel666', password = '123', email = '123@qq.com', phone = '18940980522' WHERE id = 1
INFO 2019-04-28 01:44:58,693 daniel0
2019-04-29 23:11:15,199 [Thread-16:9008] [django.request:228] [log:log_response] [ERROR]- Internal Server Error: /admins/
Traceback (most recent call last):
  File "D:\development\Python\lib\site-packages\django\template\base.py", line 470, in parse
    compile_func = self.tags[command]
KeyError: 'static'

During handling of the above exception, another exception occurred:

Traceback (most recent call last):
  File "D:\development\Python\lib\site-packages\django\core\handlers\exception.py", line 34, in inner
    response = get_response(request)
  File "D:\development\Python\lib\site-packages\django\core\handlers\base.py", line 115, in _get_response
    response = self.process_exception_by_middleware(e, request)
  File "D:\development\Python\lib\site-packages\django\core\handlers\base.py", line 113, in _get_response
    response = wrapped_callback(request, *callback_args, **callback_kwargs)
  File "D:\workspace\workspace-python\plant\admins\views.py", line 6, in index
    return render(request, 'admins/index.html', context)
  File "D:\development\Python\lib\site-packages\django\shortcuts.py", line 36, in render
    content = loader.render_to_string(template_name, context, request, using=using)
  File "D:\development\Python\lib\site-packages\django\template\loader.py", line 62, in render_to_string
    return template.render(context, request)
  File "D:\development\Python\lib\site-packages\django\template\backends\django.py", line 61, in render
    return self.template.render(context)
  File "D:\development\Python\lib\site-packages\django\template\base.py", line 171, in render
    return self._render(context)
  File "D:\development\Python\lib\site-packages\django\template\base.py", line 163, in _render
    return self.nodelist.render(context)
  File "D:\development\Python\lib\site-packages\django\template\base.py", line 937, in render
    bit = node.render_annotated(context)
  File "D:\development\Python\lib\site-packages\django\template\base.py", line 904, in render_annotated
    return self.render(context)
  File "D:\development\Python\lib\site-packages\django\template\loader_tags.py", line 176, in render
    template = context.template.engine.get_template(template_name)
  File "D:\development\Python\lib\site-packages\django\template\engine.py", line 143, in get_template
    template, origin = self.find_template(template_name)
  File "D:\development\Python\lib\site-packages\django\template\engine.py", line 125, in find_template
    template = loader.get_template(name, skip=skip)
  File "D:\development\Python\lib\site-packages\django\template\loaders\base.py", line 30, in get_template
    contents, origin, origin.template_name, self.engine,
  File "D:\development\Python\lib\site-packages\django\template\base.py", line 156, in __init__
    self.nodelist = self.compile_nodelist()
  File "D:\development\Python\lib\site-packages\django\template\base.py", line 194, in compile_nodelist
    return parser.parse()
  File "D:\development\Python\lib\site-packages\django\template\base.py", line 472, in parse
    self.invalid_block_tag(token, command, parse_until)
  File "D:\development\Python\lib\site-packages\django\template\base.py", line 534, in invalid_block_tag
    "or load this tag?" % (token.lineno, command)
django.template.exceptions.TemplateSyntaxError: Invalid block tag on line 4: 'static'. Did you forget to register or load this tag?
2019-04-29 23:12:01,405 [Thread-3:12964] [django.request:228] [log:log_response] [ERROR]- Internal Server Error: /admins/
Traceback (most recent call last):
  File "D:\development\Python\lib\site-packages\django\template\base.py", line 470, in parse
    compile_func = self.tags[command]
KeyError: 'static'

During handling of the above exception, another exception occurred:

Traceback (most recent call last):
  File "D:\development\Python\lib\site-packages\django\core\handlers\exception.py", line 34, in inner
    response = get_response(request)
  File "D:\development\Python\lib\site-packages\django\core\handlers\base.py", line 115, in _get_response
    response = self.process_exception_by_middleware(e, request)
  File "D:\development\Python\lib\site-packages\django\core\handlers\base.py", line 113, in _get_response
    response = wrapped_callback(request, *callback_args, **callback_kwargs)
  File "D:\workspace\workspace-python\plant\admins\views.py", line 6, in index
    return render(request, 'admins/index.html', context)
  File "D:\development\Python\lib\site-packages\django\shortcuts.py", line 36, in render
    content = loader.render_to_string(template_name, context, request, using=using)
  File "D:\development\Python\lib\site-packages\django\template\loader.py", line 62, in render_to_string
    return template.render(context, request)
  File "D:\development\Python\lib\site-packages\django\template\backends\django.py", line 61, in render
    return self.template.render(context)
  File "D:\development\Python\lib\site-packages\django\template\base.py", line 171, in render
    return self._render(context)
  File "D:\development\Python\lib\site-packages\django\template\base.py", line 163, in _render
    return self.nodelist.render(context)
  File "D:\development\Python\lib\site-packages\django\template\base.py", line 937, in render
    bit = node.render_annotated(context)
  File "D:\development\Python\lib\site-packages\django\template\base.py", line 904, in render_annotated
    return self.render(context)
  File "D:\development\Python\lib\site-packages\django\template\loader_tags.py", line 176, in render
    template = context.template.engine.get_template(template_name)
  File "D:\development\Python\lib\site-packages\django\template\engine.py", line 143, in get_template
    template, origin = self.find_template(template_name)
  File "D:\development\Python\lib\site-packages\django\template\engine.py", line 125, in find_template
    template = loader.get_template(name, skip=skip)
  File "D:\development\Python\lib\site-packages\django\template\loaders\base.py", line 30, in get_template
    contents, origin, origin.template_name, self.engine,
  File "D:\development\Python\lib\site-packages\django\template\base.py", line 156, in __init__
    self.nodelist = self.compile_nodelist()
  File "D:\development\Python\lib\site-packages\django\template\base.py", line 194, in compile_nodelist
    return parser.parse()
  File "D:\development\Python\lib\site-packages\django\template\base.py", line 472, in parse
    self.invalid_block_tag(token, command, parse_until)
  File "D:\development\Python\lib\site-packages\django\template\base.py", line 534, in invalid_block_tag
    "or load this tag?" % (token.lineno, command)
django.template.exceptions.TemplateSyntaxError: Invalid block tag on line 4: 'static'. Did you forget to register or load this tag?
2019-05-04 02:10:50,235 [Thread-28:15336] [django.request:228] [log:log_response] [ERROR]- Internal Server Error: /plant/user_center/
Traceback (most recent call last):
  File "D:\development\Python\lib\site-packages\django\core\handlers\exception.py", line 34, in inner
    response = get_response(request)
  File "D:\development\Python\lib\site-packages\django\core\handlers\base.py", line 115, in _get_response
    response = self.process_exception_by_middleware(e, request)
  File "D:\development\Python\lib\site-packages\django\core\handlers\base.py", line 113, in _get_response
    response = wrapped_callback(request, *callback_args, **callback_kwargs)
  File "D:\workspace\workspace-python\plant\application\views.py", line 119, in user_center
    return render(request, 'application/user_center.html', context)
  File "D:\development\Python\lib\site-packages\django\shortcuts.py", line 36, in render
    content = loader.render_to_string(template_name, context, request, using=using)
  File "D:\development\Python\lib\site-packages\django\template\loader.py", line 62, in render_to_string
    return template.render(context, request)
  File "D:\development\Python\lib\site-packages\django\template\backends\django.py", line 61, in render
    return self.template.render(context)
  File "D:\development\Python\lib\site-packages\django\template\base.py", line 171, in render
    return self._render(context)
  File "D:\development\Python\lib\site-packages\django\template\base.py", line 163, in _render
    return self.nodelist.render(context)
  File "D:\development\Python\lib\site-packages\django\template\base.py", line 937, in render
    bit = node.render_annotated(context)
  File "D:\development\Python\lib\site-packages\django\template\base.py", line 904, in render_annotated
    return self.render(context)
  File "D:\development\Python\lib\site-packages\django\template\defaulttags.py", line 209, in render
    nodelist.append(node.render_annotated(context))
  File "D:\development\Python\lib\site-packages\django\template\base.py", line 904, in render_annotated
    return self.render(context)
  File "D:\development\Python\lib\site-packages\django\template\defaulttags.py", line 443, in render
    url = reverse(view_name, args=args, kwargs=kwargs, current_app=current_app)
  File "D:\development\Python\lib\site-packages\django\urls\base.py", line 90, in reverse
    return iri_to_uri(resolver._reverse_with_prefix(view, prefix, *args, **kwargs))
  File "D:\development\Python\lib\site-packages\django\urls\resolvers.py", line 660, in _reverse_with_prefix
    raise NoReverseMatch(msg)
django.urls.exceptions.NoReverseMatch: Reverse for 'plant_detail' not found. 'plant_detail' is not a valid view function or pattern name.
2019-05-04 02:18:43,168 [Thread-3:2832] [django.request:228] [log:log_response] [ERROR]- Internal Server Error: /plant/plant_detail/1
Traceback (most recent call last):
  File "D:\development\Python\lib\site-packages\django\core\handlers\exception.py", line 34, in inner
    response = get_response(request)
  File "D:\development\Python\lib\site-packages\django\core\handlers\base.py", line 115, in _get_response
    response = self.process_exception_by_middleware(e, request)
  File "D:\development\Python\lib\site-packages\django\core\handlers\base.py", line 113, in _get_response
    response = wrapped_callback(request, *callback_args, **callback_kwargs)
TypeError: plant_detail() got an unexpected keyword argument 'id'
2019-05-04 02:19:59,404 [Thread-2:1028] [django.request:228] [log:log_response] [ERROR]- Internal Server Error: /plant/plant_detail/1
Traceback (most recent call last):
  File "D:\development\Python\lib\site-packages\django\core\handlers\exception.py", line 34, in inner
    response = get_response(request)
  File "D:\development\Python\lib\site-packages\django\core\handlers\base.py", line 115, in _get_response
    response = self.process_exception_by_middleware(e, request)
  File "D:\development\Python\lib\site-packages\django\core\handlers\base.py", line 113, in _get_response
    response = wrapped_callback(request, *callback_args, **callback_kwargs)
TypeError: plant_detail() got an unexpected keyword argument 'id'
2019-05-04 02:20:21,618 [Thread-2:1028] [django.request:228] [log:log_response] [ERROR]- Internal Server Error: /plant/plant_detail/1
Traceback (most recent call last):
  File "D:\development\Python\lib\site-packages\django\core\handlers\exception.py", line 34, in inner
    response = get_response(request)
  File "D:\development\Python\lib\site-packages\django\core\handlers\base.py", line 115, in _get_response
    response = self.process_exception_by_middleware(e, request)
  File "D:\development\Python\lib\site-packages\django\core\handlers\base.py", line 113, in _get_response
    response = wrapped_callback(request, *callback_args, **callback_kwargs)
TypeError: plant_detail() got an unexpected keyword argument 'id'
2019-05-04 18:51:50,469 [Thread-2:9772] [django.request:228] [log:log_response] [ERROR]- Internal Server Error: /tf/tf/
Traceback (most recent call last):
  File "D:\development\Python\lib\site-packages\django\core\handlers\exception.py", line 34, in inner
    response = get_response(request)
  File "D:\development\Python\lib\site-packages\django\core\handlers\base.py", line 115, in _get_response
    response = self.process_exception_by_middleware(e, request)
  File "D:\development\Python\lib\site-packages\django\core\handlers\base.py", line 113, in _get_response
    response = wrapped_callback(request, *callback_args, **callback_kwargs)
  File "D:\workspace\workspace-python\plant\tf\views.py", line 22, in tf
    image_data = request.FILES.getlist('files')[0]
IndexError: list index out of range
2019-05-04 18:52:05,168 [Thread-2:9772] [django.request:228] [log:log_response] [ERROR]- Internal Server Error: /tf/tf/
Traceback (most recent call last):
  File "D:\development\Python\lib\site-packages\django\core\handlers\exception.py", line 34, in inner
    response = get_response(request)
  File "D:\development\Python\lib\site-packages\django\core\handlers\base.py", line 115, in _get_response
    response = self.process_exception_by_middleware(e, request)
  File "D:\development\Python\lib\site-packages\django\core\handlers\base.py", line 113, in _get_response
    response = wrapped_callback(request, *callback_args, **callback_kwargs)
  File "D:\workspace\workspace-python\plant\tf\views.py", line 22, in tf
    image_data = request.FILES.getlist('files')[0]
IndexError: list index out of range
2019-05-04 18:53:15,087 [Thread-2:9772] [django.request:228] [log:log_response] [ERROR]- Internal Server Error: /tf/tf/
Traceback (most recent call last):
  File "D:\development\Python\lib\site-packages\django\core\handlers\exception.py", line 34, in inner
    response = get_response(request)
  File "D:\development\Python\lib\site-packages\django\core\handlers\base.py", line 115, in _get_response
    response = self.process_exception_by_middleware(e, request)
  File "D:\development\Python\lib\site-packages\django\core\handlers\base.py", line 113, in _get_response
    response = wrapped_callback(request, *callback_args, **callback_kwargs)
  File "D:\workspace\workspace-python\plant\tf\views.py", line 22, in tf
    image_data = request.FILES.getlist('files')[0]
IndexError: list index out of range
2019-05-04 18:55:27,044 [Thread-2:9772] [django.request:228] [log:log_response] [ERROR]- Internal Server Error: /tf/tf/
Traceback (most recent call last):
  File "D:\development\Python\lib\site-packages\django\core\handlers\exception.py", line 34, in inner
    response = get_response(request)
  File "D:\development\Python\lib\site-packages\django\core\handlers\base.py", line 115, in _get_response
    response = self.process_exception_by_middleware(e, request)
  File "D:\development\Python\lib\site-packages\django\core\handlers\base.py", line 113, in _get_response
    response = wrapped_callback(request, *callback_args, **callback_kwargs)
  File "D:\workspace\workspace-python\plant\tf\views.py", line 25, in tf
    label_lines = [line.rstrip() for line in tf.gfile.GFile("model/retrained_labels.txt")]
AttributeError: 'function' object has no attribute 'gfile'
2019-05-04 18:58:39,925 [Thread-2:6084] [django.request:228] [log:log_response] [ERROR]- Internal Server Error: /tf/tf/
Traceback (most recent call last):
  File "D:\development\Python\lib\site-packages\django\core\handlers\exception.py", line 34, in inner
    response = get_response(request)
  File "D:\development\Python\lib\site-packages\django\core\handlers\base.py", line 115, in _get_response
    response = self.process_exception_by_middleware(e, request)
  File "D:\development\Python\lib\site-packages\django\core\handlers\base.py", line 113, in _get_response
    response = wrapped_callback(request, *callback_args, **callback_kwargs)
  File "D:\workspace\workspace-python\plant\tf\views.py", line 25, in tf
    label_lines = [line.rstrip() for line in tf.gfile.GFile("model/retrained_labels.txt")]
AttributeError: 'function' object has no attribute 'gfile'
2019-05-04 19:06:58,200 [Thread-2:15492] [django.request:228] [log:log_response] [ERROR]- Internal Server Error: /tf/tf/
Traceback (most recent call last):
  File "D:\development\Python\lib\site-packages\django\core\handlers\exception.py", line 34, in inner
    response = get_response(request)
  File "D:\development\Python\lib\site-packages\django\core\handlers\base.py", line 115, in _get_response
    response = self.process_exception_by_middleware(e, request)
  File "D:\development\Python\lib\site-packages\django\core\handlers\base.py", line 113, in _get_response
    response = wrapped_callback(request, *callback_args, **callback_kwargs)
  File "D:\workspace\workspace-python\plant\tf\views.py", line 25, in tf
    label_lines = [line.rstrip() for line in tf.gfile.FastGFile("model/retrained_labels.txt")]
AttributeError: 'function' object has no attribute 'gfile'
2019-05-04 19:13:44,469 [Thread-2:11172] [django.request:228] [log:log_response] [ERROR]- Internal Server Error: /tf/tf/
Traceback (most recent call last):
  File "D:\development\Python\lib\site-packages\tensorflow\python\client\session.py", line 1334, in _do_call
    return fn(*args)
  File "D:\development\Python\lib\site-packages\tensorflow\python\client\session.py", line 1319, in _run_fn
    options, feed_dict, fetch_list, target_list, run_metadata)
  File "D:\development\Python\lib\site-packages\tensorflow\python\client\session.py", line 1407, in _call_tf_sessionrun
    run_metadata)
tensorflow.python.framework.errors_impl.InternalError: Unable to get element as bytes.

During handling of the above exception, another exception occurred:

Traceback (most recent call last):
  File "D:\development\Python\lib\site-packages\django\core\handlers\exception.py", line 34, in inner
    response = get_response(request)
  File "D:\development\Python\lib\site-packages\django\core\handlers\base.py", line 115, in _get_response
    response = self.process_exception_by_middleware(e, request)
  File "D:\development\Python\lib\site-packages\django\core\handlers\base.py", line 113, in _get_response
    response = wrapped_callback(request, *callback_args, **callback_kwargs)
  File "D:\workspace\workspace-python\plant\tf\views.py", line 39, in tf_plant
    predictions = sess.run(softmax_tensor, {'DecodeJpeg/contents:0': image_data})
  File "D:\development\Python\lib\site-packages\tensorflow\python\client\session.py", line 929, in run
    run_metadata_ptr)
  File "D:\development\Python\lib\site-packages\tensorflow\python\client\session.py", line 1152, in _run
    feed_dict_tensor, options, run_metadata)
  File "D:\development\Python\lib\site-packages\tensorflow\python\client\session.py", line 1328, in _do_run
    run_metadata)
  File "D:\development\Python\lib\site-packages\tensorflow\python\client\session.py", line 1348, in _do_call
    raise type(e)(node_def, op, message)
tensorflow.python.framework.errors_impl.InternalError: Unable to get element as bytes.
2019-05-04 19:17:39,143 [Thread-2:11284] [django.request:228] [log:log_response] [ERROR]- Internal Server Error: /tf/tf/
Traceback (most recent call last):
  File "D:\development\Python\lib\site-packages\tensorflow\python\client\session.py", line 1334, in _do_call
    return fn(*args)
  File "D:\development\Python\lib\site-packages\tensorflow\python\client\session.py", line 1319, in _run_fn
    options, feed_dict, fetch_list, target_list, run_metadata)
  File "D:\development\Python\lib\site-packages\tensorflow\python\client\session.py", line 1407, in _call_tf_sessionrun
    run_metadata)
tensorflow.python.framework.errors_impl.InternalError: Unable to get element as bytes.

During handling of the above exception, another exception occurred:

Traceback (most recent call last):
  File "D:\development\Python\lib\site-packages\django\core\handlers\exception.py", line 34, in inner
    response = get_response(request)
  File "D:\development\Python\lib\site-packages\django\core\handlers\base.py", line 115, in _get_response
    response = self.process_exception_by_middleware(e, request)
  File "D:\development\Python\lib\site-packages\django\core\handlers\base.py", line 113, in _get_response
    response = wrapped_callback(request, *callback_args, **callback_kwargs)
  File "D:\workspace\workspace-python\plant\tf\views.py", line 39, in tf_plant
    predictions = sess.run(softmax_tensor, {'DecodeJpeg/contents:0': image_data})
  File "D:\development\Python\lib\site-packages\tensorflow\python\client\session.py", line 929, in run
    run_metadata_ptr)
  File "D:\development\Python\lib\site-packages\tensorflow\python\client\session.py", line 1152, in _run
    feed_dict_tensor, options, run_metadata)
  File "D:\development\Python\lib\site-packages\tensorflow\python\client\session.py", line 1328, in _do_run
    run_metadata)
  File "D:\development\Python\lib\site-packages\tensorflow\python\client\session.py", line 1348, in _do_call
    raise type(e)(node_def, op, message)
tensorflow.python.framework.errors_impl.InternalError: Unable to get element as bytes.
2019-05-04 19:36:52,547 [Thread-2:12632] [django.request:228] [log:log_response] [ERROR]- Internal Server Error: /tf/tf/
Traceback (most recent call last):
  File "D:\development\Python\lib\site-packages\django\core\handlers\exception.py", line 34, in inner
    response = get_response(request)
  File "D:\development\Python\lib\site-packages\django\core\handlers\base.py", line 115, in _get_response
    response = self.process_exception_by_middleware(e, request)
  File "D:\development\Python\lib\site-packages\django\core\handlers\base.py", line 113, in _get_response
    response = wrapped_callback(request, *callback_args, **callback_kwargs)
  File "D:\workspace\workspace-python\plant\tf\views.py", line 15, in tf_plant
    obj.stdin.write('label_image.py D:\\workspace\\workspace-python\\tensorflow-image\\1.jpg')
TypeError: a bytes-like object is required, not 'str'
2019-05-04 19:39:06,844 [Thread-2:15864] [django.request:228] [log:log_response] [ERROR]- Internal Server Error: /tf/tf/
Traceback (most recent call last):
  File "D:\development\Python\lib\site-packages\django\core\handlers\exception.py", line 34, in inner
    response = get_response(request)
  File "D:\development\Python\lib\site-packages\django\core\handlers\base.py", line 115, in _get_response
    response = self.process_exception_by_middleware(e, request)
  File "D:\development\Python\lib\site-packages\django\core\handlers\base.py", line 113, in _get_response
    response = wrapped_callback(request, *callback_args, **callback_kwargs)
  File "D:\workspace\workspace-python\plant\tf\views.py", line 16, in tf_plant
    obj.stdin.write('print 1 \n ')
TypeError: a bytes-like object is required, not 'str'
2019-05-04 19:43:58,251 [Thread-2:4572] [django.request:228] [log:log_response] [ERROR]- Internal Server Error: /tf/tf/
Traceback (most recent call last):
  File "D:\development\Python\lib\site-packages\django\core\handlers\exception.py", line 34, in inner
    response = get_response(request)
  File "D:\development\Python\lib\site-packages\django\core\handlers\base.py", line 115, in _get_response
    response = self.process_exception_by_middleware(e, request)
  File "D:\development\Python\lib\site-packages\django\core\handlers\base.py", line 113, in _get_response
    response = wrapped_callback(request, *callback_args, **callback_kwargs)
  File "D:\workspace\workspace-python\plant\tf\views.py", line 16, in tf_plant
    obj.stdin.write('print 1 \n')
TypeError: a bytes-like object is required, not 'str'
2019-05-04 19:45:28,688 [Thread-2:11196] [django.request:228] [log:log_response] [ERROR]- Internal Server Error: /tf/tf/
Traceback (most recent call last):
  File "D:\development\Python\lib\site-packages\django\core\handlers\exception.py", line 34, in inner
    response = get_response(request)
  File "D:\development\Python\lib\site-packages\django\core\handlers\base.py", line 115, in _get_response
    response = self.process_exception_by_middleware(e, request)
  File "D:\development\Python\lib\site-packages\django\core\handlers\base.py", line 113, in _get_response
    response = wrapped_callback(request, *callback_args, **callback_kwargs)
  File "D:\workspace\workspace-python\plant\tf\views.py", line 16, in tf_plant
    obj.stdin.write('1+1')
TypeError: a bytes-like object is required, not 'str'
2019-05-04 23:27:23,509 [Thread-2:11824] [django.request:228] [log:log_response] [ERROR]- Internal Server Error: /tf/tf/
Traceback (most recent call last):
  File "D:\development\Python\lib\site-packages\django\core\handlers\exception.py", line 34, in inner
    response = get_response(request)
  File "D:\development\Python\lib\site-packages\django\core\handlers\base.py", line 115, in _get_response
    response = self.process_exception_by_middleware(e, request)
  File "D:\development\Python\lib\site-packages\django\core\handlers\base.py", line 113, in _get_response
    response = wrapped_callback(request, *callback_args, **callback_kwargs)
  File "D:\workspace\workspace-python\plant\tf\views.py", line 14, in tf_plant
    image_data = request.FILES.getlist('files')[0]
IndexError: list index out of range
2019-05-04 23:34:04,233 [Thread-2:14080] [django.request:228] [log:log_response] [ERROR]- Internal Server Error: /tf/tf/
Traceback (most recent call last):
  File "D:\development\Python\lib\site-packages\django\core\handlers\exception.py", line 34, in inner
    response = get_response(request)
  File "D:\development\Python\lib\site-packages\django\core\handlers\base.py", line 115, in _get_response
    response = self.process_exception_by_middleware(e, request)
  File "D:\development\Python\lib\site-packages\django\core\handlers\base.py", line 113, in _get_response
    response = wrapped_callback(request, *callback_args, **callback_kwargs)
  File "D:\workspace\workspace-python\plant\tf\views.py", line 22, in tf_plant
    return HttpResponse(json.dumps(result_json), content_type="application/json")
  File "D:\development\Python\lib\json\__init__.py", line 231, in dumps
    return _default_encoder.encode(obj)
  File "D:\development\Python\lib\json\encoder.py", line 199, in encode
    chunks = self.iterencode(o, _one_shot=True)
  File "D:\development\Python\lib\json\encoder.py", line 257, in iterencode
    return _iterencode(o, 0)
  File "D:\development\Python\lib\json\encoder.py", line 180, in default
    o.__class__.__name__)
TypeError: Object of type 'bytes' is not JSON serializable
2019-05-05 00:39:52,978 [Thread-2:8888] [django.request:228] [log:log_response] [ERROR]- Internal Server Error: /tf/tf/
Traceback (most recent call last):
  File "D:\development\Python\lib\site-packages\django\core\handlers\exception.py", line 34, in inner
    response = get_response(request)
  File "D:\development\Python\lib\site-packages\django\core\handlers\base.py", line 115, in _get_response
    response = self.process_exception_by_middleware(e, request)
  File "D:\development\Python\lib\site-packages\django\core\handlers\base.py", line 113, in _get_response
    response = wrapped_callback(request, *callback_args, **callback_kwargs)
  File "D:\workspace\workspace-python\plant\tf\views.py", line 20, in tf_plant
    result = json.loads(data)
  File "D:\development\Python\lib\json\__init__.py", line 354, in loads
    return _default_decoder.decode(s)
  File "D:\development\Python\lib\json\decoder.py", line 339, in decode
    obj, end = self.raw_decode(s, idx=_w(s, 0).end())
  File "D:\development\Python\lib\json\decoder.py", line 357, in raw_decode
    raise JSONDecodeError("Expecting value", s, err.value) from None
json.decoder.JSONDecodeError: Expecting value: line 1 column 1 (char 0)
2019-05-05 00:41:49,565 [Thread-2:13412] [django.request:228] [log:log_response] [ERROR]- Internal Server Error: /tf/tf/
Traceback (most recent call last):
  File "D:\development\Python\lib\site-packages\django\core\handlers\exception.py", line 34, in inner
    response = get_response(request)
  File "D:\development\Python\lib\site-packages\django\core\handlers\base.py", line 115, in _get_response
    response = self.process_exception_by_middleware(e, request)
  File "D:\development\Python\lib\site-packages\django\core\handlers\base.py", line 113, in _get_response
    response = wrapped_callback(request, *callback_args, **callback_kwargs)
  File "D:\workspace\workspace-python\plant\tf\views.py", line 20, in tf_plant
    result = json.loads(data)
  File "D:\development\Python\lib\json\__init__.py", line 354, in loads
    return _default_decoder.decode(s)
  File "D:\development\Python\lib\json\decoder.py", line 339, in decode
    obj, end = self.raw_decode(s, idx=_w(s, 0).end())
  File "D:\development\Python\lib\json\decoder.py", line 357, in raw_decode
    raise JSONDecodeError("Expecting value", s, err.value) from None
json.decoder.JSONDecodeError: Expecting value: line 1 column 1 (char 0)
2019-05-05 00:42:24,233 [Thread-2:13412] [django.request:228] [log:log_response] [ERROR]- Internal Server Error: /tf/tf/
Traceback (most recent call last):
  File "D:\development\Python\lib\site-packages\django\core\handlers\exception.py", line 34, in inner
    response = get_response(request)
  File "D:\development\Python\lib\site-packages\django\core\handlers\base.py", line 115, in _get_response
    response = self.process_exception_by_middleware(e, request)
  File "D:\development\Python\lib\site-packages\django\core\handlers\base.py", line 113, in _get_response
    response = wrapped_callback(request, *callback_args, **callback_kwargs)
  File "D:\workspace\workspace-python\plant\tf\views.py", line 20, in tf_plant
    result = json.loads(data)
  File "D:\development\Python\lib\json\__init__.py", line 354, in loads
    return _default_decoder.decode(s)
  File "D:\development\Python\lib\json\decoder.py", line 339, in decode
    obj, end = self.raw_decode(s, idx=_w(s, 0).end())
  File "D:\development\Python\lib\json\decoder.py", line 357, in raw_decode
    raise JSONDecodeError("Expecting value", s, err.value) from None
json.decoder.JSONDecodeError: Expecting value: line 1 column 1 (char 0)
2019-05-05 01:02:17,076 [Thread-2:8436] [django.request:228] [log:log_response] [ERROR]- Internal Server Error: /tf/tf/
Traceback (most recent call last):
  File "D:\development\Python\lib\site-packages\django\core\handlers\exception.py", line 34, in inner
    response = get_response(request)
  File "D:\development\Python\lib\site-packages\django\core\handlers\base.py", line 115, in _get_response
    response = self.process_exception_by_middleware(e, request)
  File "D:\development\Python\lib\site-packages\django\core\handlers\base.py", line 113, in _get_response
    response = wrapped_callback(request, *callback_args, **callback_kwargs)
  File "D:\workspace\workspace-python\plant\tf\views.py", line 17, in tf_plant
    path = tmp_dir + str(uuid.uuid4()) + os.path.splitext(img_file)[-1]
  File "D:\development\Python\lib\ntpath.py", line 224, in splitext
    p = os.fspath(p)
TypeError: expected str, bytes or os.PathLike object, not InMemoryUploadedFile
2019-05-05 01:52:38,706 [Thread-9:10200] [django.request:228] [log:log_response] [ERROR]- Internal Server Error: /tf/predictions/
Traceback (most recent call last):
  File "D:\development\Python\lib\site-packages\django\core\handlers\exception.py", line 34, in inner
    response = get_response(request)
  File "D:\development\Python\lib\site-packages\django\core\handlers\base.py", line 115, in _get_response
    response = self.process_exception_by_middleware(e, request)
  File "D:\development\Python\lib\site-packages\django\core\handlers\base.py", line 113, in _get_response
    response = wrapped_callback(request, *callback_args, **callback_kwargs)
  File "D:\workspace\workspace-python\plant\tf\views.py", line 17, in predictions
    path = tmp_dir + str(uuid.uuid4()) + '.' + img_file.name.split('.')[-1]
AttributeError: 'NoneType' object has no attribute 'name'
2019-05-05 01:53:18,908 [Thread-9:10200] [django.request:228] [log:log_response] [ERROR]- Internal Server Error: /tf/predictions/
Traceback (most recent call last):
  File "D:\development\Python\lib\site-packages\django\core\handlers\exception.py", line 34, in inner
    response = get_response(request)
  File "D:\development\Python\lib\site-packages\django\core\handlers\base.py", line 115, in _get_response
    response = self.process_exception_by_middleware(e, request)
  File "D:\development\Python\lib\site-packages\django\core\handlers\base.py", line 113, in _get_response
    response = wrapped_callback(request, *callback_args, **callback_kwargs)
  File "D:\workspace\workspace-python\plant\tf\views.py", line 17, in predictions
    path = tmp_dir + str(uuid.uuid4()) + '.' + img_file.name.split('.')[-1]
AttributeError: 'NoneType' object has no attribute 'name'
2019-05-05 01:53:34,699 [Thread-9:10200] [django.request:228] [log:log_response] [ERROR]- Internal Server Error: /tf/predictions/
Traceback (most recent call last):
  File "D:\development\Python\lib\site-packages\django\core\handlers\exception.py", line 34, in inner
    response = get_response(request)
  File "D:\development\Python\lib\site-packages\django\core\handlers\base.py", line 115, in _get_response
    response = self.process_exception_by_middleware(e, request)
  File "D:\development\Python\lib\site-packages\django\core\handlers\base.py", line 113, in _get_response
    response = wrapped_callback(request, *callback_args, **callback_kwargs)
  File "D:\workspace\workspace-python\plant\tf\views.py", line 17, in predictions
    path = tmp_dir + str(uuid.uuid4()) + '.' + img_file.name.split('.')[-1]
AttributeError: 'NoneType' object has no attribute 'name'
2019-05-05 01:56:13,823 [Thread-9:10200] [django.request:228] [log:log_response] [ERROR]- Internal Server Error: /tf/predictions/
Traceback (most recent call last):
  File "D:\development\Python\lib\site-packages\django\core\handlers\exception.py", line 34, in inner
    response = get_response(request)
  File "D:\development\Python\lib\site-packages\django\core\handlers\base.py", line 115, in _get_response
    response = self.process_exception_by_middleware(e, request)
  File "D:\development\Python\lib\site-packages\django\core\handlers\base.py", line 113, in _get_response
    response = wrapped_callback(request, *callback_args, **callback_kwargs)
  File "D:\workspace\workspace-python\plant\tf\views.py", line 17, in predictions
    path = tmp_dir + str(uuid.uuid4()) + '.' + img_file.name.split('.')[-1]
AttributeError: 'NoneType' object has no attribute 'name'
2019-05-05 01:56:21,270 [Thread-9:10200] [django.request:228] [log:log_response] [ERROR]- Internal Server Error: /tf/predictions/
Traceback (most recent call last):
  File "D:\development\Python\lib\site-packages\django\core\handlers\exception.py", line 34, in inner
    response = get_response(request)
  File "D:\development\Python\lib\site-packages\django\core\handlers\base.py", line 115, in _get_response
    response = self.process_exception_by_middleware(e, request)
  File "D:\development\Python\lib\site-packages\django\core\handlers\base.py", line 113, in _get_response
    response = wrapped_callback(request, *callback_args, **callback_kwargs)
  File "D:\workspace\workspace-python\plant\tf\views.py", line 17, in predictions
    path = tmp_dir + str(uuid.uuid4()) + '.' + img_file.name.split('.')[-1]
AttributeError: 'NoneType' object has no attribute 'name'
2019-05-05 01:56:39,505 [Thread-9:10200] [django.request:228] [log:log_response] [ERROR]- Internal Server Error: /tf/predictions/
Traceback (most recent call last):
  File "D:\development\Python\lib\site-packages\django\core\handlers\exception.py", line 34, in inner
    response = get_response(request)
  File "D:\development\Python\lib\site-packages\django\core\handlers\base.py", line 115, in _get_response
    response = self.process_exception_by_middleware(e, request)
  File "D:\development\Python\lib\site-packages\django\core\handlers\base.py", line 113, in _get_response
    response = wrapped_callback(request, *callback_args, **callback_kwargs)
  File "D:\workspace\workspace-python\plant\tf\views.py", line 17, in predictions
    path = tmp_dir + str(uuid.uuid4()) + '.' + img_file.name.split('.')[-1]
AttributeError: 'NoneType' object has no attribute 'name'
2019-05-05 01:57:31,109 [Thread-9:10200] [django.request:228] [log:log_response] [ERROR]- Internal Server Error: /tf/predictions/
Traceback (most recent call last):
  File "D:\development\Python\lib\site-packages\django\core\handlers\exception.py", line 34, in inner
    response = get_response(request)
  File "D:\development\Python\lib\site-packages\django\core\handlers\base.py", line 115, in _get_response
    response = self.process_exception_by_middleware(e, request)
  File "D:\development\Python\lib\site-packages\django\core\handlers\base.py", line 113, in _get_response
    response = wrapped_callback(request, *callback_args, **callback_kwargs)
  File "D:\workspace\workspace-python\plant\tf\views.py", line 17, in predictions
    path = tmp_dir + str(uuid.uuid4()) + '.' + img_file.name.split('.')[-1]
AttributeError: 'NoneType' object has no attribute 'name'
2019-05-05 01:59:38,531 [Thread-9:10200] [django.request:228] [log:log_response] [ERROR]- Internal Server Error: /tf/predictions/
Traceback (most recent call last):
  File "D:\development\Python\lib\site-packages\django\core\handlers\exception.py", line 34, in inner
    response = get_response(request)
  File "D:\development\Python\lib\site-packages\django\core\handlers\base.py", line 115, in _get_response
    response = self.process_exception_by_middleware(e, request)
  File "D:\development\Python\lib\site-packages\django\core\handlers\base.py", line 113, in _get_response
    response = wrapped_callback(request, *callback_args, **callback_kwargs)
  File "D:\workspace\workspace-python\plant\tf\views.py", line 17, in predictions
    path = tmp_dir + str(uuid.uuid4()) + '.' + img_file.name.split('.')[-1]
AttributeError: 'NoneType' object has no attribute 'name'
2019-05-05 02:01:16,422 [Thread-9:10200] [django.request:228] [log:log_response] [ERROR]- Internal Server Error: /tf/predictions/
Traceback (most recent call last):
  File "D:\development\Python\lib\site-packages\django\core\handlers\exception.py", line 34, in inner
    response = get_response(request)
  File "D:\development\Python\lib\site-packages\django\core\handlers\base.py", line 115, in _get_response
    response = self.process_exception_by_middleware(e, request)
  File "D:\development\Python\lib\site-packages\django\core\handlers\base.py", line 113, in _get_response
    response = wrapped_callback(request, *callback_args, **callback_kwargs)
  File "D:\workspace\workspace-python\plant\tf\views.py", line 17, in predictions
    path = tmp_dir + str(uuid.uuid4()) + '.' + img_file.name.split('.')[-1]
AttributeError: 'NoneType' object has no attribute 'name'
2019-05-05 02:02:57,646 [Thread-9:10200] [django.request:228] [log:log_response] [ERROR]- Internal Server Error: /tf/predictions/
Traceback (most recent call last):
  File "D:\development\Python\lib\site-packages\django\core\handlers\exception.py", line 34, in inner
    response = get_response(request)
  File "D:\development\Python\lib\site-packages\django\core\handlers\base.py", line 115, in _get_response
    response = self.process_exception_by_middleware(e, request)
  File "D:\development\Python\lib\site-packages\django\core\handlers\base.py", line 113, in _get_response
    response = wrapped_callback(request, *callback_args, **callback_kwargs)
  File "D:\workspace\workspace-python\plant\tf\views.py", line 17, in predictions
    path = tmp_dir + str(uuid.uuid4()) + '.' + img_file.name.split('.')[-1]
AttributeError: 'NoneType' object has no attribute 'name'
2019-05-05 02:03:06,345 [Thread-9:10200] [django.request:228] [log:log_response] [ERROR]- Internal Server Error: /tf/predictions/
Traceback (most recent call last):
  File "D:\development\Python\lib\site-packages\django\core\handlers\exception.py", line 34, in inner
    response = get_response(request)
  File "D:\development\Python\lib\site-packages\django\core\handlers\base.py", line 115, in _get_response
    response = self.process_exception_by_middleware(e, request)
  File "D:\development\Python\lib\site-packages\django\core\handlers\base.py", line 113, in _get_response
    response = wrapped_callback(request, *callback_args, **callback_kwargs)
  File "D:\workspace\workspace-python\plant\tf\views.py", line 17, in predictions
    path = tmp_dir + str(uuid.uuid4()) + '.' + img_file.name.split('.')[-1]
AttributeError: 'NoneType' object has no attribute 'name'
2019-05-05 02:03:07,543 [Thread-9:10200] [django.request:228] [log:log_response] [ERROR]- Internal Server Error: /tf/predictions/
Traceback (most recent call last):
  File "D:\development\Python\lib\site-packages\django\core\handlers\exception.py", line 34, in inner
    response = get_response(request)
  File "D:\development\Python\lib\site-packages\django\core\handlers\base.py", line 115, in _get_response
    response = self.process_exception_by_middleware(e, request)
  File "D:\development\Python\lib\site-packages\django\core\handlers\base.py", line 113, in _get_response
    response = wrapped_callback(request, *callback_args, **callback_kwargs)
  File "D:\workspace\workspace-python\plant\tf\views.py", line 17, in predictions
    path = tmp_dir + str(uuid.uuid4()) + '.' + img_file.name.split('.')[-1]
AttributeError: 'NoneType' object has no attribute 'name'
2019-05-05 02:32:54,977 [Thread-23:3104] [django.request:228] [log:log_response] [ERROR]- Internal Server Error: /tf/predictions/
Traceback (most recent call last):
  File "D:\development\Python\lib\site-packages\django\core\handlers\exception.py", line 34, in inner
    response = get_response(request)
  File "D:\development\Python\lib\site-packages\django\core\handlers\base.py", line 115, in _get_response
    response = self.process_exception_by_middleware(e, request)
  File "D:\development\Python\lib\site-packages\django\core\handlers\base.py", line 113, in _get_response
    response = wrapped_callback(request, *callback_args, **callback_kwargs)
  File "D:\workspace\workspace-python\plant\tf\views.py", line 17, in predictions
    path = tmp_dir + str(uuid.uuid4()) + '.' + img_file.name.split('.')[-1]
AttributeError: 'NoneType' object has no attribute 'name'
