2019-03-31 21:58:34,188 [Thread-2:11004] [django.request:228] [log:log_response] [ERROR]- Internal Server Error: /plant/user_center/
Traceback (most recent call last):
  File "D:\development\Python\lib\site-packages\django\core\handlers\exception.py", line 34, in inner
    response = get_response(request)
  File "D:\development\Python\lib\site-packages\django\core\handlers\base.py", line 126, in _get_response
    response = self.process_exception_by_middleware(e, request)
  File "D:\development\Python\lib\site-packages\django\core\handlers\base.py", line 124, in _get_response
    response = wrapped_callback(request, *callback_args, **callback_kwargs)
  File "D:\workspace\workspace-python\plant\application\views.py", line 69, in user_center
    user = cursor.query('select * from application_user')[0]
  File "D:\development\Python\lib\site-packages\django\db\backends\utils.py", line 24, in __getattr__
    cursor_attr = getattr(self.cursor, attr)
  File "D:\development\Python\lib\site-packages\django\db\backends\mysql\base.py", line 90, in __getattr__
    return getattr(self.cursor, attr)
AttributeError: 'Cursor' object has no attribute 'query'
2019-03-31 21:58:55,038 [Thread-2:8772] [django.request:228] [log:log_response] [ERROR]- Internal Server Error: /plant/user_center/
Traceback (most recent call last):
  File "D:\development\Python\lib\site-packages\django\core\handlers\exception.py", line 34, in inner
    response = get_response(request)
  File "D:\development\Python\lib\site-packages\django\core\handlers\base.py", line 126, in _get_response
    response = self.process_exception_by_middleware(e, request)
  File "D:\development\Python\lib\site-packages\django\core\handlers\base.py", line 124, in _get_response
    response = wrapped_callback(request, *callback_args, **callback_kwargs)
  File "D:\workspace\workspace-python\plant\application\views.py", line 69, in user_center
    user = cursor.execute('select * from application_user')[0]
TypeError: 'int' object is not subscriptable
2019-03-31 22:02:14,451 [Thread-4:10424] [django.request:228] [log:log_response] [ERROR]- Internal Server Error: /plant/user_center/
Traceback (most recent call last):
  File "D:\development\Python\lib\site-packages\django\core\handlers\exception.py", line 34, in inner
    response = get_response(request)
  File "D:\development\Python\lib\site-packages\django\core\handlers\base.py", line 126, in _get_response
    response = self.process_exception_by_middleware(e, request)
  File "D:\development\Python\lib\site-packages\django\core\handlers\base.py", line 124, in _get_response
    response = wrapped_callback(request, *callback_args, **callback_kwargs)
  File "D:\workspace\workspace-python\plant\application\views.py", line 69, in user_center
    user = cursor.execute('select * from application_user').fetchone()
TypeError: 'int' object is not subscriptable
2019-03-31 22:02:34,219 [Thread-2:6248] [django.request:228] [log:log_response] [ERROR]- Internal Server Error: /plant/user_center/
Traceback (most recent call last):
  File "D:\development\Python\lib\site-packages\django\core\handlers\exception.py", line 34, in inner
    response = get_response(request)
  File "D:\development\Python\lib\site-packages\django\core\handlers\base.py", line 126, in _get_response
    response = self.process_exception_by_middleware(e, request)
  File "D:\development\Python\lib\site-packages\django\core\handlers\base.py", line 124, in _get_response
    response = wrapped_callback(request, *callback_args, **callback_kwargs)
  File "D:\workspace\workspace-python\plant\application\views.py", line 69, in user_center
    user = cursor.execute('select * from application_user').fetchone()
AttributeError: 'int' object has no attribute 'fetchone'
2019-03-31 22:04:18,112 [Thread-2:6248] [django.request:228] [log:log_response] [ERROR]- Internal Server Error: /plant/user_center/
Traceback (most recent call last):
  File "D:\development\Python\lib\site-packages\django\core\handlers\exception.py", line 34, in inner
    response = get_response(request)
  File "D:\development\Python\lib\site-packages\django\core\handlers\base.py", line 126, in _get_response
    response = self.process_exception_by_middleware(e, request)
  File "D:\development\Python\lib\site-packages\django\core\handlers\base.py", line 124, in _get_response
    response = wrapped_callback(request, *callback_args, **callback_kwargs)
  File "D:\workspace\workspace-python\plant\application\views.py", line 69, in user_center
    user = cursor.execute('select * from application_user').fetchone()
AttributeError: 'int' object has no attribute 'fetchone'
2019-03-31 22:04:19,617 [Thread-2:6248] [django.request:228] [log:log_response] [ERROR]- Internal Server Error: /plant/user_center/
Traceback (most recent call last):
  File "D:\development\Python\lib\site-packages\django\core\handlers\exception.py", line 34, in inner
    response = get_response(request)
  File "D:\development\Python\lib\site-packages\django\core\handlers\base.py", line 126, in _get_response
    response = self.process_exception_by_middleware(e, request)
  File "D:\development\Python\lib\site-packages\django\core\handlers\base.py", line 124, in _get_response
    response = wrapped_callback(request, *callback_args, **callback_kwargs)
  File "D:\workspace\workspace-python\plant\application\views.py", line 69, in user_center
    user = cursor.execute('select * from application_user').fetchone()
AttributeError: 'int' object has no attribute 'fetchone'
2019-03-31 22:04:20,614 [Thread-2:6248] [django.request:228] [log:log_response] [ERROR]- Internal Server Error: /plant/user_center/
Traceback (most recent call last):
  File "D:\development\Python\lib\site-packages\django\core\handlers\exception.py", line 34, in inner
    response = get_response(request)
  File "D:\development\Python\lib\site-packages\django\core\handlers\base.py", line 126, in _get_response
    response = self.process_exception_by_middleware(e, request)
  File "D:\development\Python\lib\site-packages\django\core\handlers\base.py", line 124, in _get_response
    response = wrapped_callback(request, *callback_args, **callback_kwargs)
  File "D:\workspace\workspace-python\plant\application\views.py", line 69, in user_center
    user = cursor.execute('select * from application_user').fetchone()
AttributeError: 'int' object has no attribute 'fetchone'
2019-03-31 22:04:20,991 [Thread-2:6248] [django.request:228] [log:log_response] [ERROR]- Internal Server Error: /plant/user_center/
Traceback (most recent call last):
  File "D:\development\Python\lib\site-packages\django\core\handlers\exception.py", line 34, in inner
    response = get_response(request)
  File "D:\development\Python\lib\site-packages\django\core\handlers\base.py", line 126, in _get_response
    response = self.process_exception_by_middleware(e, request)
  File "D:\development\Python\lib\site-packages\django\core\handlers\base.py", line 124, in _get_response
    response = wrapped_callback(request, *callback_args, **callback_kwargs)
  File "D:\workspace\workspace-python\plant\application\views.py", line 69, in user_center
    user = cursor.execute('select * from application_user').fetchone()
AttributeError: 'int' object has no attribute 'fetchone'
2019-03-31 22:04:21,382 [Thread-2:6248] [django.request:228] [log:log_response] [ERROR]- Internal Server Error: /plant/user_center/
Traceback (most recent call last):
  File "D:\development\Python\lib\site-packages\django\core\handlers\exception.py", line 34, in inner
    response = get_response(request)
  File "D:\development\Python\lib\site-packages\django\core\handlers\base.py", line 126, in _get_response
    response = self.process_exception_by_middleware(e, request)
  File "D:\development\Python\lib\site-packages\django\core\handlers\base.py", line 124, in _get_response
    response = wrapped_callback(request, *callback_args, **callback_kwargs)
  File "D:\workspace\workspace-python\plant\application\views.py", line 69, in user_center
    user = cursor.execute('select * from application_user').fetchone()
AttributeError: 'int' object has no attribute 'fetchone'
2019-03-31 22:04:21,662 [Thread-3:9756] [django.request:228] [log:log_response] [ERROR]- Internal Server Error: /plant/user_center/
Traceback (most recent call last):
  File "D:\development\Python\lib\site-packages\django\core\handlers\exception.py", line 34, in inner
    response = get_response(request)
  File "D:\development\Python\lib\site-packages\django\core\handlers\base.py", line 126, in _get_response
    response = self.process_exception_by_middleware(e, request)
  File "D:\development\Python\lib\site-packages\django\core\handlers\base.py", line 124, in _get_response
    response = wrapped_callback(request, *callback_args, **callback_kwargs)
  File "D:\workspace\workspace-python\plant\application\views.py", line 69, in user_center
    user = cursor.execute('select * from application_user').fetchone()
AttributeError: 'int' object has no attribute 'fetchone'
2019-03-31 22:04:22,032 [Thread-3:9756] [django.request:228] [log:log_response] [ERROR]- Internal Server Error: /plant/user_center/
Traceback (most recent call last):
  File "D:\development\Python\lib\site-packages\django\core\handlers\exception.py", line 34, in inner
    response = get_response(request)
  File "D:\development\Python\lib\site-packages\django\core\handlers\base.py", line 126, in _get_response
    response = self.process_exception_by_middleware(e, request)
  File "D:\development\Python\lib\site-packages\django\core\handlers\base.py", line 124, in _get_response
    response = wrapped_callback(request, *callback_args, **callback_kwargs)
  File "D:\workspace\workspace-python\plant\application\views.py", line 69, in user_center
    user = cursor.execute('select * from application_user').fetchone()
AttributeError: 'int' object has no attribute 'fetchone'
INFO 2019-03-31 22:04:35,440 4
INFO 2019-03-31 22:24:02,869 0
2019-03-31 22:24:29,011 [Thread-2:11980] [django.request:228] [log:log_response] [ERROR]- Internal Server Error: /plant/user_center/
Traceback (most recent call last):
  File "D:\development\Python\lib\site-packages\django\core\handlers\exception.py", line 34, in inner
    response = get_response(request)
  File "D:\development\Python\lib\site-packages\django\core\handlers\base.py", line 126, in _get_response
    response = self.process_exception_by_middleware(e, request)
  File "D:\development\Python\lib\site-packages\django\core\handlers\base.py", line 124, in _get_response
    response = wrapped_callback(request, *callback_args, **callback_kwargs)
  File "D:\workspace\workspace-python\plant\application\views.py", line 69, in user_center
    user = cursor.execute('select * from user').fetchone()
AttributeError: 'int' object has no attribute 'fetchone'
2019-03-31 22:30:27,231 [Thread-6:9408] [django.request:228] [log:log_response] [ERROR]- Internal Server Error: /plant/user_update/
Traceback (most recent call last):
  File "D:\development\Python\lib\site-packages\django\db\backends\utils.py", line 83, in _execute
    return self.cursor.execute(sql)
  File "D:\development\Python\lib\site-packages\django\db\backends\mysql\base.py", line 71, in execute
    return self.cursor.execute(query, args)
  File "D:\development\Python\lib\site-packages\pymysql\cursors.py", line 170, in execute
    result = self._query(query)
  File "D:\development\Python\lib\site-packages\pymysql\cursors.py", line 328, in _query
    conn.query(q)
  File "D:\development\Python\lib\site-packages\pymysql\connections.py", line 516, in query
    self._affected_rows = self._read_query_result(unbuffered=unbuffered)
  File "D:\development\Python\lib\site-packages\pymysql\connections.py", line 727, in _read_query_result
    result.read()
  File "D:\development\Python\lib\site-packages\pymysql\connections.py", line 1066, in read
    first_packet = self.connection._read_packet()
  File "D:\development\Python\lib\site-packages\pymysql\connections.py", line 683, in _read_packet
    packet.check_error()
  File "D:\development\Python\lib\site-packages\pymysql\protocol.py", line 220, in check_error
    err.raise_mysql_exception(self._data)
  File "D:\development\Python\lib\site-packages\pymysql\err.py", line 109, in raise_mysql_exception
    raise errorclass(errno, errval)
pymysql.err.ProgrammingError: (1064, "You have an error in your SQL syntax; check the manual that corresponds to your MySQL server version for the right syntax to use near '@qq.com,1893456123)' at line 1")

The above exception was the direct cause of the following exception:

Traceback (most recent call last):
  File "D:\development\Python\lib\site-packages\django\core\handlers\exception.py", line 34, in inner
    response = get_response(request)
  File "D:\development\Python\lib\site-packages\django\core\handlers\base.py", line 126, in _get_response
    response = self.process_exception_by_middleware(e, request)
  File "D:\development\Python\lib\site-packages\django\core\handlers\base.py", line 124, in _get_response
    response = wrapped_callback(request, *callback_args, **callback_kwargs)
  File "D:\workspace\workspace-python\plant\application\views.py", line 82, in user_update
    % (name, pw, email, phone))
  File "D:\development\Python\lib\site-packages\django\db\backends\utils.py", line 100, in execute
    return super().execute(sql, params)
  File "D:\development\Python\lib\site-packages\django\db\backends\utils.py", line 68, in execute
    return self._execute_with_wrappers(sql, params, many=False, executor=self._execute)
  File "D:\development\Python\lib\site-packages\django\db\backends\utils.py", line 77, in _execute_with_wrappers
    return executor(sql, params, many, context)
  File "D:\development\Python\lib\site-packages\django\db\backends\utils.py", line 85, in _execute
    return self.cursor.execute(sql, params)
  File "D:\development\Python\lib\site-packages\django\db\utils.py", line 89, in __exit__
    raise dj_exc_value.with_traceback(traceback) from exc_value
  File "D:\development\Python\lib\site-packages\django\db\backends\utils.py", line 83, in _execute
    return self.cursor.execute(sql)
  File "D:\development\Python\lib\site-packages\django\db\backends\mysql\base.py", line 71, in execute
    return self.cursor.execute(query, args)
  File "D:\development\Python\lib\site-packages\pymysql\cursors.py", line 170, in execute
    result = self._query(query)
  File "D:\development\Python\lib\site-packages\pymysql\cursors.py", line 328, in _query
    conn.query(q)
  File "D:\development\Python\lib\site-packages\pymysql\connections.py", line 516, in query
    self._affected_rows = self._read_query_result(unbuffered=unbuffered)
  File "D:\development\Python\lib\site-packages\pymysql\connections.py", line 727, in _read_query_result
    result.read()
  File "D:\development\Python\lib\site-packages\pymysql\connections.py", line 1066, in read
    first_packet = self.connection._read_packet()
  File "D:\development\Python\lib\site-packages\pymysql\connections.py", line 683, in _read_packet
    packet.check_error()
  File "D:\development\Python\lib\site-packages\pymysql\protocol.py", line 220, in check_error
    err.raise_mysql_exception(self._data)
  File "D:\development\Python\lib\site-packages\pymysql\err.py", line 109, in raise_mysql_exception
    raise errorclass(errno, errval)
django.db.utils.ProgrammingError: (1064, "You have an error in your SQL syntax; check the manual that corresponds to your MySQL server version for the right syntax to use near '@qq.com,1893456123)' at line 1")
2019-03-31 22:31:33,595 [Thread-2:13188] [django.request:228] [log:log_response] [ERROR]- Internal Server Error: /plant/user_update/
Traceback (most recent call last):
  File "D:\development\Python\lib\site-packages\django\db\backends\utils.py", line 83, in _execute
    return self.cursor.execute(sql)
  File "D:\development\Python\lib\site-packages\django\db\backends\mysql\base.py", line 71, in execute
    return self.cursor.execute(query, args)
  File "D:\development\Python\lib\site-packages\pymysql\cursors.py", line 170, in execute
    result = self._query(query)
  File "D:\development\Python\lib\site-packages\pymysql\cursors.py", line 328, in _query
    conn.query(q)
  File "D:\development\Python\lib\site-packages\pymysql\connections.py", line 516, in query
    self._affected_rows = self._read_query_result(unbuffered=unbuffered)
  File "D:\development\Python\lib\site-packages\pymysql\connections.py", line 727, in _read_query_result
    result.read()
  File "D:\development\Python\lib\site-packages\pymysql\connections.py", line 1066, in read
    first_packet = self.connection._read_packet()
  File "D:\development\Python\lib\site-packages\pymysql\connections.py", line 683, in _read_packet
    packet.check_error()
  File "D:\development\Python\lib\site-packages\pymysql\protocol.py", line 220, in check_error
    err.raise_mysql_exception(self._data)
  File "D:\development\Python\lib\site-packages\pymysql\err.py", line 109, in raise_mysql_exception
    raise errorclass(errno, errval)
pymysql.err.ProgrammingError: (1064, "You have an error in your SQL syntax; check the manual that corresponds to your MySQL server version for the right syntax to use near '@qq.com,1893456123)' at line 1")

The above exception was the direct cause of the following exception:

Traceback (most recent call last):
  File "D:\development\Python\lib\site-packages\django\core\handlers\exception.py", line 34, in inner
    response = get_response(request)
  File "D:\development\Python\lib\site-packages\django\core\handlers\base.py", line 126, in _get_response
    response = self.process_exception_by_middleware(e, request)
  File "D:\development\Python\lib\site-packages\django\core\handlers\base.py", line 124, in _get_response
    response = wrapped_callback(request, *callback_args, **callback_kwargs)
  File "D:\workspace\workspace-python\plant\application\views.py", line 82, in user_update
    % (name, pw, email, phone))
  File "D:\development\Python\lib\site-packages\django\db\backends\utils.py", line 100, in execute
    return super().execute(sql, params)
  File "D:\development\Python\lib\site-packages\django\db\backends\utils.py", line 68, in execute
    return self._execute_with_wrappers(sql, params, many=False, executor=self._execute)
  File "D:\development\Python\lib\site-packages\django\db\backends\utils.py", line 77, in _execute_with_wrappers
    return executor(sql, params, many, context)
  File "D:\development\Python\lib\site-packages\django\db\backends\utils.py", line 85, in _execute
    return self.cursor.execute(sql, params)
  File "D:\development\Python\lib\site-packages\django\db\utils.py", line 89, in __exit__
    raise dj_exc_value.with_traceback(traceback) from exc_value
  File "D:\development\Python\lib\site-packages\django\db\backends\utils.py", line 83, in _execute
    return self.cursor.execute(sql)
  File "D:\development\Python\lib\site-packages\django\db\backends\mysql\base.py", line 71, in execute
    return self.cursor.execute(query, args)
  File "D:\development\Python\lib\site-packages\pymysql\cursors.py", line 170, in execute
    result = self._query(query)
  File "D:\development\Python\lib\site-packages\pymysql\cursors.py", line 328, in _query
    conn.query(q)
  File "D:\development\Python\lib\site-packages\pymysql\connections.py", line 516, in query
    self._affected_rows = self._read_query_result(unbuffered=unbuffered)
  File "D:\development\Python\lib\site-packages\pymysql\connections.py", line 727, in _read_query_result
    result.read()
  File "D:\development\Python\lib\site-packages\pymysql\connections.py", line 1066, in read
    first_packet = self.connection._read_packet()
  File "D:\development\Python\lib\site-packages\pymysql\connections.py", line 683, in _read_packet
    packet.check_error()
  File "D:\development\Python\lib\site-packages\pymysql\protocol.py", line 220, in check_error
    err.raise_mysql_exception(self._data)
  File "D:\development\Python\lib\site-packages\pymysql\err.py", line 109, in raise_mysql_exception
    raise errorclass(errno, errval)
django.db.utils.ProgrammingError: (1064, "You have an error in your SQL syntax; check the manual that corresponds to your MySQL server version for the right syntax to use near '@qq.com,1893456123)' at line 1")
2019-03-31 22:46:06,439 [Thread-2:14996] [django.request:228] [log:log_response] [ERROR]- Internal Server Error: /plant/user_update/
Traceback (most recent call last):
  File "D:\development\Python\lib\site-packages\django\db\backends\utils.py", line 83, in _execute
    return self.cursor.execute(sql)
  File "D:\development\Python\lib\site-packages\django\db\backends\mysql\base.py", line 71, in execute
    return self.cursor.execute(query, args)
  File "D:\development\Python\lib\site-packages\pymysql\cursors.py", line 170, in execute
    result = self._query(query)
  File "D:\development\Python\lib\site-packages\pymysql\cursors.py", line 328, in _query
    conn.query(q)
  File "D:\development\Python\lib\site-packages\pymysql\connections.py", line 516, in query
    self._affected_rows = self._read_query_result(unbuffered=unbuffered)
  File "D:\development\Python\lib\site-packages\pymysql\connections.py", line 727, in _read_query_result
    result.read()
  File "D:\development\Python\lib\site-packages\pymysql\connections.py", line 1066, in read
    first_packet = self.connection._read_packet()
  File "D:\development\Python\lib\site-packages\pymysql\connections.py", line 683, in _read_packet
    packet.check_error()
  File "D:\development\Python\lib\site-packages\pymysql\protocol.py", line 220, in check_error
    err.raise_mysql_exception(self._data)
  File "D:\development\Python\lib\site-packages\pymysql\err.py", line 109, in raise_mysql_exception
    raise errorclass(errno, errval)
pymysql.err.ProgrammingError: (1064, "You have an error in your SQL syntax; check the manual that corresponds to your MySQL server version for the right syntax to use near '@qq.com,1893456123)' at line 1")

The above exception was the direct cause of the following exception:

Traceback (most recent call last):
  File "D:\development\Python\lib\site-packages\django\core\handlers\exception.py", line 34, in inner
    response = get_response(request)
  File "D:\development\Python\lib\site-packages\django\core\handlers\base.py", line 126, in _get_response
    response = self.process_exception_by_middleware(e, request)
  File "D:\development\Python\lib\site-packages\django\core\handlers\base.py", line 124, in _get_response
    response = wrapped_callback(request, *callback_args, **callback_kwargs)
  File "D:\workspace\workspace-python\plant\application\views.py", line 83, in user_update
    cursor.execute(sql)
  File "D:\development\Python\lib\site-packages\django\db\backends\utils.py", line 100, in execute
    return super().execute(sql, params)
  File "D:\development\Python\lib\site-packages\django\db\backends\utils.py", line 68, in execute
    return self._execute_with_wrappers(sql, params, many=False, executor=self._execute)
  File "D:\development\Python\lib\site-packages\django\db\backends\utils.py", line 77, in _execute_with_wrappers
    return executor(sql, params, many, context)
  File "D:\development\Python\lib\site-packages\django\db\backends\utils.py", line 85, in _execute
    return self.cursor.execute(sql, params)
  File "D:\development\Python\lib\site-packages\django\db\utils.py", line 89, in __exit__
    raise dj_exc_value.with_traceback(traceback) from exc_value
  File "D:\development\Python\lib\site-packages\django\db\backends\utils.py", line 83, in _execute
    return self.cursor.execute(sql)
  File "D:\development\Python\lib\site-packages\django\db\backends\mysql\base.py", line 71, in execute
    return self.cursor.execute(query, args)
  File "D:\development\Python\lib\site-packages\pymysql\cursors.py", line 170, in execute
    result = self._query(query)
  File "D:\development\Python\lib\site-packages\pymysql\cursors.py", line 328, in _query
    conn.query(q)
  File "D:\development\Python\lib\site-packages\pymysql\connections.py", line 516, in query
    self._affected_rows = self._read_query_result(unbuffered=unbuffered)
  File "D:\development\Python\lib\site-packages\pymysql\connections.py", line 727, in _read_query_result
    result.read()
  File "D:\development\Python\lib\site-packages\pymysql\connections.py", line 1066, in read
    first_packet = self.connection._read_packet()
  File "D:\development\Python\lib\site-packages\pymysql\connections.py", line 683, in _read_packet
    packet.check_error()
  File "D:\development\Python\lib\site-packages\pymysql\protocol.py", line 220, in check_error
    err.raise_mysql_exception(self._data)
  File "D:\development\Python\lib\site-packages\pymysql\err.py", line 109, in raise_mysql_exception
    raise errorclass(errno, errval)
django.db.utils.ProgrammingError: (1064, "You have an error in your SQL syntax; check the manual that corresponds to your MySQL server version for the right syntax to use near '@qq.com,1893456123)' at line 1")
2019-03-31 22:47:04,776 [Thread-2:2860] [django.request:228] [log:log_response] [ERROR]- Internal Server Error: /plant/user_update/
Traceback (most recent call last):
  File "D:\development\Python\lib\site-packages\django\db\backends\utils.py", line 83, in _execute
    return self.cursor.execute(sql)
  File "D:\development\Python\lib\site-packages\django\db\backends\mysql\base.py", line 71, in execute
    return self.cursor.execute(query, args)
  File "D:\development\Python\lib\site-packages\pymysql\cursors.py", line 170, in execute
    result = self._query(query)
  File "D:\development\Python\lib\site-packages\pymysql\cursors.py", line 328, in _query
    conn.query(q)
  File "D:\development\Python\lib\site-packages\pymysql\connections.py", line 516, in query
    self._affected_rows = self._read_query_result(unbuffered=unbuffered)
  File "D:\development\Python\lib\site-packages\pymysql\connections.py", line 727, in _read_query_result
    result.read()
  File "D:\development\Python\lib\site-packages\pymysql\connections.py", line 1066, in read
    first_packet = self.connection._read_packet()
  File "D:\development\Python\lib\site-packages\pymysql\connections.py", line 683, in _read_packet
    packet.check_error()
  File "D:\development\Python\lib\site-packages\pymysql\protocol.py", line 220, in check_error
    err.raise_mysql_exception(self._data)
  File "D:\development\Python\lib\site-packages\pymysql\err.py", line 109, in raise_mysql_exception
    raise errorclass(errno, errval)
pymysql.err.ProgrammingError: (1064, "You have an error in your SQL syntax; check the manual that corresponds to your MySQL server version for the right syntax to use near '@qq.com,1893456123)' at line 1")

The above exception was the direct cause of the following exception:

Traceback (most recent call last):
  File "D:\development\Python\lib\site-packages\django\core\handlers\exception.py", line 34, in inner
    response = get_response(request)
  File "D:\development\Python\lib\site-packages\django\core\handlers\base.py", line 126, in _get_response
    response = self.process_exception_by_middleware(e, request)
  File "D:\development\Python\lib\site-packages\django\core\handlers\base.py", line 124, in _get_response
    response = wrapped_callback(request, *callback_args, **callback_kwargs)
  File "D:\workspace\workspace-python\plant\application\views.py", line 83, in user_update
    cursor.execute(sql)
  File "D:\development\Python\lib\site-packages\django\db\backends\utils.py", line 100, in execute
    return super().execute(sql, params)
  File "D:\development\Python\lib\site-packages\django\db\backends\utils.py", line 68, in execute
    return self._execute_with_wrappers(sql, params, many=False, executor=self._execute)
  File "D:\development\Python\lib\site-packages\django\db\backends\utils.py", line 77, in _execute_with_wrappers
    return executor(sql, params, many, context)
  File "D:\development\Python\lib\site-packages\django\db\backends\utils.py", line 85, in _execute
    return self.cursor.execute(sql, params)
  File "D:\development\Python\lib\site-packages\django\db\utils.py", line 89, in __exit__
    raise dj_exc_value.with_traceback(traceback) from exc_value
  File "D:\development\Python\lib\site-packages\django\db\backends\utils.py", line 83, in _execute
    return self.cursor.execute(sql)
  File "D:\development\Python\lib\site-packages\django\db\backends\mysql\base.py", line 71, in execute
    return self.cursor.execute(query, args)
  File "D:\development\Python\lib\site-packages\pymysql\cursors.py", line 170, in execute
    result = self._query(query)
  File "D:\development\Python\lib\site-packages\pymysql\cursors.py", line 328, in _query
    conn.query(q)
  File "D:\development\Python\lib\site-packages\pymysql\connections.py", line 516, in query
    self._affected_rows = self._read_query_result(unbuffered=unbuffered)
  File "D:\development\Python\lib\site-packages\pymysql\connections.py", line 727, in _read_query_result
    result.read()
  File "D:\development\Python\lib\site-packages\pymysql\connections.py", line 1066, in read
    first_packet = self.connection._read_packet()
  File "D:\development\Python\lib\site-packages\pymysql\connections.py", line 683, in _read_packet
    packet.check_error()
  File "D:\development\Python\lib\site-packages\pymysql\protocol.py", line 220, in check_error
    err.raise_mysql_exception(self._data)
  File "D:\development\Python\lib\site-packages\pymysql\err.py", line 109, in raise_mysql_exception
    raise errorclass(errno, errval)
django.db.utils.ProgrammingError: (1064, "You have an error in your SQL syntax; check the manual that corresponds to your MySQL server version for the right syntax to use near '@qq.com,1893456123)' at line 1")
INFO 2019-03-31 22:50:42,344 huanginsert into user (name,password,email,phone) values ('shengjie','123','111@qq.com','18940980533')
2019-03-31 22:52:55,345 [Thread-2:12256] [django.request:228] [log:log_response] [ERROR]- Internal Server Error: /plant/user_update/
Traceback (most recent call last):
  File "D:\development\Python\lib\site-packages\django\db\backends\utils.py", line 83, in _execute
    return self.cursor.execute(sql)
  File "D:\development\Python\lib\site-packages\django\db\backends\mysql\base.py", line 71, in execute
    return self.cursor.execute(query, args)
  File "D:\development\Python\lib\site-packages\pymysql\cursors.py", line 170, in execute
    result = self._query(query)
  File "D:\development\Python\lib\site-packages\pymysql\cursors.py", line 328, in _query
    conn.query(q)
  File "D:\development\Python\lib\site-packages\pymysql\connections.py", line 516, in query
    self._affected_rows = self._read_query_result(unbuffered=unbuffered)
  File "D:\development\Python\lib\site-packages\pymysql\connections.py", line 727, in _read_query_result
    result.read()
  File "D:\development\Python\lib\site-packages\pymysql\connections.py", line 1066, in read
    first_packet = self.connection._read_packet()
  File "D:\development\Python\lib\site-packages\pymysql\connections.py", line 683, in _read_packet
    packet.check_error()
  File "D:\development\Python\lib\site-packages\pymysql\protocol.py", line 220, in check_error
    err.raise_mysql_exception(self._data)
  File "D:\development\Python\lib\site-packages\pymysql\err.py", line 109, in raise_mysql_exception
    raise errorclass(errno, errval)
pymysql.err.IntegrityError: (1062, "Duplicate entry '18940980522' for key 'phone'")

The above exception was the direct cause of the following exception:

Traceback (most recent call last):
  File "D:\development\Python\lib\site-packages\django\core\handlers\exception.py", line 34, in inner
    response = get_response(request)
  File "D:\development\Python\lib\site-packages\django\core\handlers\base.py", line 126, in _get_response
    response = self.process_exception_by_middleware(e, request)
  File "D:\development\Python\lib\site-packages\django\core\handlers\base.py", line 124, in _get_response
    response = wrapped_callback(request, *callback_args, **callback_kwargs)
  File "D:\workspace\workspace-python\plant\application\views.py", line 85, in user_update
    cursor.execute(sql)
  File "D:\development\Python\lib\site-packages\django\db\backends\utils.py", line 100, in execute
    return super().execute(sql, params)
  File "D:\development\Python\lib\site-packages\django\db\backends\utils.py", line 68, in execute
    return self._execute_with_wrappers(sql, params, many=False, executor=self._execute)
  File "D:\development\Python\lib\site-packages\django\db\backends\utils.py", line 77, in _execute_with_wrappers
    return executor(sql, params, many, context)
  File "D:\development\Python\lib\site-packages\django\db\backends\utils.py", line 85, in _execute
    return self.cursor.execute(sql, params)
  File "D:\development\Python\lib\site-packages\django\db\utils.py", line 89, in __exit__
    raise dj_exc_value.with_traceback(traceback) from exc_value
  File "D:\development\Python\lib\site-packages\django\db\backends\utils.py", line 83, in _execute
    return self.cursor.execute(sql)
  File "D:\development\Python\lib\site-packages\django\db\backends\mysql\base.py", line 71, in execute
    return self.cursor.execute(query, args)
  File "D:\development\Python\lib\site-packages\pymysql\cursors.py", line 170, in execute
    result = self._query(query)
  File "D:\development\Python\lib\site-packages\pymysql\cursors.py", line 328, in _query
    conn.query(q)
  File "D:\development\Python\lib\site-packages\pymysql\connections.py", line 516, in query
    self._affected_rows = self._read_query_result(unbuffered=unbuffered)
  File "D:\development\Python\lib\site-packages\pymysql\connections.py", line 727, in _read_query_result
    result.read()
  File "D:\development\Python\lib\site-packages\pymysql\connections.py", line 1066, in read
    first_packet = self.connection._read_packet()
  File "D:\development\Python\lib\site-packages\pymysql\connections.py", line 683, in _read_packet
    packet.check_error()
  File "D:\development\Python\lib\site-packages\pymysql\protocol.py", line 220, in check_error
    err.raise_mysql_exception(self._data)
  File "D:\development\Python\lib\site-packages\pymysql\err.py", line 109, in raise_mysql_exception
    raise errorclass(errno, errval)
django.db.utils.IntegrityError: (1062, "Duplicate entry '18940980522' for key 'phone'")
INFO 2019-03-31 22:53:14,735 huanginsert into user (name,password,email,phone) values ('xiu','123','55@qqq.com','18940980520')
2019-03-31 23:18:02,808 [Thread-2:9304] [django.request:228] [log:log_response] [ERROR]- Internal Server Error: /plant/login/
Traceback (most recent call last):
  File "D:\development\Python\lib\site-packages\django\core\handlers\exception.py", line 34, in inner
    response = get_response(request)
  File "D:\development\Python\lib\site-packages\django\core\handlers\base.py", line 126, in _get_response
    response = self.process_exception_by_middleware(e, request)
  File "D:\development\Python\lib\site-packages\django\core\handlers\base.py", line 124, in _get_response
    response = wrapped_callback(request, *callback_args, **callback_kwargs)
  File "D:\workspace\workspace-python\plant\application\views.py", line 116, in login
    request.session['user'+user.id] = user.id
TypeError: can only concatenate str (not "int") to str
2019-03-31 23:18:43,644 [Thread-3:12304] [django.request:228] [log:log_response] [ERROR]- Internal Server Error: /plant/login/
Traceback (most recent call last):
  File "D:\development\Python\lib\site-packages\django\core\handlers\exception.py", line 34, in inner
    response = get_response(request)
  File "D:\development\Python\lib\site-packages\django\core\handlers\base.py", line 126, in _get_response
    response = self.process_exception_by_middleware(e, request)
  File "D:\development\Python\lib\site-packages\django\core\handlers\base.py", line 124, in _get_response
    response = wrapped_callback(request, *callback_args, **callback_kwargs)
  File "D:\workspace\workspace-python\plant\application\views.py", line 116, in login
    request.session['user'+user.id] = user.id
TypeError: can only concatenate str (not "int") to str
2019-03-31 23:21:02,420 [Thread-3:8364] [django.request:228] [log:log_response] [ERROR]- Internal Server Error: /plant/login/
Traceback (most recent call last):
  File "D:\development\Python\lib\site-packages\django\core\handlers\exception.py", line 34, in inner
    response = get_response(request)
  File "D:\development\Python\lib\site-packages\django\core\handlers\base.py", line 126, in _get_response
    response = self.process_exception_by_middleware(e, request)
  File "D:\development\Python\lib\site-packages\django\core\handlers\base.py", line 124, in _get_response
    response = wrapped_callback(request, *callback_args, **callback_kwargs)
  File "D:\workspace\workspace-python\plant\application\views.py", line 117, in login
    response = render(request, '')
  File "D:\development\Python\lib\site-packages\django\shortcuts.py", line 36, in render
    content = loader.render_to_string(template_name, context, request, using=using)
  File "D:\development\Python\lib\site-packages\django\template\loader.py", line 61, in render_to_string
    template = get_template(template_name, using=using)
  File "D:\development\Python\lib\site-packages\django\template\loader.py", line 15, in get_template
    return engine.get_template(template_name)
  File "D:\development\Python\lib\site-packages\django\template\backends\django.py", line 34, in get_template
    return Template(self.engine.get_template(template_name), self)
  File "D:\development\Python\lib\site-packages\django\template\engine.py", line 144, in get_template
    template, origin = self.find_template(template_name)
  File "D:\development\Python\lib\site-packages\django\template\engine.py", line 126, in find_template
    template = loader.get_template(name, skip=skip)
  File "D:\development\Python\lib\site-packages\django\template\loaders\base.py", line 24, in get_template
    contents = self.get_contents(origin)
  File "D:\development\Python\lib\site-packages\django\template\loaders\filesystem.py", line 23, in get_contents
    with open(origin.name, encoding=self.engine.file_charset) as fp:
PermissionError: [Errno 13] Permission denied: 'D:\\workspace\\workspace-python\\plant\\application\\templates'
2019-04-07 11:28:48,721 [Thread-12:13536] [django.request:228] [log:log_response] [ERROR]- Internal Server Error: /admin/application/notify/add/
Traceback (most recent call last):
  File "D:\development\Python\lib\site-packages\django\db\backends\utils.py", line 85, in _execute
    return self.cursor.execute(sql, params)
  File "D:\development\Python\lib\site-packages\django\db\backends\mysql\base.py", line 71, in execute
    return self.cursor.execute(query, args)
  File "D:\development\Python\lib\site-packages\pymysql\cursors.py", line 170, in execute
    result = self._query(query)
  File "D:\development\Python\lib\site-packages\pymysql\cursors.py", line 328, in _query
    conn.query(q)
  File "D:\development\Python\lib\site-packages\pymysql\connections.py", line 516, in query
    self._affected_rows = self._read_query_result(unbuffered=unbuffered)
  File "D:\development\Python\lib\site-packages\pymysql\connections.py", line 727, in _read_query_result
    result.read()
  File "D:\development\Python\lib\site-packages\pymysql\connections.py", line 1066, in read
    first_packet = self.connection._read_packet()
  File "D:\development\Python\lib\site-packages\pymysql\connections.py", line 683, in _read_packet
    packet.check_error()
  File "D:\development\Python\lib\site-packages\pymysql\protocol.py", line 220, in check_error
    err.raise_mysql_exception(self._data)
  File "D:\development\Python\lib\site-packages\pymysql\err.py", line 109, in raise_mysql_exception
    raise errorclass(errno, errval)
pymysql.err.InternalError: (1366, "Incorrect string value: '\\xE5\\x93\\x88\\xE5\\x93\\x88...' for column 'title' at row 1")

The above exception was the direct cause of the following exception:

Traceback (most recent call last):
  File "D:\development\Python\lib\site-packages\django\core\handlers\exception.py", line 34, in inner
    response = get_response(request)
  File "D:\development\Python\lib\site-packages\django\core\handlers\base.py", line 126, in _get_response
    response = self.process_exception_by_middleware(e, request)
  File "D:\development\Python\lib\site-packages\django\core\handlers\base.py", line 124, in _get_response
    response = wrapped_callback(request, *callback_args, **callback_kwargs)
  File "D:\development\Python\lib\site-packages\django\contrib\admin\options.py", line 604, in wrapper
    return self.admin_site.admin_view(view)(*args, **kwargs)
  File "D:\development\Python\lib\site-packages\django\utils\decorators.py", line 142, in _wrapped_view
    response = view_func(request, *args, **kwargs)
  File "D:\development\Python\lib\site-packages\django\views\decorators\cache.py", line 44, in _wrapped_view_func
    response = view_func(request, *args, **kwargs)
  File "D:\development\Python\lib\site-packages\django\contrib\admin\sites.py", line 223, in inner
    return view(request, *args, **kwargs)
  File "D:\development\Python\lib\site-packages\django\contrib\admin\options.py", line 1637, in add_view
    return self.changeform_view(request, None, form_url, extra_context)
  File "D:\development\Python\lib\site-packages\django\utils\decorators.py", line 45, in _wrapper
    return bound_method(*args, **kwargs)
  File "D:\development\Python\lib\site-packages\django\utils\decorators.py", line 142, in _wrapped_view
    response = view_func(request, *args, **kwargs)
  File "D:\development\Python\lib\site-packages\django\contrib\admin\options.py", line 1525, in changeform_view
    return self._changeform_view(request, object_id, form_url, extra_context)
  File "D:\development\Python\lib\site-packages\django\contrib\admin\options.py", line 1564, in _changeform_view
    self.save_model(request, new_object, form, not add)
  File "D:\development\Python\lib\site-packages\django\contrib\admin\options.py", line 1091, in save_model
    obj.save()
  File "D:\development\Python\lib\site-packages\django\db\models\base.py", line 718, in save
    force_update=force_update, update_fields=update_fields)
  File "D:\development\Python\lib\site-packages\django\db\models\base.py", line 748, in save_base
    updated = self._save_table(raw, cls, force_insert, force_update, using, update_fields)
  File "D:\development\Python\lib\site-packages\django\db\models\base.py", line 831, in _save_table
    result = self._do_insert(cls._base_manager, using, fields, update_pk, raw)
  File "D:\development\Python\lib\site-packages\django\db\models\base.py", line 869, in _do_insert
    using=using, raw=raw)
  File "D:\development\Python\lib\site-packages\django\db\models\manager.py", line 82, in manager_method
    return getattr(self.get_queryset(), name)(*args, **kwargs)
  File "D:\development\Python\lib\site-packages\django\db\models\query.py", line 1136, in _insert
    return query.get_compiler(using=using).execute_sql(return_id)
  File "D:\development\Python\lib\site-packages\django\db\models\sql\compiler.py", line 1289, in execute_sql
    cursor.execute(sql, params)
  File "D:\development\Python\lib\site-packages\django\db\backends\utils.py", line 100, in execute
    return super().execute(sql, params)
  File "D:\development\Python\lib\site-packages\django\db\backends\utils.py", line 68, in execute
    return self._execute_with_wrappers(sql, params, many=False, executor=self._execute)
  File "D:\development\Python\lib\site-packages\django\db\backends\utils.py", line 77, in _execute_with_wrappers
    return executor(sql, params, many, context)
  File "D:\development\Python\lib\site-packages\django\db\backends\utils.py", line 85, in _execute
    return self.cursor.execute(sql, params)
  File "D:\development\Python\lib\site-packages\django\db\utils.py", line 89, in __exit__
    raise dj_exc_value.with_traceback(traceback) from exc_value
  File "D:\development\Python\lib\site-packages\django\db\backends\utils.py", line 85, in _execute
    return self.cursor.execute(sql, params)
  File "D:\development\Python\lib\site-packages\django\db\backends\mysql\base.py", line 71, in execute
    return self.cursor.execute(query, args)
  File "D:\development\Python\lib\site-packages\pymysql\cursors.py", line 170, in execute
    result = self._query(query)
  File "D:\development\Python\lib\site-packages\pymysql\cursors.py", line 328, in _query
    conn.query(q)
  File "D:\development\Python\lib\site-packages\pymysql\connections.py", line 516, in query
    self._affected_rows = self._read_query_result(unbuffered=unbuffered)
  File "D:\development\Python\lib\site-packages\pymysql\connections.py", line 727, in _read_query_result
    result.read()
  File "D:\development\Python\lib\site-packages\pymysql\connections.py", line 1066, in read
    first_packet = self.connection._read_packet()
  File "D:\development\Python\lib\site-packages\pymysql\connections.py", line 683, in _read_packet
    packet.check_error()
  File "D:\development\Python\lib\site-packages\pymysql\protocol.py", line 220, in check_error
    err.raise_mysql_exception(self._data)
  File "D:\development\Python\lib\site-packages\pymysql\err.py", line 109, in raise_mysql_exception
    raise errorclass(errno, errval)
django.db.utils.InternalError: (1366, "Incorrect string value: '\\xE5\\x93\\x88\\xE5\\x93\\x88...' for column 'title' at row 1")
2019-04-07 11:30:21,785 [Thread-12:13536] [django.request:228] [log:log_response] [ERROR]- Internal Server Error: /admin/application/notify/add/
Traceback (most recent call last):
  File "D:\development\Python\lib\site-packages\django\db\backends\utils.py", line 85, in _execute
    return self.cursor.execute(sql, params)
  File "D:\development\Python\lib\site-packages\django\db\backends\mysql\base.py", line 71, in execute
    return self.cursor.execute(query, args)
  File "D:\development\Python\lib\site-packages\pymysql\cursors.py", line 170, in execute
    result = self._query(query)
  File "D:\development\Python\lib\site-packages\pymysql\cursors.py", line 328, in _query
    conn.query(q)
  File "D:\development\Python\lib\site-packages\pymysql\connections.py", line 516, in query
    self._affected_rows = self._read_query_result(unbuffered=unbuffered)
  File "D:\development\Python\lib\site-packages\pymysql\connections.py", line 727, in _read_query_result
    result.read()
  File "D:\development\Python\lib\site-packages\pymysql\connections.py", line 1066, in read
    first_packet = self.connection._read_packet()
  File "D:\development\Python\lib\site-packages\pymysql\connections.py", line 683, in _read_packet
    packet.check_error()
  File "D:\development\Python\lib\site-packages\pymysql\protocol.py", line 220, in check_error
    err.raise_mysql_exception(self._data)
  File "D:\development\Python\lib\site-packages\pymysql\err.py", line 109, in raise_mysql_exception
    raise errorclass(errno, errval)
pymysql.err.InternalError: (1366, "Incorrect string value: '\\xE5\\x93\\x88\\xE5\\x93\\x88...' for column 'title' at row 1")

The above exception was the direct cause of the following exception:

Traceback (most recent call last):
  File "D:\development\Python\lib\site-packages\django\core\handlers\exception.py", line 34, in inner
    response = get_response(request)
  File "D:\development\Python\lib\site-packages\django\core\handlers\base.py", line 126, in _get_response
    response = self.process_exception_by_middleware(e, request)
  File "D:\development\Python\lib\site-packages\django\core\handlers\base.py", line 124, in _get_response
    response = wrapped_callback(request, *callback_args, **callback_kwargs)
  File "D:\development\Python\lib\site-packages\django\contrib\admin\options.py", line 604, in wrapper
    return self.admin_site.admin_view(view)(*args, **kwargs)
  File "D:\development\Python\lib\site-packages\django\utils\decorators.py", line 142, in _wrapped_view
    response = view_func(request, *args, **kwargs)
  File "D:\development\Python\lib\site-packages\django\views\decorators\cache.py", line 44, in _wrapped_view_func
    response = view_func(request, *args, **kwargs)
  File "D:\development\Python\lib\site-packages\django\contrib\admin\sites.py", line 223, in inner
    return view(request, *args, **kwargs)
  File "D:\development\Python\lib\site-packages\django\contrib\admin\options.py", line 1637, in add_view
    return self.changeform_view(request, None, form_url, extra_context)
  File "D:\development\Python\lib\site-packages\django\utils\decorators.py", line 45, in _wrapper
    return bound_method(*args, **kwargs)
  File "D:\development\Python\lib\site-packages\django\utils\decorators.py", line 142, in _wrapped_view
    response = view_func(request, *args, **kwargs)
  File "D:\development\Python\lib\site-packages\django\contrib\admin\options.py", line 1525, in changeform_view
    return self._changeform_view(request, object_id, form_url, extra_context)
  File "D:\development\Python\lib\site-packages\django\contrib\admin\options.py", line 1564, in _changeform_view
    self.save_model(request, new_object, form, not add)
  File "D:\development\Python\lib\site-packages\django\contrib\admin\options.py", line 1091, in save_model
    obj.save()
  File "D:\development\Python\lib\site-packages\django\db\models\base.py", line 718, in save
    force_update=force_update, update_fields=update_fields)
  File "D:\development\Python\lib\site-packages\django\db\models\base.py", line 748, in save_base
    updated = self._save_table(raw, cls, force_insert, force_update, using, update_fields)
  File "D:\development\Python\lib\site-packages\django\db\models\base.py", line 831, in _save_table
    result = self._do_insert(cls._base_manager, using, fields, update_pk, raw)
  File "D:\development\Python\lib\site-packages\django\db\models\base.py", line 869, in _do_insert
    using=using, raw=raw)
  File "D:\development\Python\lib\site-packages\django\db\models\manager.py", line 82, in manager_method
    return getattr(self.get_queryset(), name)(*args, **kwargs)
  File "D:\development\Python\lib\site-packages\django\db\models\query.py", line 1136, in _insert
    return query.get_compiler(using=using).execute_sql(return_id)
  File "D:\development\Python\lib\site-packages\django\db\models\sql\compiler.py", line 1289, in execute_sql
    cursor.execute(sql, params)
  File "D:\development\Python\lib\site-packages\django\db\backends\utils.py", line 100, in execute
    return super().execute(sql, params)
  File "D:\development\Python\lib\site-packages\django\db\backends\utils.py", line 68, in execute
    return self._execute_with_wrappers(sql, params, many=False, executor=self._execute)
  File "D:\development\Python\lib\site-packages\django\db\backends\utils.py", line 77, in _execute_with_wrappers
    return executor(sql, params, many, context)
  File "D:\development\Python\lib\site-packages\django\db\backends\utils.py", line 85, in _execute
    return self.cursor.execute(sql, params)
  File "D:\development\Python\lib\site-packages\django\db\utils.py", line 89, in __exit__
    raise dj_exc_value.with_traceback(traceback) from exc_value
  File "D:\development\Python\lib\site-packages\django\db\backends\utils.py", line 85, in _execute
    return self.cursor.execute(sql, params)
  File "D:\development\Python\lib\site-packages\django\db\backends\mysql\base.py", line 71, in execute
    return self.cursor.execute(query, args)
  File "D:\development\Python\lib\site-packages\pymysql\cursors.py", line 170, in execute
    result = self._query(query)
  File "D:\development\Python\lib\site-packages\pymysql\cursors.py", line 328, in _query
    conn.query(q)
  File "D:\development\Python\lib\site-packages\pymysql\connections.py", line 516, in query
    self._affected_rows = self._read_query_result(unbuffered=unbuffered)
  File "D:\development\Python\lib\site-packages\pymysql\connections.py", line 727, in _read_query_result
    result.read()
  File "D:\development\Python\lib\site-packages\pymysql\connections.py", line 1066, in read
    first_packet = self.connection._read_packet()
  File "D:\development\Python\lib\site-packages\pymysql\connections.py", line 683, in _read_packet
    packet.check_error()
  File "D:\development\Python\lib\site-packages\pymysql\protocol.py", line 220, in check_error
    err.raise_mysql_exception(self._data)
  File "D:\development\Python\lib\site-packages\pymysql\err.py", line 109, in raise_mysql_exception
    raise errorclass(errno, errval)
django.db.utils.InternalError: (1366, "Incorrect string value: '\\xE5\\x93\\x88\\xE5\\x93\\x88...' for column 'title' at row 1")
2019-04-07 11:34:29,279 [Thread-31:4036] [django.request:228] [log:log_response] [ERROR]- Internal Server Error: /admin/application/news/add/
Traceback (most recent call last):
  File "D:\development\Python\lib\site-packages\django\db\backends\utils.py", line 85, in _execute
    return self.cursor.execute(sql, params)
  File "D:\development\Python\lib\site-packages\django\db\backends\mysql\base.py", line 71, in execute
    return self.cursor.execute(query, args)
  File "D:\development\Python\lib\site-packages\pymysql\cursors.py", line 170, in execute
    result = self._query(query)
  File "D:\development\Python\lib\site-packages\pymysql\cursors.py", line 328, in _query
    conn.query(q)
  File "D:\development\Python\lib\site-packages\pymysql\connections.py", line 516, in query
    self._affected_rows = self._read_query_result(unbuffered=unbuffered)
  File "D:\development\Python\lib\site-packages\pymysql\connections.py", line 727, in _read_query_result
    result.read()
  File "D:\development\Python\lib\site-packages\pymysql\connections.py", line 1066, in read
    first_packet = self.connection._read_packet()
  File "D:\development\Python\lib\site-packages\pymysql\connections.py", line 683, in _read_packet
    packet.check_error()
  File "D:\development\Python\lib\site-packages\pymysql\protocol.py", line 220, in check_error
    err.raise_mysql_exception(self._data)
  File "D:\development\Python\lib\site-packages\pymysql\err.py", line 109, in raise_mysql_exception
    raise errorclass(errno, errval)
pymysql.err.InternalError: (1366, "Incorrect string value: '\\xE5\\x93\\x88\\xE5\\x93\\x88...' for column 'title' at row 1")

The above exception was the direct cause of the following exception:

Traceback (most recent call last):
  File "D:\development\Python\lib\site-packages\django\core\handlers\exception.py", line 34, in inner
    response = get_response(request)
  File "D:\development\Python\lib\site-packages\django\core\handlers\base.py", line 126, in _get_response
    response = self.process_exception_by_middleware(e, request)
  File "D:\development\Python\lib\site-packages\django\core\handlers\base.py", line 124, in _get_response
    response = wrapped_callback(request, *callback_args, **callback_kwargs)
  File "D:\development\Python\lib\site-packages\django\contrib\admin\options.py", line 604, in wrapper
    return self.admin_site.admin_view(view)(*args, **kwargs)
  File "D:\development\Python\lib\site-packages\django\utils\decorators.py", line 142, in _wrapped_view
    response = view_func(request, *args, **kwargs)
  File "D:\development\Python\lib\site-packages\django\views\decorators\cache.py", line 44, in _wrapped_view_func
    response = view_func(request, *args, **kwargs)
  File "D:\development\Python\lib\site-packages\django\contrib\admin\sites.py", line 223, in inner
    return view(request, *args, **kwargs)
  File "D:\development\Python\lib\site-packages\django\contrib\admin\options.py", line 1637, in add_view
    return self.changeform_view(request, None, form_url, extra_context)
  File "D:\development\Python\lib\site-packages\django\utils\decorators.py", line 45, in _wrapper
    return bound_method(*args, **kwargs)
  File "D:\development\Python\lib\site-packages\django\utils\decorators.py", line 142, in _wrapped_view
    response = view_func(request, *args, **kwargs)
  File "D:\development\Python\lib\site-packages\django\contrib\admin\options.py", line 1525, in changeform_view
    return self._changeform_view(request, object_id, form_url, extra_context)
  File "D:\development\Python\lib\site-packages\django\contrib\admin\options.py", line 1564, in _changeform_view
    self.save_model(request, new_object, form, not add)
  File "D:\development\Python\lib\site-packages\django\contrib\admin\options.py", line 1091, in save_model
    obj.save()
  File "D:\development\Python\lib\site-packages\django\db\models\base.py", line 718, in save
    force_update=force_update, update_fields=update_fields)
  File "D:\development\Python\lib\site-packages\django\db\models\base.py", line 748, in save_base
    updated = self._save_table(raw, cls, force_insert, force_update, using, update_fields)
  File "D:\development\Python\lib\site-packages\django\db\models\base.py", line 831, in _save_table
    result = self._do_insert(cls._base_manager, using, fields, update_pk, raw)
  File "D:\development\Python\lib\site-packages\django\db\models\base.py", line 869, in _do_insert
    using=using, raw=raw)
  File "D:\development\Python\lib\site-packages\django\db\models\manager.py", line 82, in manager_method
    return getattr(self.get_queryset(), name)(*args, **kwargs)
  File "D:\development\Python\lib\site-packages\django\db\models\query.py", line 1136, in _insert
    return query.get_compiler(using=using).execute_sql(return_id)
  File "D:\development\Python\lib\site-packages\django\db\models\sql\compiler.py", line 1289, in execute_sql
    cursor.execute(sql, params)
  File "D:\development\Python\lib\site-packages\django\db\backends\utils.py", line 100, in execute
    return super().execute(sql, params)
  File "D:\development\Python\lib\site-packages\django\db\backends\utils.py", line 68, in execute
    return self._execute_with_wrappers(sql, params, many=False, executor=self._execute)
  File "D:\development\Python\lib\site-packages\django\db\backends\utils.py", line 77, in _execute_with_wrappers
    return executor(sql, params, many, context)
  File "D:\development\Python\lib\site-packages\django\db\backends\utils.py", line 85, in _execute
    return self.cursor.execute(sql, params)
  File "D:\development\Python\lib\site-packages\django\db\utils.py", line 89, in __exit__
    raise dj_exc_value.with_traceback(traceback) from exc_value
  File "D:\development\Python\lib\site-packages\django\db\backends\utils.py", line 85, in _execute
    return self.cursor.execute(sql, params)
  File "D:\development\Python\lib\site-packages\django\db\backends\mysql\base.py", line 71, in execute
    return self.cursor.execute(query, args)
  File "D:\development\Python\lib\site-packages\pymysql\cursors.py", line 170, in execute
    result = self._query(query)
  File "D:\development\Python\lib\site-packages\pymysql\cursors.py", line 328, in _query
    conn.query(q)
  File "D:\development\Python\lib\site-packages\pymysql\connections.py", line 516, in query
    self._affected_rows = self._read_query_result(unbuffered=unbuffered)
  File "D:\development\Python\lib\site-packages\pymysql\connections.py", line 727, in _read_query_result
    result.read()
  File "D:\development\Python\lib\site-packages\pymysql\connections.py", line 1066, in read
    first_packet = self.connection._read_packet()
  File "D:\development\Python\lib\site-packages\pymysql\connections.py", line 683, in _read_packet
    packet.check_error()
  File "D:\development\Python\lib\site-packages\pymysql\protocol.py", line 220, in check_error
    err.raise_mysql_exception(self._data)
  File "D:\development\Python\lib\site-packages\pymysql\err.py", line 109, in raise_mysql_exception
    raise errorclass(errno, errval)
django.db.utils.InternalError: (1366, "Incorrect string value: '\\xE5\\x93\\x88\\xE5\\x93\\x88...' for column 'title' at row 1")
2019-04-07 16:42:51,361 [Thread-9:9008] [django.request:228] [log:log_response] [ERROR]- Internal Server Error: /admin/application/plant/add/
Traceback (most recent call last):
  File "D:\development\Python\lib\site-packages\django\db\backends\utils.py", line 85, in _execute
    return self.cursor.execute(sql, params)
  File "D:\development\Python\lib\site-packages\django\db\backends\mysql\base.py", line 71, in execute
    return self.cursor.execute(query, args)
  File "D:\development\Python\lib\site-packages\pymysql\cursors.py", line 170, in execute
    result = self._query(query)
  File "D:\development\Python\lib\site-packages\pymysql\cursors.py", line 328, in _query
    conn.query(q)
  File "D:\development\Python\lib\site-packages\pymysql\connections.py", line 516, in query
    self._affected_rows = self._read_query_result(unbuffered=unbuffered)
  File "D:\development\Python\lib\site-packages\pymysql\connections.py", line 727, in _read_query_result
    result.read()
  File "D:\development\Python\lib\site-packages\pymysql\connections.py", line 1066, in read
    first_packet = self.connection._read_packet()
  File "D:\development\Python\lib\site-packages\pymysql\connections.py", line 683, in _read_packet
    packet.check_error()
  File "D:\development\Python\lib\site-packages\pymysql\protocol.py", line 220, in check_error
    err.raise_mysql_exception(self._data)
  File "D:\development\Python\lib\site-packages\pymysql\err.py", line 109, in raise_mysql_exception
    raise errorclass(errno, errval)
pymysql.err.InternalError: (1366, "Incorrect string value: '\\xE6\\xA4\\x8D\\xE7\\x89\\xA9...' for column 'name' at row 1")

The above exception was the direct cause of the following exception:

Traceback (most recent call last):
  File "D:\development\Python\lib\site-packages\django\core\handlers\exception.py", line 34, in inner
    response = get_response(request)
  File "D:\development\Python\lib\site-packages\django\core\handlers\base.py", line 126, in _get_response
    response = self.process_exception_by_middleware(e, request)
  File "D:\development\Python\lib\site-packages\django\core\handlers\base.py", line 124, in _get_response
    response = wrapped_callback(request, *callback_args, **callback_kwargs)
  File "D:\development\Python\lib\site-packages\django\contrib\admin\options.py", line 604, in wrapper
    return self.admin_site.admin_view(view)(*args, **kwargs)
  File "D:\development\Python\lib\site-packages\django\utils\decorators.py", line 142, in _wrapped_view
    response = view_func(request, *args, **kwargs)
  File "D:\development\Python\lib\site-packages\django\views\decorators\cache.py", line 44, in _wrapped_view_func
    response = view_func(request, *args, **kwargs)
  File "D:\development\Python\lib\site-packages\django\contrib\admin\sites.py", line 223, in inner
    return view(request, *args, **kwargs)
  File "D:\development\Python\lib\site-packages\django\contrib\admin\options.py", line 1637, in add_view
    return self.changeform_view(request, None, form_url, extra_context)
  File "D:\development\Python\lib\site-packages\django\utils\decorators.py", line 45, in _wrapper
    return bound_method(*args, **kwargs)
  File "D:\development\Python\lib\site-packages\django\utils\decorators.py", line 142, in _wrapped_view
    response = view_func(request, *args, **kwargs)
  File "D:\development\Python\lib\site-packages\django\contrib\admin\options.py", line 1525, in changeform_view
    return self._changeform_view(request, object_id, form_url, extra_context)
  File "D:\development\Python\lib\site-packages\django\contrib\admin\options.py", line 1564, in _changeform_view
    self.save_model(request, new_object, form, not add)
  File "D:\development\Python\lib\site-packages\django\contrib\admin\options.py", line 1091, in save_model
    obj.save()
  File "D:\development\Python\lib\site-packages\django\db\models\base.py", line 718, in save
    force_update=force_update, update_fields=update_fields)
  File "D:\development\Python\lib\site-packages\django\db\models\base.py", line 748, in save_base
    updated = self._save_table(raw, cls, force_insert, force_update, using, update_fields)
  File "D:\development\Python\lib\site-packages\django\db\models\base.py", line 831, in _save_table
    result = self._do_insert(cls._base_manager, using, fields, update_pk, raw)
  File "D:\development\Python\lib\site-packages\django\db\models\base.py", line 869, in _do_insert
    using=using, raw=raw)
  File "D:\development\Python\lib\site-packages\django\db\models\manager.py", line 82, in manager_method
    return getattr(self.get_queryset(), name)(*args, **kwargs)
  File "D:\development\Python\lib\site-packages\django\db\models\query.py", line 1136, in _insert
    return query.get_compiler(using=using).execute_sql(return_id)
  File "D:\development\Python\lib\site-packages\django\db\models\sql\compiler.py", line 1289, in execute_sql
    cursor.execute(sql, params)
  File "D:\development\Python\lib\site-packages\django\db\backends\utils.py", line 100, in execute
    return super().execute(sql, params)
  File "D:\development\Python\lib\site-packages\django\db\backends\utils.py", line 68, in execute
    return self._execute_with_wrappers(sql, params, many=False, executor=self._execute)
  File "D:\development\Python\lib\site-packages\django\db\backends\utils.py", line 77, in _execute_with_wrappers
    return executor(sql, params, many, context)
  File "D:\development\Python\lib\site-packages\django\db\backends\utils.py", line 85, in _execute
    return self.cursor.execute(sql, params)
  File "D:\development\Python\lib\site-packages\django\db\utils.py", line 89, in __exit__
    raise dj_exc_value.with_traceback(traceback) from exc_value
  File "D:\development\Python\lib\site-packages\django\db\backends\utils.py", line 85, in _execute
    return self.cursor.execute(sql, params)
  File "D:\development\Python\lib\site-packages\django\db\backends\mysql\base.py", line 71, in execute
    return self.cursor.execute(query, args)
  File "D:\development\Python\lib\site-packages\pymysql\cursors.py", line 170, in execute
    result = self._query(query)
  File "D:\development\Python\lib\site-packages\pymysql\cursors.py", line 328, in _query
    conn.query(q)
  File "D:\development\Python\lib\site-packages\pymysql\connections.py", line 516, in query
    self._affected_rows = self._read_query_result(unbuffered=unbuffered)
  File "D:\development\Python\lib\site-packages\pymysql\connections.py", line 727, in _read_query_result
    result.read()
  File "D:\development\Python\lib\site-packages\pymysql\connections.py", line 1066, in read
    first_packet = self.connection._read_packet()
  File "D:\development\Python\lib\site-packages\pymysql\connections.py", line 683, in _read_packet
    packet.check_error()
  File "D:\development\Python\lib\site-packages\pymysql\protocol.py", line 220, in check_error
    err.raise_mysql_exception(self._data)
  File "D:\development\Python\lib\site-packages\pymysql\err.py", line 109, in raise_mysql_exception
    raise errorclass(errno, errval)
django.db.utils.InternalError: (1366, "Incorrect string value: '\\xE6\\xA4\\x8D\\xE7\\x89\\xA9...' for column 'name' at row 1")
2019-04-07 22:52:19,978 [Thread-2:17492] [django.request:228] [log:log_response] [ERROR]- Internal Server Error: /admin/application/category/add/
Traceback (most recent call last):
  File "D:\development\Python\lib\site-packages\django\db\backends\utils.py", line 85, in _execute
    return self.cursor.execute(sql, params)
  File "D:\development\Python\lib\site-packages\django\db\backends\mysql\base.py", line 71, in execute
    return self.cursor.execute(query, args)
  File "D:\development\Python\lib\site-packages\pymysql\cursors.py", line 170, in execute
    result = self._query(query)
  File "D:\development\Python\lib\site-packages\pymysql\cursors.py", line 328, in _query
    conn.query(q)
  File "D:\development\Python\lib\site-packages\pymysql\connections.py", line 516, in query
    self._affected_rows = self._read_query_result(unbuffered=unbuffered)
  File "D:\development\Python\lib\site-packages\pymysql\connections.py", line 727, in _read_query_result
    result.read()
  File "D:\development\Python\lib\site-packages\pymysql\connections.py", line 1066, in read
    first_packet = self.connection._read_packet()
  File "D:\development\Python\lib\site-packages\pymysql\connections.py", line 683, in _read_packet
    packet.check_error()
  File "D:\development\Python\lib\site-packages\pymysql\protocol.py", line 220, in check_error
    err.raise_mysql_exception(self._data)
  File "D:\development\Python\lib\site-packages\pymysql\err.py", line 109, in raise_mysql_exception
    raise errorclass(errno, errval)
pymysql.err.InternalError: (1366, "Incorrect string value: '\\xE5\\x90\\x91\\xE6\\x97\\xA5...' for column 'name' at row 1")

The above exception was the direct cause of the following exception:

Traceback (most recent call last):
  File "D:\development\Python\lib\site-packages\django\core\handlers\exception.py", line 34, in inner
    response = get_response(request)
  File "D:\development\Python\lib\site-packages\django\core\handlers\base.py", line 126, in _get_response
    response = self.process_exception_by_middleware(e, request)
  File "D:\development\Python\lib\site-packages\django\core\handlers\base.py", line 124, in _get_response
    response = wrapped_callback(request, *callback_args, **callback_kwargs)
  File "D:\development\Python\lib\site-packages\django\contrib\admin\options.py", line 604, in wrapper
    return self.admin_site.admin_view(view)(*args, **kwargs)
  File "D:\development\Python\lib\site-packages\django\utils\decorators.py", line 142, in _wrapped_view
    response = view_func(request, *args, **kwargs)
  File "D:\development\Python\lib\site-packages\django\views\decorators\cache.py", line 44, in _wrapped_view_func
    response = view_func(request, *args, **kwargs)
  File "D:\development\Python\lib\site-packages\django\contrib\admin\sites.py", line 223, in inner
    return view(request, *args, **kwargs)
  File "D:\development\Python\lib\site-packages\django\contrib\admin\options.py", line 1637, in add_view
    return self.changeform_view(request, None, form_url, extra_context)
  File "D:\development\Python\lib\site-packages\django\utils\decorators.py", line 45, in _wrapper
    return bound_method(*args, **kwargs)
  File "D:\development\Python\lib\site-packages\django\utils\decorators.py", line 142, in _wrapped_view
    response = view_func(request, *args, **kwargs)
  File "D:\development\Python\lib\site-packages\django\contrib\admin\options.py", line 1525, in changeform_view
    return self._changeform_view(request, object_id, form_url, extra_context)
  File "D:\development\Python\lib\site-packages\django\contrib\admin\options.py", line 1564, in _changeform_view
    self.save_model(request, new_object, form, not add)
  File "D:\development\Python\lib\site-packages\django\contrib\admin\options.py", line 1091, in save_model
    obj.save()
  File "D:\development\Python\lib\site-packages\django\db\models\base.py", line 718, in save
    force_update=force_update, update_fields=update_fields)
  File "D:\development\Python\lib\site-packages\django\db\models\base.py", line 748, in save_base
    updated = self._save_table(raw, cls, force_insert, force_update, using, update_fields)
  File "D:\development\Python\lib\site-packages\django\db\models\base.py", line 831, in _save_table
    result = self._do_insert(cls._base_manager, using, fields, update_pk, raw)
  File "D:\development\Python\lib\site-packages\django\db\models\base.py", line 869, in _do_insert
    using=using, raw=raw)
  File "D:\development\Python\lib\site-packages\django\db\models\manager.py", line 82, in manager_method
    return getattr(self.get_queryset(), name)(*args, **kwargs)
  File "D:\development\Python\lib\site-packages\django\db\models\query.py", line 1136, in _insert
    return query.get_compiler(using=using).execute_sql(return_id)
  File "D:\development\Python\lib\site-packages\django\db\models\sql\compiler.py", line 1289, in execute_sql
    cursor.execute(sql, params)
  File "D:\development\Python\lib\site-packages\django\db\backends\utils.py", line 100, in execute
    return super().execute(sql, params)
  File "D:\development\Python\lib\site-packages\django\db\backends\utils.py", line 68, in execute
    return self._execute_with_wrappers(sql, params, many=False, executor=self._execute)
  File "D:\development\Python\lib\site-packages\django\db\backends\utils.py", line 77, in _execute_with_wrappers
    return executor(sql, params, many, context)
  File "D:\development\Python\lib\site-packages\django\db\backends\utils.py", line 85, in _execute
    return self.cursor.execute(sql, params)
  File "D:\development\Python\lib\site-packages\django\db\utils.py", line 89, in __exit__
    raise dj_exc_value.with_traceback(traceback) from exc_value
  File "D:\development\Python\lib\site-packages\django\db\backends\utils.py", line 85, in _execute
    return self.cursor.execute(sql, params)
  File "D:\development\Python\lib\site-packages\django\db\backends\mysql\base.py", line 71, in execute
    return self.cursor.execute(query, args)
  File "D:\development\Python\lib\site-packages\pymysql\cursors.py", line 170, in execute
    result = self._query(query)
  File "D:\development\Python\lib\site-packages\pymysql\cursors.py", line 328, in _query
    conn.query(q)
  File "D:\development\Python\lib\site-packages\pymysql\connections.py", line 516, in query
    self._affected_rows = self._read_query_result(unbuffered=unbuffered)
  File "D:\development\Python\lib\site-packages\pymysql\connections.py", line 727, in _read_query_result
    result.read()
  File "D:\development\Python\lib\site-packages\pymysql\connections.py", line 1066, in read
    first_packet = self.connection._read_packet()
  File "D:\development\Python\lib\site-packages\pymysql\connections.py", line 683, in _read_packet
    packet.check_error()
  File "D:\development\Python\lib\site-packages\pymysql\protocol.py", line 220, in check_error
    err.raise_mysql_exception(self._data)
  File "D:\development\Python\lib\site-packages\pymysql\err.py", line 109, in raise_mysql_exception
    raise errorclass(errno, errval)
django.db.utils.InternalError: (1366, "Incorrect string value: '\\xE5\\x90\\x91\\xE6\\x97\\xA5...' for column 'name' at row 1")
2019-04-07 22:52:52,234 [Thread-2:17492] [django.request:228] [log:log_response] [ERROR]- Internal Server Error: /admin/application/category/add/
Traceback (most recent call last):
  File "D:\development\Python\lib\site-packages\django\db\backends\utils.py", line 85, in _execute
    return self.cursor.execute(sql, params)
  File "D:\development\Python\lib\site-packages\django\db\backends\mysql\base.py", line 71, in execute
    return self.cursor.execute(query, args)
  File "D:\development\Python\lib\site-packages\pymysql\cursors.py", line 170, in execute
    result = self._query(query)
  File "D:\development\Python\lib\site-packages\pymysql\cursors.py", line 328, in _query
    conn.query(q)
  File "D:\development\Python\lib\site-packages\pymysql\connections.py", line 516, in query
    self._affected_rows = self._read_query_result(unbuffered=unbuffered)
  File "D:\development\Python\lib\site-packages\pymysql\connections.py", line 727, in _read_query_result
    result.read()
  File "D:\development\Python\lib\site-packages\pymysql\connections.py", line 1066, in read
    first_packet = self.connection._read_packet()
  File "D:\development\Python\lib\site-packages\pymysql\connections.py", line 683, in _read_packet
    packet.check_error()
  File "D:\development\Python\lib\site-packages\pymysql\protocol.py", line 220, in check_error
    err.raise_mysql_exception(self._data)
  File "D:\development\Python\lib\site-packages\pymysql\err.py", line 109, in raise_mysql_exception
    raise errorclass(errno, errval)
pymysql.err.InternalError: (1366, "Incorrect string value: '\\xE5\\x90\\x91\\xE6\\x97\\xA5...' for column 'name' at row 1")

The above exception was the direct cause of the following exception:

Traceback (most recent call last):
  File "D:\development\Python\lib\site-packages\django\core\handlers\exception.py", line 34, in inner
    response = get_response(request)
  File "D:\development\Python\lib\site-packages\django\core\handlers\base.py", line 126, in _get_response
    response = self.process_exception_by_middleware(e, request)
  File "D:\development\Python\lib\site-packages\django\core\handlers\base.py", line 124, in _get_response
    response = wrapped_callback(request, *callback_args, **callback_kwargs)
  File "D:\development\Python\lib\site-packages\django\contrib\admin\options.py", line 604, in wrapper
    return self.admin_site.admin_view(view)(*args, **kwargs)
  File "D:\development\Python\lib\site-packages\django\utils\decorators.py", line 142, in _wrapped_view
    response = view_func(request, *args, **kwargs)
  File "D:\development\Python\lib\site-packages\django\views\decorators\cache.py", line 44, in _wrapped_view_func
    response = view_func(request, *args, **kwargs)
  File "D:\development\Python\lib\site-packages\django\contrib\admin\sites.py", line 223, in inner
    return view(request, *args, **kwargs)
  File "D:\development\Python\lib\site-packages\django\contrib\admin\options.py", line 1637, in add_view
    return self.changeform_view(request, None, form_url, extra_context)
  File "D:\development\Python\lib\site-packages\django\utils\decorators.py", line 45, in _wrapper
    return bound_method(*args, **kwargs)
  File "D:\development\Python\lib\site-packages\django\utils\decorators.py", line 142, in _wrapped_view
    response = view_func(request, *args, **kwargs)
  File "D:\development\Python\lib\site-packages\django\contrib\admin\options.py", line 1525, in changeform_view
    return self._changeform_view(request, object_id, form_url, extra_context)
  File "D:\development\Python\lib\site-packages\django\contrib\admin\options.py", line 1564, in _changeform_view
    self.save_model(request, new_object, form, not add)
  File "D:\development\Python\lib\site-packages\django\contrib\admin\options.py", line 1091, in save_model
    obj.save()
  File "D:\development\Python\lib\site-packages\django\db\models\base.py", line 718, in save
    force_update=force_update, update_fields=update_fields)
  File "D:\development\Python\lib\site-packages\django\db\models\base.py", line 748, in save_base
    updated = self._save_table(raw, cls, force_insert, force_update, using, update_fields)
  File "D:\development\Python\lib\site-packages\django\db\models\base.py", line 831, in _save_table
    result = self._do_insert(cls._base_manager, using, fields, update_pk, raw)
  File "D:\development\Python\lib\site-packages\django\db\models\base.py", line 869, in _do_insert
    using=using, raw=raw)
  File "D:\development\Python\lib\site-packages\django\db\models\manager.py", line 82, in manager_method
    return getattr(self.get_queryset(), name)(*args, **kwargs)
  File "D:\development\Python\lib\site-packages\django\db\models\query.py", line 1136, in _insert
    return query.get_compiler(using=using).execute_sql(return_id)
  File "D:\development\Python\lib\site-packages\django\db\models\sql\compiler.py", line 1289, in execute_sql
    cursor.execute(sql, params)
  File "D:\development\Python\lib\site-packages\django\db\backends\utils.py", line 100, in execute
    return super().execute(sql, params)
  File "D:\development\Python\lib\site-packages\django\db\backends\utils.py", line 68, in execute
    return self._execute_with_wrappers(sql, params, many=False, executor=self._execute)
  File "D:\development\Python\lib\site-packages\django\db\backends\utils.py", line 77, in _execute_with_wrappers
    return executor(sql, params, many, context)
  File "D:\development\Python\lib\site-packages\django\db\backends\utils.py", line 85, in _execute
    return self.cursor.execute(sql, params)
  File "D:\development\Python\lib\site-packages\django\db\utils.py", line 89, in __exit__
    raise dj_exc_value.with_traceback(traceback) from exc_value
  File "D:\development\Python\lib\site-packages\django\db\backends\utils.py", line 85, in _execute
    return self.cursor.execute(sql, params)
  File "D:\development\Python\lib\site-packages\django\db\backends\mysql\base.py", line 71, in execute
    return self.cursor.execute(query, args)
  File "D:\development\Python\lib\site-packages\pymysql\cursors.py", line 170, in execute
    result = self._query(query)
  File "D:\development\Python\lib\site-packages\pymysql\cursors.py", line 328, in _query
    conn.query(q)
  File "D:\development\Python\lib\site-packages\pymysql\connections.py", line 516, in query
    self._affected_rows = self._read_query_result(unbuffered=unbuffered)
  File "D:\development\Python\lib\site-packages\pymysql\connections.py", line 727, in _read_query_result
    result.read()
  File "D:\development\Python\lib\site-packages\pymysql\connections.py", line 1066, in read
    first_packet = self.connection._read_packet()
  File "D:\development\Python\lib\site-packages\pymysql\connections.py", line 683, in _read_packet
    packet.check_error()
  File "D:\development\Python\lib\site-packages\pymysql\protocol.py", line 220, in check_error
    err.raise_mysql_exception(self._data)
  File "D:\development\Python\lib\site-packages\pymysql\err.py", line 109, in raise_mysql_exception
    raise errorclass(errno, errval)
django.db.utils.InternalError: (1366, "Incorrect string value: '\\xE5\\x90\\x91\\xE6\\x97\\xA5...' for column 'name' at row 1")
2019-04-07 22:55:52,172 [Thread-2:18372] [django.request:228] [log:log_response] [ERROR]- Internal Server Error: /admin/application/category/1/change/
Traceback (most recent call last):
  File "D:\development\Python\lib\site-packages\django\db\backends\utils.py", line 85, in _execute
    return self.cursor.execute(sql, params)
  File "D:\development\Python\lib\site-packages\django\db\backends\mysql\base.py", line 71, in execute
    return self.cursor.execute(query, args)
  File "D:\development\Python\lib\site-packages\pymysql\cursors.py", line 170, in execute
    result = self._query(query)
  File "D:\development\Python\lib\site-packages\pymysql\cursors.py", line 328, in _query
    conn.query(q)
  File "D:\development\Python\lib\site-packages\pymysql\connections.py", line 516, in query
    self._affected_rows = self._read_query_result(unbuffered=unbuffered)
  File "D:\development\Python\lib\site-packages\pymysql\connections.py", line 727, in _read_query_result
    result.read()
  File "D:\development\Python\lib\site-packages\pymysql\connections.py", line 1066, in read
    first_packet = self.connection._read_packet()
  File "D:\development\Python\lib\site-packages\pymysql\connections.py", line 683, in _read_packet
    packet.check_error()
  File "D:\development\Python\lib\site-packages\pymysql\protocol.py", line 220, in check_error
    err.raise_mysql_exception(self._data)
  File "D:\development\Python\lib\site-packages\pymysql\err.py", line 109, in raise_mysql_exception
    raise errorclass(errno, errval)
pymysql.err.InternalError: (1366, "Incorrect string value: '\\xE5\\x90\\x91\\xE6\\x97\\xA5...' for column 'name' at row 1")

The above exception was the direct cause of the following exception:

Traceback (most recent call last):
  File "D:\development\Python\lib\site-packages\django\core\handlers\exception.py", line 34, in inner
    response = get_response(request)
  File "D:\development\Python\lib\site-packages\django\core\handlers\base.py", line 126, in _get_response
    response = self.process_exception_by_middleware(e, request)
  File "D:\development\Python\lib\site-packages\django\core\handlers\base.py", line 124, in _get_response
    response = wrapped_callback(request, *callback_args, **callback_kwargs)
  File "D:\development\Python\lib\site-packages\django\contrib\admin\options.py", line 604, in wrapper
    return self.admin_site.admin_view(view)(*args, **kwargs)
  File "D:\development\Python\lib\site-packages\django\utils\decorators.py", line 142, in _wrapped_view
    response = view_func(request, *args, **kwargs)
  File "D:\development\Python\lib\site-packages\django\views\decorators\cache.py", line 44, in _wrapped_view_func
    response = view_func(request, *args, **kwargs)
  File "D:\development\Python\lib\site-packages\django\contrib\admin\sites.py", line 223, in inner
    return view(request, *args, **kwargs)
  File "D:\development\Python\lib\site-packages\django\contrib\admin\options.py", line 1640, in change_view
    return self.changeform_view(request, object_id, form_url, extra_context)
  File "D:\development\Python\lib\site-packages\django\utils\decorators.py", line 45, in _wrapper
    return bound_method(*args, **kwargs)
  File "D:\development\Python\lib\site-packages\django\utils\decorators.py", line 142, in _wrapped_view
    response = view_func(request, *args, **kwargs)
  File "D:\development\Python\lib\site-packages\django\contrib\admin\options.py", line 1525, in changeform_view
    return self._changeform_view(request, object_id, form_url, extra_context)
  File "D:\development\Python\lib\site-packages\django\contrib\admin\options.py", line 1564, in _changeform_view
    self.save_model(request, new_object, form, not add)
  File "D:\development\Python\lib\site-packages\django\contrib\admin\options.py", line 1091, in save_model
    obj.save()
  File "D:\development\Python\lib\site-packages\django\db\models\base.py", line 718, in save
    force_update=force_update, update_fields=update_fields)
  File "D:\development\Python\lib\site-packages\django\db\models\base.py", line 748, in save_base
    updated = self._save_table(raw, cls, force_insert, force_update, using, update_fields)
  File "D:\development\Python\lib\site-packages\django\db\models\base.py", line 812, in _save_table
    forced_update)
  File "D:\development\Python\lib\site-packages\django\db\models\base.py", line 861, in _do_update
    return filtered._update(values) > 0
  File "D:\development\Python\lib\site-packages\django\db\models\query.py", line 712, in _update
    return query.get_compiler(self.db).execute_sql(CURSOR)
  File "D:\development\Python\lib\site-packages\django\db\models\sql\compiler.py", line 1383, in execute_sql
    cursor = super().execute_sql(result_type)
  File "D:\development\Python\lib\site-packages\django\db\models\sql\compiler.py", line 1065, in execute_sql
    cursor.execute(sql, params)
  File "D:\development\Python\lib\site-packages\django\db\backends\utils.py", line 100, in execute
    return super().execute(sql, params)
  File "D:\development\Python\lib\site-packages\django\db\backends\utils.py", line 68, in execute
    return self._execute_with_wrappers(sql, params, many=False, executor=self._execute)
  File "D:\development\Python\lib\site-packages\django\db\backends\utils.py", line 77, in _execute_with_wrappers
    return executor(sql, params, many, context)
  File "D:\development\Python\lib\site-packages\django\db\backends\utils.py", line 85, in _execute
    return self.cursor.execute(sql, params)
  File "D:\development\Python\lib\site-packages\django\db\utils.py", line 89, in __exit__
    raise dj_exc_value.with_traceback(traceback) from exc_value
  File "D:\development\Python\lib\site-packages\django\db\backends\utils.py", line 85, in _execute
    return self.cursor.execute(sql, params)
  File "D:\development\Python\lib\site-packages\django\db\backends\mysql\base.py", line 71, in execute
    return self.cursor.execute(query, args)
  File "D:\development\Python\lib\site-packages\pymysql\cursors.py", line 170, in execute
    result = self._query(query)
  File "D:\development\Python\lib\site-packages\pymysql\cursors.py", line 328, in _query
    conn.query(q)
  File "D:\development\Python\lib\site-packages\pymysql\connections.py", line 516, in query
    self._affected_rows = self._read_query_result(unbuffered=unbuffered)
  File "D:\development\Python\lib\site-packages\pymysql\connections.py", line 727, in _read_query_result
    result.read()
  File "D:\development\Python\lib\site-packages\pymysql\connections.py", line 1066, in read
    first_packet = self.connection._read_packet()
  File "D:\development\Python\lib\site-packages\pymysql\connections.py", line 683, in _read_packet
    packet.check_error()
  File "D:\development\Python\lib\site-packages\pymysql\protocol.py", line 220, in check_error
    err.raise_mysql_exception(self._data)
  File "D:\development\Python\lib\site-packages\pymysql\err.py", line 109, in raise_mysql_exception
    raise errorclass(errno, errval)
django.db.utils.InternalError: (1366, "Incorrect string value: '\\xE5\\x90\\x91\\xE6\\x97\\xA5...' for column 'name' at row 1")
2019-04-08 01:19:46,389 [Thread-2:8320] [django.request:228] [log:log_response] [ERROR]- Internal Server Error: /admin/application/plant/
Traceback (most recent call last):
  File "D:\development\Python\lib\site-packages\django\db\backends\utils.py", line 85, in _execute
    return self.cursor.execute(sql, params)
  File "D:\development\Python\lib\site-packages\django\db\backends\mysql\base.py", line 71, in execute
    return self.cursor.execute(query, args)
  File "D:\development\Python\lib\site-packages\pymysql\cursors.py", line 170, in execute
    result = self._query(query)
  File "D:\development\Python\lib\site-packages\pymysql\cursors.py", line 328, in _query
    conn.query(q)
  File "D:\development\Python\lib\site-packages\pymysql\connections.py", line 516, in query
    self._affected_rows = self._read_query_result(unbuffered=unbuffered)
  File "D:\development\Python\lib\site-packages\pymysql\connections.py", line 727, in _read_query_result
    result.read()
  File "D:\development\Python\lib\site-packages\pymysql\connections.py", line 1066, in read
    first_packet = self.connection._read_packet()
  File "D:\development\Python\lib\site-packages\pymysql\connections.py", line 683, in _read_packet
    packet.check_error()
  File "D:\development\Python\lib\site-packages\pymysql\protocol.py", line 220, in check_error
    err.raise_mysql_exception(self._data)
  File "D:\development\Python\lib\site-packages\pymysql\err.py", line 109, in raise_mysql_exception
    raise errorclass(errno, errval)
pymysql.err.ProgrammingError: (1146, "Table 'plant.vote' doesn't exist")

The above exception was the direct cause of the following exception:

Traceback (most recent call last):
  File "D:\development\Python\lib\site-packages\django\core\handlers\exception.py", line 34, in inner
    response = get_response(request)
  File "D:\development\Python\lib\site-packages\django\core\handlers\base.py", line 126, in _get_response
    response = self.process_exception_by_middleware(e, request)
  File "D:\development\Python\lib\site-packages\django\core\handlers\base.py", line 124, in _get_response
    response = wrapped_callback(request, *callback_args, **callback_kwargs)
  File "D:\development\Python\lib\site-packages\django\contrib\admin\options.py", line 604, in wrapper
    return self.admin_site.admin_view(view)(*args, **kwargs)
  File "D:\development\Python\lib\site-packages\django\utils\decorators.py", line 142, in _wrapped_view
    response = view_func(request, *args, **kwargs)
  File "D:\development\Python\lib\site-packages\django\views\decorators\cache.py", line 44, in _wrapped_view_func
    response = view_func(request, *args, **kwargs)
  File "D:\development\Python\lib\site-packages\django\contrib\admin\sites.py", line 223, in inner
    return view(request, *args, **kwargs)
  File "D:\development\Python\lib\site-packages\django\utils\decorators.py", line 45, in _wrapper
    return bound_method(*args, **kwargs)
  File "D:\development\Python\lib\site-packages\django\utils\decorators.py", line 142, in _wrapped_view
    response = view_func(request, *args, **kwargs)
  File "D:\development\Python\lib\site-packages\django\contrib\admin\options.py", line 1701, in changelist_view
    response = self.response_action(request, queryset=cl.get_queryset(request))
  File "D:\development\Python\lib\site-packages\django\contrib\admin\options.py", line 1400, in response_action
    response = func(self, request, queryset)
  File "D:\development\Python\lib\site-packages\django\contrib\admin\actions.py", line 28, in delete_selected
    deletable_objects, model_count, perms_needed, protected = modeladmin.get_deleted_objects(queryset, request)
  File "D:\development\Python\lib\site-packages\django\contrib\admin\options.py", line 1823, in get_deleted_objects
    return get_deleted_objects(objs, request, self.admin_site)
  File "D:\development\Python\lib\site-packages\django\contrib\admin\utils.py", line 134, in get_deleted_objects
    collector.collect(objs)
  File "D:\development\Python\lib\site-packages\django\contrib\admin\utils.py", line 197, in collect
    return super().collect(objs, source_attr=source_attr, **kwargs)
  File "D:\development\Python\lib\site-packages\django\db\models\deletion.py", line 220, in collect
    elif sub_objs:
  File "D:\development\Python\lib\site-packages\django\db\models\query.py", line 272, in __bool__
    self._fetch_all()
  File "D:\development\Python\lib\site-packages\django\db\models\query.py", line 1186, in _fetch_all
    self._result_cache = list(self._iterable_class(self))
  File "D:\development\Python\lib\site-packages\django\db\models\query.py", line 54, in __iter__
    results = compiler.execute_sql(chunked_fetch=self.chunked_fetch, chunk_size=self.chunk_size)
  File "D:\development\Python\lib\site-packages\django\db\models\sql\compiler.py", line 1065, in execute_sql
    cursor.execute(sql, params)
  File "D:\development\Python\lib\site-packages\django\db\backends\utils.py", line 100, in execute
    return super().execute(sql, params)
  File "D:\development\Python\lib\site-packages\django\db\backends\utils.py", line 68, in execute
    return self._execute_with_wrappers(sql, params, many=False, executor=self._execute)
  File "D:\development\Python\lib\site-packages\django\db\backends\utils.py", line 77, in _execute_with_wrappers
    return executor(sql, params, many, context)
  File "D:\development\Python\lib\site-packages\django\db\backends\utils.py", line 85, in _execute
    return self.cursor.execute(sql, params)
  File "D:\development\Python\lib\site-packages\django\db\utils.py", line 89, in __exit__
    raise dj_exc_value.with_traceback(traceback) from exc_value
  File "D:\development\Python\lib\site-packages\django\db\backends\utils.py", line 85, in _execute
    return self.cursor.execute(sql, params)
  File "D:\development\Python\lib\site-packages\django\db\backends\mysql\base.py", line 71, in execute
    return self.cursor.execute(query, args)
  File "D:\development\Python\lib\site-packages\pymysql\cursors.py", line 170, in execute
    result = self._query(query)
  File "D:\development\Python\lib\site-packages\pymysql\cursors.py", line 328, in _query
    conn.query(q)
  File "D:\development\Python\lib\site-packages\pymysql\connections.py", line 516, in query
    self._affected_rows = self._read_query_result(unbuffered=unbuffered)
  File "D:\development\Python\lib\site-packages\pymysql\connections.py", line 727, in _read_query_result
    result.read()
  File "D:\development\Python\lib\site-packages\pymysql\connections.py", line 1066, in read
    first_packet = self.connection._read_packet()
  File "D:\development\Python\lib\site-packages\pymysql\connections.py", line 683, in _read_packet
    packet.check_error()
  File "D:\development\Python\lib\site-packages\pymysql\protocol.py", line 220, in check_error
    err.raise_mysql_exception(self._data)
  File "D:\development\Python\lib\site-packages\pymysql\err.py", line 109, in raise_mysql_exception
    raise errorclass(errno, errval)
django.db.utils.ProgrammingError: (1146, "Table 'plant.vote' doesn't exist")
2019-04-09 01:33:24,763 [Thread-2:6464] [django.request:228] [log:log_response] [ERROR]- Internal Server Error: /plant/login/
Traceback (most recent call last):
  File "D:\development\Python\lib\site-packages\django\utils\datastructures.py", line 77, in __getitem__
    list_ = super().__getitem__(key)
KeyError: 'email'

During handling of the above exception, another exception occurred:

Traceback (most recent call last):
  File "D:\development\Python\lib\site-packages\django\core\handlers\exception.py", line 34, in inner
    response = get_response(request)
  File "D:\development\Python\lib\site-packages\django\core\handlers\base.py", line 126, in _get_response
    response = self.process_exception_by_middleware(e, request)
  File "D:\development\Python\lib\site-packages\django\core\handlers\base.py", line 124, in _get_response
    response = wrapped_callback(request, *callback_args, **callback_kwargs)
  File "D:\workspace\workspace-python\plant\application\views.py", line 166, in login
    email = request.POST['email']
  File "D:\development\Python\lib\site-packages\django\utils\datastructures.py", line 79, in __getitem__
    raise MultiValueDictKeyError(key)
django.utils.datastructures.MultiValueDictKeyError: 'email'
2019-04-09 01:36:55,524 [Thread-7:6272] [django.request:228] [log:log_response] [ERROR]- Internal Server Error: /plant/login/
Traceback (most recent call last):
  File "D:\development\Python\lib\site-packages\django\utils\datastructures.py", line 77, in __getitem__
    list_ = super().__getitem__(key)
KeyError: 'email'

During handling of the above exception, another exception occurred:

Traceback (most recent call last):
  File "D:\development\Python\lib\site-packages\django\core\handlers\exception.py", line 34, in inner
    response = get_response(request)
  File "D:\development\Python\lib\site-packages\django\core\handlers\base.py", line 126, in _get_response
    response = self.process_exception_by_middleware(e, request)
  File "D:\development\Python\lib\site-packages\django\core\handlers\base.py", line 124, in _get_response
    response = wrapped_callback(request, *callback_args, **callback_kwargs)
  File "D:\workspace\workspace-python\plant\application\views.py", line 166, in login
    email = request.POST['email']
  File "D:\development\Python\lib\site-packages\django\utils\datastructures.py", line 79, in __getitem__
    raise MultiValueDictKeyError(key)
django.utils.datastructures.MultiValueDictKeyError: 'email'
2019-04-09 01:37:33,625 [Thread-7:12812] [django.request:228] [log:log_response] [ERROR]- Internal Server Error: /plant/new_plant/
Traceback (most recent call last):
  File "D:\development\Python\lib\site-packages\django\utils\datastructures.py", line 77, in __getitem__
    list_ = super().__getitem__(key)
KeyError: 'category'

During handling of the above exception, another exception occurred:

Traceback (most recent call last):
  File "D:\development\Python\lib\site-packages\django\core\handlers\exception.py", line 34, in inner
    response = get_response(request)
  File "D:\development\Python\lib\site-packages\django\core\handlers\base.py", line 126, in _get_response
    response = self.process_exception_by_middleware(e, request)
  File "D:\development\Python\lib\site-packages\django\core\handlers\base.py", line 124, in _get_response
    response = wrapped_callback(request, *callback_args, **callback_kwargs)
  File "D:\workspace\workspace-python\plant\application\views.py", line 128, in new_plant
    category = request.POST['category']
  File "D:\development\Python\lib\site-packages\django\utils\datastructures.py", line 79, in __getitem__
    raise MultiValueDictKeyError(key)
django.utils.datastructures.MultiValueDictKeyError: 'category'
2019-04-09 01:42:58,587 [Thread-12:13972] [django.request:228] [log:log_response] [ERROR]- Internal Server Error: /plant/new_plant/
Traceback (most recent call last):
  File "D:\development\Python\lib\site-packages\django\utils\datastructures.py", line 77, in __getitem__
    list_ = super().__getitem__(key)
KeyError: 'category'

During handling of the above exception, another exception occurred:

Traceback (most recent call last):
  File "D:\development\Python\lib\site-packages\django\core\handlers\exception.py", line 34, in inner
    response = get_response(request)
  File "D:\development\Python\lib\site-packages\django\core\handlers\base.py", line 126, in _get_response
    response = self.process_exception_by_middleware(e, request)
  File "D:\development\Python\lib\site-packages\django\core\handlers\base.py", line 124, in _get_response
    response = wrapped_callback(request, *callback_args, **callback_kwargs)
  File "D:\workspace\workspace-python\plant\application\views.py", line 128, in new_plant
    category = request.POST['category']
  File "D:\development\Python\lib\site-packages\django\utils\datastructures.py", line 79, in __getitem__
    raise MultiValueDictKeyError(key)
django.utils.datastructures.MultiValueDictKeyError: 'category'
2019-04-09 01:44:08,355 [Thread-2:15156] [django.request:228] [log:log_response] [ERROR]- Internal Server Error: /plant/new_plant/
Traceback (most recent call last):
  File "D:\development\Python\lib\site-packages\django\core\handlers\exception.py", line 34, in inner
    response = get_response(request)
  File "D:\development\Python\lib\site-packages\django\core\handlers\base.py", line 126, in _get_response
    response = self.process_exception_by_middleware(e, request)
  File "D:\development\Python\lib\site-packages\django\core\handlers\base.py", line 124, in _get_response
    response = wrapped_callback(request, *callback_args, **callback_kwargs)
  File "D:\workspace\workspace-python\plant\application\views.py", line 134, in new_plant
    extension = os.path.splitext(file.name)[1]
AttributeError: 'bytes' object has no attribute 'name'
2019-04-09 01:46:59,715 [Thread-3:2152] [django.request:228] [log:log_response] [ERROR]- Internal Server Error: /plant/new_plant/
Traceback (most recent call last):
  File "D:\development\Python\lib\site-packages\django\core\handlers\exception.py", line 34, in inner
    response = get_response(request)
  File "D:\development\Python\lib\site-packages\django\core\handlers\base.py", line 126, in _get_response
    response = self.process_exception_by_middleware(e, request)
  File "D:\development\Python\lib\site-packages\django\core\handlers\base.py", line 124, in _get_response
    response = wrapped_callback(request, *callback_args, **callback_kwargs)
  File "D:\workspace\workspace-python\plant\application\views.py", line 131, in new_plant
    files = request.FILES.getList('avatar')
AttributeError: 'MultiValueDict' object has no attribute 'getList'
2019-04-09 01:47:58,974 [Thread-3:2152] [django.request:228] [log:log_response] [ERROR]- Internal Server Error: /plant/new_plant/
Traceback (most recent call last):
  File "D:\development\Python\lib\site-packages\django\core\handlers\exception.py", line 34, in inner
    response = get_response(request)
  File "D:\development\Python\lib\site-packages\django\core\handlers\base.py", line 126, in _get_response
    response = self.process_exception_by_middleware(e, request)
  File "D:\development\Python\lib\site-packages\django\core\handlers\base.py", line 124, in _get_response
    response = wrapped_callback(request, *callback_args, **callback_kwargs)
  File "D:\workspace\workspace-python\plant\application\views.py", line 131, in new_plant
    files = request.FILES.getList('avatar')
AttributeError: 'MultiValueDict' object has no attribute 'getList'
2019-04-09 02:04:12,996 [Thread-2:11076] [django.request:228] [log:log_response] [ERROR]- Internal Server Error: /plant/new_plant/
Traceback (most recent call last):
  File "D:\development\Python\lib\site-packages\django\core\handlers\exception.py", line 34, in inner
    response = get_response(request)
  File "D:\development\Python\lib\site-packages\django\core\handlers\base.py", line 126, in _get_response
    response = self.process_exception_by_middleware(e, request)
  File "D:\development\Python\lib\site-packages\django\core\handlers\base.py", line 124, in _get_response
    response = wrapped_callback(request, *callback_args, **callback_kwargs)
  File "D:\workspace\workspace-python\plant\application\views.py", line 131, in new_plant
    files = request.FILES.getList('avatar')
AttributeError: 'MultiValueDict' object has no attribute 'getList'
2019-04-14 21:18:44,759 [Thread-2:13104] [django.request:228] [log:log_response] [ERROR]- Internal Server Error: /plant/new_gallery/
Traceback (most recent call last):
  File "D:\development\Python\lib\site-packages\django\db\backends\utils.py", line 83, in _execute
    return self.cursor.execute(sql)
  File "D:\development\Python\lib\site-packages\django\db\backends\mysql\base.py", line 71, in execute
    return self.cursor.execute(query, args)
  File "D:\development\Python\lib\site-packages\pymysql\cursors.py", line 170, in execute
    result = self._query(query)
  File "D:\development\Python\lib\site-packages\pymysql\cursors.py", line 328, in _query
    conn.query(q)
  File "D:\development\Python\lib\site-packages\pymysql\connections.py", line 516, in query
    self._affected_rows = self._read_query_result(unbuffered=unbuffered)
  File "D:\development\Python\lib\site-packages\pymysql\connections.py", line 727, in _read_query_result
    result.read()
  File "D:\development\Python\lib\site-packages\pymysql\connections.py", line 1066, in read
    first_packet = self.connection._read_packet()
  File "D:\development\Python\lib\site-packages\pymysql\connections.py", line 683, in _read_packet
    packet.check_error()
  File "D:\development\Python\lib\site-packages\pymysql\protocol.py", line 220, in check_error
    err.raise_mysql_exception(self._data)
  File "D:\development\Python\lib\site-packages\pymysql\err.py", line 109, in raise_mysql_exception
    raise errorclass(errno, errval)
pymysql.err.ProgrammingError: (1064, "You have an error in your SQL syntax; check the manual that corresponds to your MySQL server version for the right syntax to use near 'desc,date)values ('1','1','2118','33','Apr 16, 2019')' at line 1")

The above exception was the direct cause of the following exception:

Traceback (most recent call last):
  File "D:\development\Python\lib\site-packages\django\core\handlers\exception.py", line 34, in inner
    response = get_response(request)
  File "D:\development\Python\lib\site-packages\django\core\handlers\base.py", line 126, in _get_response
    response = self.process_exception_by_middleware(e, request)
  File "D:\development\Python\lib\site-packages\django\core\handlers\base.py", line 124, in _get_response
    response = wrapped_callback(request, *callback_args, **callback_kwargs)
  File "D:\workspace\workspace-python\plant\application\views.py", line 165, in new_gallery
    cursor.execute(sql)
  File "D:\development\Python\lib\site-packages\django\db\backends\utils.py", line 100, in execute
    return super().execute(sql, params)
  File "D:\development\Python\lib\site-packages\django\db\backends\utils.py", line 68, in execute
    return self._execute_with_wrappers(sql, params, many=False, executor=self._execute)
  File "D:\development\Python\lib\site-packages\django\db\backends\utils.py", line 77, in _execute_with_wrappers
    return executor(sql, params, many, context)
  File "D:\development\Python\lib\site-packages\django\db\backends\utils.py", line 85, in _execute
    return self.cursor.execute(sql, params)
  File "D:\development\Python\lib\site-packages\django\db\utils.py", line 89, in __exit__
    raise dj_exc_value.with_traceback(traceback) from exc_value
  File "D:\development\Python\lib\site-packages\django\db\backends\utils.py", line 83, in _execute
    return self.cursor.execute(sql)
  File "D:\development\Python\lib\site-packages\django\db\backends\mysql\base.py", line 71, in execute
    return self.cursor.execute(query, args)
  File "D:\development\Python\lib\site-packages\pymysql\cursors.py", line 170, in execute
    result = self._query(query)
  File "D:\development\Python\lib\site-packages\pymysql\cursors.py", line 328, in _query
    conn.query(q)
  File "D:\development\Python\lib\site-packages\pymysql\connections.py", line 516, in query
    self._affected_rows = self._read_query_result(unbuffered=unbuffered)
  File "D:\development\Python\lib\site-packages\pymysql\connections.py", line 727, in _read_query_result
    result.read()
  File "D:\development\Python\lib\site-packages\pymysql\connections.py", line 1066, in read
    first_packet = self.connection._read_packet()
  File "D:\development\Python\lib\site-packages\pymysql\connections.py", line 683, in _read_packet
    packet.check_error()
  File "D:\development\Python\lib\site-packages\pymysql\protocol.py", line 220, in check_error
    err.raise_mysql_exception(self._data)
  File "D:\development\Python\lib\site-packages\pymysql\err.py", line 109, in raise_mysql_exception
    raise errorclass(errno, errval)
django.db.utils.ProgrammingError: (1064, "You have an error in your SQL syntax; check the manual that corresponds to your MySQL server version for the right syntax to use near 'desc,date)values ('1','1','2118','33','Apr 16, 2019')' at line 1")
2019-04-14 22:35:20,334 [Thread-2:7480] [django.request:228] [log:log_response] [ERROR]- Internal Server Error: /plant/new_gallery/
Traceback (most recent call last):
  File "D:\development\Python\lib\site-packages\django\db\backends\utils.py", line 83, in _execute
    return self.cursor.execute(sql)
  File "D:\development\Python\lib\site-packages\django\db\backends\mysql\base.py", line 71, in execute
    return self.cursor.execute(query, args)
  File "D:\development\Python\lib\site-packages\pymysql\cursors.py", line 170, in execute
    result = self._query(query)
  File "D:\development\Python\lib\site-packages\pymysql\cursors.py", line 328, in _query
    conn.query(q)
  File "D:\development\Python\lib\site-packages\pymysql\connections.py", line 516, in query
    self._affected_rows = self._read_query_result(unbuffered=unbuffered)
  File "D:\development\Python\lib\site-packages\pymysql\connections.py", line 727, in _read_query_result
    result.read()
  File "D:\development\Python\lib\site-packages\pymysql\connections.py", line 1066, in read
    first_packet = self.connection._read_packet()
  File "D:\development\Python\lib\site-packages\pymysql\connections.py", line 683, in _read_packet
    packet.check_error()
  File "D:\development\Python\lib\site-packages\pymysql\protocol.py", line 220, in check_error
    err.raise_mysql_exception(self._data)
  File "D:\development\Python\lib\site-packages\pymysql\err.py", line 109, in raise_mysql_exception
    raise errorclass(errno, errval)
pymysql.err.ProgrammingError: (1064, "You have an error in your SQL syntax; check the manual that corresponds to your MySQL server version for the right syntax to use near 'desc,date)values ('1','1','2118','33','2019-04-14 22:35:17')' at line 1")

The above exception was the direct cause of the following exception:

Traceback (most recent call last):
  File "D:\development\Python\lib\site-packages\django\core\handlers\exception.py", line 34, in inner
    response = get_response(request)
  File "D:\development\Python\lib\site-packages\django\core\handlers\base.py", line 126, in _get_response
    response = self.process_exception_by_middleware(e, request)
  File "D:\development\Python\lib\site-packages\django\core\handlers\base.py", line 124, in _get_response
    response = wrapped_callback(request, *callback_args, **callback_kwargs)
  File "D:\workspace\workspace-python\plant\application\views.py", line 166, in new_gallery
    cursor.execute(sql)
  File "D:\development\Python\lib\site-packages\django\db\backends\utils.py", line 100, in execute
    return super().execute(sql, params)
  File "D:\development\Python\lib\site-packages\django\db\backends\utils.py", line 68, in execute
    return self._execute_with_wrappers(sql, params, many=False, executor=self._execute)
  File "D:\development\Python\lib\site-packages\django\db\backends\utils.py", line 77, in _execute_with_wrappers
    return executor(sql, params, many, context)
  File "D:\development\Python\lib\site-packages\django\db\backends\utils.py", line 85, in _execute
    return self.cursor.execute(sql, params)
  File "D:\development\Python\lib\site-packages\django\db\utils.py", line 89, in __exit__
    raise dj_exc_value.with_traceback(traceback) from exc_value
  File "D:\development\Python\lib\site-packages\django\db\backends\utils.py", line 83, in _execute
    return self.cursor.execute(sql)
  File "D:\development\Python\lib\site-packages\django\db\backends\mysql\base.py", line 71, in execute
    return self.cursor.execute(query, args)
  File "D:\development\Python\lib\site-packages\pymysql\cursors.py", line 170, in execute
    result = self._query(query)
  File "D:\development\Python\lib\site-packages\pymysql\cursors.py", line 328, in _query
    conn.query(q)
  File "D:\development\Python\lib\site-packages\pymysql\connections.py", line 516, in query
    self._affected_rows = self._read_query_result(unbuffered=unbuffered)
  File "D:\development\Python\lib\site-packages\pymysql\connections.py", line 727, in _read_query_result
    result.read()
  File "D:\development\Python\lib\site-packages\pymysql\connections.py", line 1066, in read
    first_packet = self.connection._read_packet()
  File "D:\development\Python\lib\site-packages\pymysql\connections.py", line 683, in _read_packet
    packet.check_error()
  File "D:\development\Python\lib\site-packages\pymysql\protocol.py", line 220, in check_error
    err.raise_mysql_exception(self._data)
  File "D:\development\Python\lib\site-packages\pymysql\err.py", line 109, in raise_mysql_exception
    raise errorclass(errno, errval)
django.db.utils.ProgrammingError: (1064, "You have an error in your SQL syntax; check the manual that corresponds to your MySQL server version for the right syntax to use near 'desc,date)values ('1','1','2118','33','2019-04-14 22:35:17')' at line 1")
2019-04-14 22:40:13,043 [Thread-2:4104] [django.request:228] [log:log_response] [ERROR]- Internal Server Error: /plant/new_gallery/
Traceback (most recent call last):
  File "D:\development\Python\lib\site-packages\django\core\handlers\exception.py", line 34, in inner
    response = get_response(request)
  File "D:\development\Python\lib\site-packages\django\core\handlers\base.py", line 126, in _get_response
    response = self.process_exception_by_middleware(e, request)
  File "D:\development\Python\lib\site-packages\django\core\handlers\base.py", line 124, in _get_response
    response = wrapped_callback(request, *callback_args, **callback_kwargs)
  File "D:\workspace\workspace-python\plant\application\views.py", line 163, in new_gallery
    "values ('%d','%d','%s','%s','%s')" % (user_id, plant_id, name, desc, date)
TypeError: %d format: a number is required, not str
2019-04-14 22:42:22,297 [Thread-2:6556] [django.request:228] [log:log_response] [ERROR]- Internal Server Error: /plant/new_gallery/
Traceback (most recent call last):
  File "D:\development\Python\lib\site-packages\django\db\backends\utils.py", line 83, in _execute
    return self.cursor.execute(sql)
  File "D:\development\Python\lib\site-packages\django\db\backends\mysql\base.py", line 71, in execute
    return self.cursor.execute(query, args)
  File "D:\development\Python\lib\site-packages\pymysql\cursors.py", line 170, in execute
    result = self._query(query)
  File "D:\development\Python\lib\site-packages\pymysql\cursors.py", line 328, in _query
    conn.query(q)
  File "D:\development\Python\lib\site-packages\pymysql\connections.py", line 516, in query
    self._affected_rows = self._read_query_result(unbuffered=unbuffered)
  File "D:\development\Python\lib\site-packages\pymysql\connections.py", line 727, in _read_query_result
    result.read()
  File "D:\development\Python\lib\site-packages\pymysql\connections.py", line 1066, in read
    first_packet = self.connection._read_packet()
  File "D:\development\Python\lib\site-packages\pymysql\connections.py", line 683, in _read_packet
    packet.check_error()
  File "D:\development\Python\lib\site-packages\pymysql\protocol.py", line 220, in check_error
    err.raise_mysql_exception(self._data)
  File "D:\development\Python\lib\site-packages\pymysql\err.py", line 109, in raise_mysql_exception
    raise errorclass(errno, errval)
pymysql.err.ProgrammingError: (1064, "You have an error in your SQL syntax; check the manual that corresponds to your MySQL server version for the right syntax to use near 'desc,date)values ('1','1','2118','33','2019-04-14 22:42:21')' at line 1")

The above exception was the direct cause of the following exception:

Traceback (most recent call last):
  File "D:\development\Python\lib\site-packages\django\core\handlers\exception.py", line 34, in inner
    response = get_response(request)
  File "D:\development\Python\lib\site-packages\django\core\handlers\base.py", line 126, in _get_response
    response = self.process_exception_by_middleware(e, request)
  File "D:\development\Python\lib\site-packages\django\core\handlers\base.py", line 124, in _get_response
    response = wrapped_callback(request, *callback_args, **callback_kwargs)
  File "D:\workspace\workspace-python\plant\application\views.py", line 166, in new_gallery
    cursor.execute(sql)
  File "D:\development\Python\lib\site-packages\django\db\backends\utils.py", line 100, in execute
    return super().execute(sql, params)
  File "D:\development\Python\lib\site-packages\django\db\backends\utils.py", line 68, in execute
    return self._execute_with_wrappers(sql, params, many=False, executor=self._execute)
  File "D:\development\Python\lib\site-packages\django\db\backends\utils.py", line 77, in _execute_with_wrappers
    return executor(sql, params, many, context)
  File "D:\development\Python\lib\site-packages\django\db\backends\utils.py", line 85, in _execute
    return self.cursor.execute(sql, params)
  File "D:\development\Python\lib\site-packages\django\db\utils.py", line 89, in __exit__
    raise dj_exc_value.with_traceback(traceback) from exc_value
  File "D:\development\Python\lib\site-packages\django\db\backends\utils.py", line 83, in _execute
    return self.cursor.execute(sql)
  File "D:\development\Python\lib\site-packages\django\db\backends\mysql\base.py", line 71, in execute
    return self.cursor.execute(query, args)
  File "D:\development\Python\lib\site-packages\pymysql\cursors.py", line 170, in execute
    result = self._query(query)
  File "D:\development\Python\lib\site-packages\pymysql\cursors.py", line 328, in _query
    conn.query(q)
  File "D:\development\Python\lib\site-packages\pymysql\connections.py", line 516, in query
    self._affected_rows = self._read_query_result(unbuffered=unbuffered)
  File "D:\development\Python\lib\site-packages\pymysql\connections.py", line 727, in _read_query_result
    result.read()
  File "D:\development\Python\lib\site-packages\pymysql\connections.py", line 1066, in read
    first_packet = self.connection._read_packet()
  File "D:\development\Python\lib\site-packages\pymysql\connections.py", line 683, in _read_packet
    packet.check_error()
  File "D:\development\Python\lib\site-packages\pymysql\protocol.py", line 220, in check_error
    err.raise_mysql_exception(self._data)
  File "D:\development\Python\lib\site-packages\pymysql\err.py", line 109, in raise_mysql_exception
    raise errorclass(errno, errval)
django.db.utils.ProgrammingError: (1064, "You have an error in your SQL syntax; check the manual that corresponds to your MySQL server version for the right syntax to use near 'desc,date)values ('1','1','2118','33','2019-04-14 22:42:21')' at line 1")
2019-04-14 22:43:26,875 [Thread-2:6556] [django.request:228] [log:log_response] [ERROR]- Internal Server Error: /plant/new_gallery/
Traceback (most recent call last):
  File "D:\development\Python\lib\site-packages\django\db\backends\utils.py", line 83, in _execute
    return self.cursor.execute(sql)
  File "D:\development\Python\lib\site-packages\django\db\backends\mysql\base.py", line 71, in execute
    return self.cursor.execute(query, args)
  File "D:\development\Python\lib\site-packages\pymysql\cursors.py", line 170, in execute
    result = self._query(query)
  File "D:\development\Python\lib\site-packages\pymysql\cursors.py", line 328, in _query
    conn.query(q)
  File "D:\development\Python\lib\site-packages\pymysql\connections.py", line 516, in query
    self._affected_rows = self._read_query_result(unbuffered=unbuffered)
  File "D:\development\Python\lib\site-packages\pymysql\connections.py", line 727, in _read_query_result
    result.read()
  File "D:\development\Python\lib\site-packages\pymysql\connections.py", line 1066, in read
    first_packet = self.connection._read_packet()
  File "D:\development\Python\lib\site-packages\pymysql\connections.py", line 683, in _read_packet
    packet.check_error()
  File "D:\development\Python\lib\site-packages\pymysql\protocol.py", line 220, in check_error
    err.raise_mysql_exception(self._data)
  File "D:\development\Python\lib\site-packages\pymysql\err.py", line 109, in raise_mysql_exception
    raise errorclass(errno, errval)
pymysql.err.ProgrammingError: (1064, "You have an error in your SQL syntax; check the manual that corresponds to your MySQL server version for the right syntax to use near 'desc,date)values ('1','1','2118','33','2019-04-14 22:43:26')' at line 1")

The above exception was the direct cause of the following exception:

Traceback (most recent call last):
  File "D:\development\Python\lib\site-packages\django\core\handlers\exception.py", line 34, in inner
    response = get_response(request)
  File "D:\development\Python\lib\site-packages\django\core\handlers\base.py", line 126, in _get_response
    response = self.process_exception_by_middleware(e, request)
  File "D:\development\Python\lib\site-packages\django\core\handlers\base.py", line 124, in _get_response
    response = wrapped_callback(request, *callback_args, **callback_kwargs)
  File "D:\workspace\workspace-python\plant\application\views.py", line 166, in new_gallery
    cursor.execute(sql)
  File "D:\development\Python\lib\site-packages\django\db\backends\utils.py", line 100, in execute
    return super().execute(sql, params)
  File "D:\development\Python\lib\site-packages\django\db\backends\utils.py", line 68, in execute
    return self._execute_with_wrappers(sql, params, many=False, executor=self._execute)
  File "D:\development\Python\lib\site-packages\django\db\backends\utils.py", line 77, in _execute_with_wrappers
    return executor(sql, params, many, context)
  File "D:\development\Python\lib\site-packages\django\db\backends\utils.py", line 85, in _execute
    return self.cursor.execute(sql, params)
  File "D:\development\Python\lib\site-packages\django\db\utils.py", line 89, in __exit__
    raise dj_exc_value.with_traceback(traceback) from exc_value
  File "D:\development\Python\lib\site-packages\django\db\backends\utils.py", line 83, in _execute
    return self.cursor.execute(sql)
  File "D:\development\Python\lib\site-packages\django\db\backends\mysql\base.py", line 71, in execute
    return self.cursor.execute(query, args)
  File "D:\development\Python\lib\site-packages\pymysql\cursors.py", line 170, in execute
    result = self._query(query)
  File "D:\development\Python\lib\site-packages\pymysql\cursors.py", line 328, in _query
    conn.query(q)
  File "D:\development\Python\lib\site-packages\pymysql\connections.py", line 516, in query
    self._affected_rows = self._read_query_result(unbuffered=unbuffered)
  File "D:\development\Python\lib\site-packages\pymysql\connections.py", line 727, in _read_query_result
    result.read()
  File "D:\development\Python\lib\site-packages\pymysql\connections.py", line 1066, in read
    first_packet = self.connection._read_packet()
  File "D:\development\Python\lib\site-packages\pymysql\connections.py", line 683, in _read_packet
    packet.check_error()
  File "D:\development\Python\lib\site-packages\pymysql\protocol.py", line 220, in check_error
    err.raise_mysql_exception(self._data)
  File "D:\development\Python\lib\site-packages\pymysql\err.py", line 109, in raise_mysql_exception
    raise errorclass(errno, errval)
django.db.utils.ProgrammingError: (1064, "You have an error in your SQL syntax; check the manual that corresponds to your MySQL server version for the right syntax to use near 'desc,date)values ('1','1','2118','33','2019-04-14 22:43:26')' at line 1")
2019-04-14 22:48:36,879 [Thread-2:8752] [django.request:228] [log:log_response] [ERROR]- Internal Server Error: /plant/new_gallery/
Traceback (most recent call last):
  File "D:\development\Python\lib\site-packages\django\core\handlers\exception.py", line 34, in inner
    response = get_response(request)
  File "D:\development\Python\lib\site-packages\django\core\handlers\base.py", line 126, in _get_response
    response = self.process_exception_by_middleware(e, request)
  File "D:\development\Python\lib\site-packages\django\core\handlers\base.py", line 124, in _get_response
    response = wrapped_callback(request, *callback_args, **callback_kwargs)
  File "D:\workspace\workspace-python\plant\application\views.py", line 168, in new_gallery
    Photo.objects.create(user_id=user_id, plant_id=plant_id, name=name, desc=desc, date=date)
  File "D:\development\Python\lib\site-packages\django\db\models\manager.py", line 82, in manager_method
    return getattr(self.get_queryset(), name)(*args, **kwargs)
  File "D:\development\Python\lib\site-packages\django\db\models\query.py", line 411, in create
    obj = self.model(**kwargs)
  File "D:\development\Python\lib\site-packages\django\db\models\base.py", line 485, in __init__
    raise TypeError("'%s' is an invalid keyword argument for this function" % kwarg)
TypeError: 'user_id' is an invalid keyword argument for this function
2019-04-14 22:52:31,164 [Thread-2:10272] [django.request:228] [log:log_response] [ERROR]- Internal Server Error: /plant/new_gallery/
Traceback (most recent call last):
  File "D:\development\Python\lib\site-packages\django\core\handlers\exception.py", line 34, in inner
    response = get_response(request)
  File "D:\development\Python\lib\site-packages\django\core\handlers\base.py", line 126, in _get_response
    response = self.process_exception_by_middleware(e, request)
  File "D:\development\Python\lib\site-packages\django\core\handlers\base.py", line 124, in _get_response
    response = wrapped_callback(request, *callback_args, **callback_kwargs)
  File "D:\workspace\workspace-python\plant\application\views.py", line 168, in new_gallery
    Photo.objects.create(user_id=1, plant_id=1, name=name, desc=desc, date=date)
  File "D:\development\Python\lib\site-packages\django\db\models\manager.py", line 82, in manager_method
    return getattr(self.get_queryset(), name)(*args, **kwargs)
  File "D:\development\Python\lib\site-packages\django\db\models\query.py", line 411, in create
    obj = self.model(**kwargs)
  File "D:\development\Python\lib\site-packages\django\db\models\base.py", line 485, in __init__
    raise TypeError("'%s' is an invalid keyword argument for this function" % kwarg)
TypeError: 'user_id' is an invalid keyword argument for this function
2019-04-14 22:53:42,907 [Thread-8:4344] [django.request:228] [log:log_response] [ERROR]- Internal Server Error: /plant/new_gallery/
Traceback (most recent call last):
  File "D:\development\Python\lib\site-packages\django\utils\datastructures.py", line 77, in __getitem__
    list_ = super().__getitem__(key)
KeyError: 'plant_id'

During handling of the above exception, another exception occurred:

Traceback (most recent call last):
  File "D:\development\Python\lib\site-packages\django\core\handlers\exception.py", line 34, in inner
    response = get_response(request)
  File "D:\development\Python\lib\site-packages\django\core\handlers\base.py", line 126, in _get_response
    response = self.process_exception_by_middleware(e, request)
  File "D:\development\Python\lib\site-packages\django\core\handlers\base.py", line 124, in _get_response
    response = wrapped_callback(request, *callback_args, **callback_kwargs)
  File "D:\workspace\workspace-python\plant\application\views.py", line 157, in new_gallery
    plant_id = request.POST['plant_id']
  File "D:\development\Python\lib\site-packages\django\utils\datastructures.py", line 79, in __getitem__
    raise MultiValueDictKeyError(key)
django.utils.datastructures.MultiValueDictKeyError: 'plant_id'
2019-04-14 22:54:31,226 [Thread-10:12488] [django.request:228] [log:log_response] [ERROR]- Internal Server Error: /plant/new_gallery/
Traceback (most recent call last):
  File "D:\development\Python\lib\site-packages\django\core\handlers\exception.py", line 34, in inner
    response = get_response(request)
  File "D:\development\Python\lib\site-packages\django\core\handlers\base.py", line 126, in _get_response
    response = self.process_exception_by_middleware(e, request)
  File "D:\development\Python\lib\site-packages\django\core\handlers\base.py", line 124, in _get_response
    response = wrapped_callback(request, *callback_args, **callback_kwargs)
  File "D:\workspace\workspace-python\plant\application\views.py", line 168, in new_gallery
    Photo.objects.create(user_id=1, plant_id=1, name=name, desc=desc, date=date)
  File "D:\development\Python\lib\site-packages\django\db\models\manager.py", line 82, in manager_method
    return getattr(self.get_queryset(), name)(*args, **kwargs)
  File "D:\development\Python\lib\site-packages\django\db\models\query.py", line 411, in create
    obj = self.model(**kwargs)
  File "D:\development\Python\lib\site-packages\django\db\models\base.py", line 485, in __init__
    raise TypeError("'%s' is an invalid keyword argument for this function" % kwarg)
TypeError: 'user_id' is an invalid keyword argument for this function
2019-04-21 21:50:13,939 [Thread-3:9852] [django.request:228] [log:log_response] [ERROR]- Internal Server Error: /plant/login/
Traceback (most recent call last):
  File "D:\development\Python\lib\site-packages\django\utils\datastructures.py", line 77, in __getitem__
    list_ = super().__getitem__(key)
KeyError: 'email'

During handling of the above exception, another exception occurred:

Traceback (most recent call last):
  File "D:\development\Python\lib\site-packages\django\core\handlers\exception.py", line 34, in inner
    response = get_response(request)
  File "D:\development\Python\lib\site-packages\django\core\handlers\base.py", line 126, in _get_response
    response = self.process_exception_by_middleware(e, request)
  File "D:\development\Python\lib\site-packages\django\core\handlers\base.py", line 124, in _get_response
    response = wrapped_callback(request, *callback_args, **callback_kwargs)
  File "D:\workspace\workspace-python\plant\application\views.py", line 195, in login
    email = request.POST['email']
  File "D:\development\Python\lib\site-packages\django\utils\datastructures.py", line 79, in __getitem__
    raise MultiValueDictKeyError(key)
django.utils.datastructures.MultiValueDictKeyError: 'email'
2019-04-21 23:21:12,193 [Thread-2:8708] [django.request:228] [log:log_response] [ERROR]- Internal Server Error: /plant/login/
Traceback (most recent call last):
  File "D:\development\Python\lib\site-packages\django\utils\datastructures.py", line 77, in __getitem__
    list_ = super().__getitem__(key)
KeyError: 'email'

During handling of the above exception, another exception occurred:

Traceback (most recent call last):
  File "D:\development\Python\lib\site-packages\django\core\handlers\exception.py", line 34, in inner
    response = get_response(request)
  File "D:\development\Python\lib\site-packages\django\core\handlers\base.py", line 126, in _get_response
    response = self.process_exception_by_middleware(e, request)
  File "D:\development\Python\lib\site-packages\django\core\handlers\base.py", line 124, in _get_response
    response = wrapped_callback(request, *callback_args, **callback_kwargs)
  File "D:\workspace\workspace-python\plant\application\views.py", line 195, in login
    email = request.POST['email']
  File "D:\development\Python\lib\site-packages\django\utils\datastructures.py", line 79, in __getitem__
    raise MultiValueDictKeyError(key)
django.utils.datastructures.MultiValueDictKeyError: 'email'
