INFO 2019-04-28 00:52:37,825 danielUPDATE user SET name = 'daniel90911111111111111111111111111110', password = '123', email = '123@qq.com', phone = '18940980522' WHERE id = 1
2019-04-28 00:52:37,975 [Thread-2:2700] [django.request:228] [log:log_response] [ERROR]- Internal Server Error: /api/update_user/
Traceback (most recent call last):
  File "D:\development\Python\lib\site-packages\django\db\backends\utils.py", line 82, in _execute
    return self.cursor.execute(sql)
  File "D:\development\Python\lib\site-packages\django\db\backends\mysql\base.py", line 71, in execute
    return self.cursor.execute(query, args)
  File "D:\development\Python\lib\site-packages\pymysql\cursors.py", line 170, in execute
    result = self._query(query)
  File "D:\development\Python\lib\site-packages\pymysql\cursors.py", line 328, in _query
    conn.query(q)
  File "D:\development\Python\lib\site-packages\pymysql\connections.py", line 517, in query
    self._affected_rows = self._read_query_result(unbuffered=unbuffered)
  File "D:\development\Python\lib\site-packages\pymysql\connections.py", line 732, in _read_query_result
    result.read()
  File "D:\development\Python\lib\site-packages\pymysql\connections.py", line 1075, in read
    first_packet = self.connection._read_packet()
  File "D:\development\Python\lib\site-packages\pymysql\connections.py", line 684, in _read_packet
    packet.check_error()
  File "D:\development\Python\lib\site-packages\pymysql\protocol.py", line 220, in check_error
    err.raise_mysql_exception(self._data)
  File "D:\development\Python\lib\site-packages\pymysql\err.py", line 109, in raise_mysql_exception
    raise errorclass(errno, errval)
pymysql.err.DataError: (1406, "Data too long for column 'name' at row 1")

The above exception was the direct cause of the following exception:

Traceback (most recent call last):
  File "D:\development\Python\lib\site-packages\django\core\handlers\exception.py", line 34, in inner
    response = get_response(request)
  File "D:\development\Python\lib\site-packages\django\core\handlers\base.py", line 115, in _get_response
    response = self.process_exception_by_middleware(e, request)
  File "D:\development\Python\lib\site-packages\django\core\handlers\base.py", line 113, in _get_response
    response = wrapped_callback(request, *callback_args, **callback_kwargs)
  File "D:\workspace\workspace-python\plant\api\views.py", line 35, in update_user
    cursor.execute(sql)
  File "D:\development\Python\lib\site-packages\django\db\backends\utils.py", line 99, in execute
    return super().execute(sql, params)
  File "D:\development\Python\lib\site-packages\django\db\backends\utils.py", line 67, in execute
    return self._execute_with_wrappers(sql, params, many=False, executor=self._execute)
  File "D:\development\Python\lib\site-packages\django\db\backends\utils.py", line 76, in _execute_with_wrappers
    return executor(sql, params, many, context)
  File "D:\development\Python\lib\site-packages\django\db\backends\utils.py", line 84, in _execute
    return self.cursor.execute(sql, params)
  File "D:\development\Python\lib\site-packages\django\db\utils.py", line 89, in __exit__
    raise dj_exc_value.with_traceback(traceback) from exc_value
  File "D:\development\Python\lib\site-packages\django\db\backends\utils.py", line 82, in _execute
    return self.cursor.execute(sql)
  File "D:\development\Python\lib\site-packages\django\db\backends\mysql\base.py", line 71, in execute
    return self.cursor.execute(query, args)
  File "D:\development\Python\lib\site-packages\pymysql\cursors.py", line 170, in execute
    result = self._query(query)
  File "D:\development\Python\lib\site-packages\pymysql\cursors.py", line 328, in _query
    conn.query(q)
  File "D:\development\Python\lib\site-packages\pymysql\connections.py", line 517, in query
    self._affected_rows = self._read_query_result(unbuffered=unbuffered)
  File "D:\development\Python\lib\site-packages\pymysql\connections.py", line 732, in _read_query_result
    result.read()
  File "D:\development\Python\lib\site-packages\pymysql\connections.py", line 1075, in read
    first_packet = self.connection._read_packet()
  File "D:\development\Python\lib\site-packages\pymysql\connections.py", line 684, in _read_packet
    packet.check_error()
  File "D:\development\Python\lib\site-packages\pymysql\protocol.py", line 220, in check_error
    err.raise_mysql_exception(self._data)
  File "D:\development\Python\lib\site-packages\pymysql\err.py", line 109, in raise_mysql_exception
    raise errorclass(errno, errval)
django.db.utils.DataError: (1406, "Data too long for column 'name' at row 1")
INFO 2019-04-28 00:53:44,387 danielUPDATE user SET name = 'daniel910', password = '123', email = '123@qq.com', phone = '18940980522' WHERE id = 1
INFO 2019-04-28 00:53:44,392 daniel0
INFO 2019-04-28 01:15:06,830 danielUPDATE user SET name = 'daniel1514', password = '123', email = '123@qq.com', phone = '18940980522' WHERE id = 1
INFO 2019-04-28 01:15:06,837 daniel0
INFO 2019-04-28 01:17:05,905 danielUPDATE user SET name = 'daniel666', password = '123', email = '123@qq.com', phone = '18940980522' WHERE id = 1
INFO 2019-04-28 01:17:05,910 daniel0
2019-04-28 01:28:55,796 [Thread-9:10656] [django.request:228] [log:log_response] [ERROR]- Internal Server Error: /api/update_user/
Traceback (most recent call last):
  File "D:\development\Python\lib\site-packages\django\core\handlers\exception.py", line 34, in inner
    response = get_response(request)
  File "D:\development\Python\lib\site-packages\django\core\handlers\base.py", line 115, in _get_response
    response = self.process_exception_by_middleware(e, request)
  File "D:\development\Python\lib\site-packages\django\core\handlers\base.py", line 113, in _get_response
    response = wrapped_callback(request, *callback_args, **callback_kwargs)
  File "D:\workspace\workspace-python\plant\api\views.py", line 33, in update_user
    % (name, password, email, phone, id)
TypeError: %d format: a number is required, not str
2019-04-28 01:34:38,821 [Thread-11:3396] [django.request:228] [log:log_response] [ERROR]- Internal Server Error: /api/update_user/
Traceback (most recent call last):
  File "D:\development\Python\lib\site-packages\django\core\handlers\exception.py", line 34, in inner
    response = get_response(request)
  File "D:\development\Python\lib\site-packages\django\core\handlers\base.py", line 115, in _get_response
    response = self.process_exception_by_middleware(e, request)
  File "D:\development\Python\lib\site-packages\django\core\handlers\base.py", line 113, in _get_response
    response = wrapped_callback(request, *callback_args, **callback_kwargs)
  File "D:\workspace\workspace-python\plant\api\views.py", line 33, in update_user
    % (name, password, email, phone, id)
TypeError: %d format: a number is required, not str
2019-04-28 01:40:40,577 [Thread-13:10816] [django.request:228] [log:log_response] [ERROR]- Internal Server Error: /api/update_user/
Traceback (most recent call last):
  File "D:\development\Python\lib\site-packages\django\core\handlers\exception.py", line 34, in inner
    response = get_response(request)
  File "D:\development\Python\lib\site-packages\django\core\handlers\base.py", line 115, in _get_response
    response = self.process_exception_by_middleware(e, request)
  File "D:\development\Python\lib\site-packages\django\core\handlers\base.py", line 113, in _get_response
    response = wrapped_callback(request, *callback_args, **callback_kwargs)
  File "D:\workspace\workspace-python\plant\api\views.py", line 33, in update_user
    % (name, password, email, phone, id)
TypeError: %d format: a number is required, not NoneType
2019-04-28 01:41:28,452 [Thread-13:10816] [django.request:228] [log:log_response] [ERROR]- Internal Server Error: /api/update_user/
Traceback (most recent call last):
  File "D:\development\Python\lib\site-packages\django\core\handlers\exception.py", line 34, in inner
    response = get_response(request)
  File "D:\development\Python\lib\site-packages\django\core\handlers\base.py", line 115, in _get_response
    response = self.process_exception_by_middleware(e, request)
  File "D:\development\Python\lib\site-packages\django\core\handlers\base.py", line 113, in _get_response
    response = wrapped_callback(request, *callback_args, **callback_kwargs)
  File "D:\workspace\workspace-python\plant\api\views.py", line 33, in update_user
    % (name, password, email, phone, id)
TypeError: %d format: a number is required, not NoneType
INFO 2019-04-28 01:43:28,755 danielUPDATE user SET name = 'daniel666', password = '123', email = '123@qq.com', phone = '18940980522' WHERE id = 1
INFO 2019-04-28 01:43:28,762 daniel0
INFO 2019-04-28 01:44:58,686 danielUPDATE user SET name = 'daniel666', password = '123', email = '123@qq.com', phone = '18940980522' WHERE id = 1
INFO 2019-04-28 01:44:58,693 daniel0
